Workbook

Sheet 硬件
A1: 版本 | B1: Abbr | C1: 创建日期 | D1: 创建人 | E1: 词性备注 | F1: 术语中文释义 | G1: 术语英文释义 | H1: 中文术语 | J1: 英文术语 | L1: 西文术语 | N1: 俄文术语
H2: 术语 | I2: 字符数 | J2: 术语 | K2: 字符数 | L2: 术语 | M2: 字符数 | N2: 术语 | O2: 字符数
A3: 板卡
A4: =IF(B4="","",IF(A4<>"",A4,#REF!)) -> #VALUE! | B4: cpu_module | C4: 44675.804 | D4: 鲍凯鹏 | E4: 名词短语 | G4: CPU module | H4: CPU板卡 | I4: =LEN(H4) -> 5 | J4: CPU module | K4: =LEN(J4) -> 10 | M4: =LEN(L4) -> 0 | O4: =LEN(N4) -> 0
K5: =LEN(J5) -> 0 | M5: =LEN(L5) -> 0 | O5: =LEN(N5) -> 0
K6: =LEN(J6) -> 0 | M6: =LEN(L6) -> 0 | O6: =LEN(N6) -> 0
K7: =LEN(J7) -> 0 | M7: =LEN(L7) -> 0 | O7: =LEN(N7) -> 0
K8: =LEN(J8) -> 0 | M8: =LEN(L8) -> 0 | O8: =LEN(N8) -> 0
K9: =LEN(J9) -> 0 | M9: =LEN(L9) -> 0 | O9: =LEN(N9) -> 0
K10: =LEN(J10) -> 0 | M10: =LEN(L10) -> 0 | O10: =LEN(N10) -> 0
K11: =LEN(J11) -> 0 | M11: =LEN(L11) -> 0 | O11: =LEN(N11) -> 0
I13: =LEN(H13) -> 0 | K13: =LEN(J13) -> 0 | M13: 0 | O13: 0
I14: =LEN(H14) -> 0 | K14: =LEN(J14) -> 0 | M14: 0 | O14: 0
I15: =LEN(H15) -> 0 | K15: =LEN(J15) -> 0 | M15: 0 | O15: 0
I16: =LEN(H16) -> 0 | K16: =LEN(J16) -> 0 | M16: 0 | O16: 0
A17: 机箱
A18: =IF(B18="","",IF(A18<>"",A18,#REF!)) -> #VALUE! | B18: rack | C18: =IF(B18="","",IF(C18<>"",C18,NOW())) -> 0 | D18: 鲍凯鹏 | E18: 名词短语 | G18: Rack | H18: 机箱 | I18: =LEN(H18) -> 2 | J18: Rack | K18: =LEN(J18) -> 4 | M18: =LEN(L18) -> 0 | O18: =LEN(N18) -> 0
I19: =LEN(H19) -> 0 | K19: =LEN(J19) -> 0 | M19: 0 | O19: 0
I20: =LEN(H20) -> 0 | K20: =LEN(J20) -> 0 | M20: 0 | O20: 0
I21: =LEN(H21) -> 0 | K21: =LEN(J21) -> 0 | M21: 0 | O21: 0
I22: =LEN(H22) -> 0 | K22: =LEN(J22) -> 0 | M22: 0 | O22: 0
I23: =LEN(H23) -> 0 | K23: =LEN(J23) -> 0 | M23: 0 | O23: 0
I24: =LEN(H24) -> 0 | K24: =LEN(J24) -> 0 | M24: 0 | O24: 0
I25: =LEN(H25) -> 0 | K25: =LEN(J25) -> 0 | M25: 0 | O25: 0
I26: =LEN(H26) -> 0 | K26: =LEN(J26) -> 0 | M26: 0 | O26: 0
I27: =LEN(H27) -> 0 | K27: =LEN(J27) -> 0 | M27: 0 | O27: 0
I28: =LEN(H28) -> 0 | K28: =LEN(J28) -> 0 | M28: 0 | O28: 0
I29: =LEN(H29) -> 0 | K29: =LEN(J29) -> 0 | M29: 0 | O29: 0
I30: =LEN(H30) -> 0 | K30: =LEN(J30) -> 0 | M30: 0 | O30: 0
... I42: =LEN(H42) -> 0 | K42: =LEN(J42) -> 0 | M42: 0 | O42: 0
A43: 插槽
I44: =LEN(H44) -> 0 | K44: =LEN(J44) -> 0 | M44: 0 | O44: 0
I45: =LEN(H45) -> 0 | K45: =LEN(J45) -> 0 | M45: 0 | O45: 0
I46: =LEN(H46) -> 0 | K46: =LEN(J46) -> 0 | M46: 0 | O46: 0
I47: =LEN(H47) -> 0 | K47: =LEN(J47) -> 0 | M47: 0 | O47: 0
I48: =LEN(H48) -> 0 | K48: =LEN(J48) -> 0 | M48: 0 | O48: 0
I49: =LEN(H49) -> 0 | K49: =LEN(J49) -> 0 | M49: 0 | O49: 0
I50: =LEN(H50) -> 0 | K50: =LEN(J50) -> 0 | M50: 0 | O50: 0
I51: =LEN(H51) -> 0 | K51: =LEN(J51) -> 0 | M51: 0 | O51: 0
I52: =LEN(H52) -> 0 | K52: =LEN(J52) -> 0 | M52: 0 | O52: 0
...

Sheet 装置通用
A1: 版本 | B1: Abbr | C1: 创建日期 | D1: 创建人 | E1: 词性备注 | F1: 术语中文释义 | G1: 术语英文释义 | H1: 中文术语 | J1: 英文术语 | L1: 西文术语 | N1: 俄文术语
H2: 术语 | I2: 字符数 | J2: 术语 | K2: 字符数 | L2: 术语 | M2: 字符数 | N2: 术语 | O2: 字符数
A3: 装置型号、名称
A4: =IF(B4="","",IF(A4<>"",A4,#REF!)) -> #VALUE! | B4: feeder_relay | C4: =IF(B4="","",IF(C4<>"",C4,NOW())) -> 44832.439 | D4: 鲍凯鹏 | E4: 名词短语 | G4: Feeder relay | H4: 馈线保护 | I4: =LEN(H4) -> 4 | J4: Feeder relay | K4: =LEN(J4) -> 12 | M4: =LEN(L4) -> 0 | O4: =LEN(N4) -> 0
K5: =LEN(J5) -> 0 | M5: =LEN(L5) -> 0 | O5: =LEN(N5) -> 0
K6: =LEN(J6) -> 0 | M6: =LEN(L6) -> 0 | O6: =LEN(N6) -> 0
K7: =LEN(J7) -> 0 | M7: =LEN(L7) -> 0 | O7: =LEN(N7) -> 0
K8: =LEN(J8) -> 0 | M8: =LEN(L8) -> 0 | O8: =LEN(N8) -> 0
K9: =LEN(J9) -> 0 | M9: =LEN(L9) -> 0 | O9: =LEN(N9) -> 0
A10: =IF(B10="","",IF(A10<>"",A10,#REF!)) | C10: =IF(B10="","",IF(C10<>"",C10,NOW())) | I10: =LEN(H10) -> 0 | K10: =LEN(J10) -> 0 | M10: =LEN(L10) -> 0 | O10: =LEN(N10) -> 0
A11: =IF(B11="","",IF(A11<>"",A11,#REF!)) | C11: =IF(B11="","",IF(C11<>"",C11,NOW())) | I11: =LEN(H11) -> 0 | K11: =LEN(J11) -> 0 | M11: =LEN(L11) -> 0 | O11: =LEN(N11) -> 0
A12: =IF(B12="","",IF(A12<>"",A12,#REF!)) | C12: =IF(B12="","",IF(C12<>"",C12,NOW())) | I12: =LEN(H12) -> 0 | K12: =LEN(J12) -> 0 | M12: =LEN(L12) -> 0 | O12: =LEN(N12) -> 0
A13: =IF(B13="","",IF(A13<>"",A13,#REF!)) | C13: =IF(B13="","",IF(C13<>"",C13,NOW())) | I13: =LEN(H13) -> 0 | K13: =LEN(J13) -> 0 | M13: =LEN(L13) -> 0 | O13: =LEN(N13) -> 0
A14: 装置识别码
A15: =IF(B15="","",IF(A15<>"",A15,#REF!)) | C15: =IF(B15="","",IF(C15<>"",C15,NOW())) | I15: =LEN(H15) -> 0 | K15: =LEN(J15) -> 0 | M15: =LEN(L15) -> 0 | O15: =LEN(N15) -> 0
A16: =IF(B16="","",IF(A16<>"",A16,#REF!)) | C16: =IF(B16="","",IF(C16<>"",C16,NOW())) | I16: =LEN(H16) -> 0 | K16: =LEN(J16) -> 0 | M16: =LEN(L16) -> 0 | O16: =LEN(N16) -> 0
A17: =IF(B17="","",IF(A17<>"",A17,#REF!)) | C17: =IF(B17="","",IF(C17<>"",C17,NOW())) | I17: =LEN(H17) -> 0 | K17: =LEN(J17) -> 0 | M17: =LEN(L17) -> 0 | O17: =LEN(N17) -> 0
A18: =IF(B18="","",IF(A18<>"",A18,#REF!)) | C18: =IF(B18="","",IF(C18<>"",C18,NOW())) | I18: =LEN(H18) -> 0 | K18: =LEN(J18) -> 0 | M18: =LEN(L18) -> 0 | O18: =LEN(N18) -> 0
A19: =IF(B19="","",IF(A19<>"",A19,#REF!)) | C19: =IF(B19="","",IF(C19<>"",C19,NOW())) | I19: =LEN(H19) -> 0 | K19: =LEN(J19) -> 0 | M19: =LEN(L19) -> 0 | O19: =LEN(N19) -> 0
A20: =IF(B20="","",IF(A20<>"",A20,#REF!)) | C20: =IF(B20="","",IF(C20<>"",C20,NOW())) | I20: =LEN(H20) -> 0 | K20: =LEN(J20) -> 0 | M20: =LEN(L20) -> 0 | O20: =LEN(N20) -> 0
A21: =IF(B21="","",IF(A21<>"",A21,#REF!)) | C21: =IF(B21="","",IF(C21<>"",C21,NOW())) | I21: =LEN(H21) -> 0 | K21: =LEN(J21) -> 0 | M21: =LEN(L21) -> 0 | O21: =LEN(N21) -> 0
A22: =IF(B22="","",IF(A22<>"",A22,#REF!)) | C22: =IF(B22="","",IF(C22<>"",C22,NOW())) | I22: =LEN(H22) -> 0 | K22: =LEN(J22) -> 0 | M22: =LEN(L22) -> 0 | O22: =LEN(N22) -> 0
A23: =IF(B23="","",IF(A23<>"",A23,#REF!)) | C23: =IF(B23="","",IF(C23<>"",C23,NOW())) | I23: =LEN(H23) -> 0 | K23: =LEN(J23) -> 0 | M23: =LEN(L23) -> 0 | O23: =LEN(N23) -> 0
A24: =IF(B24="","",IF(A24<>"",A24,#REF!)) | C24: =IF(B24="","",IF(C24<>"",C24,NOW())) | I24: =LEN(H24) -> 0 | K24: =LEN(J24) -> 0 | M24: =LEN(L24) -> 0 | O24: =LEN(N24) -> 0
A25: =IF(B25="","",IF(A25<>"",A25,#REF!)) | C25: =IF(B25="","",IF(C25<>"",C25,NOW())) | I25: =LEN(H25) -> 0 | K25: =LEN(J25) -> 0 | M25: =LEN(L25) -> 0 | O25: =LEN(N25) -> 0
A26: =IF(B26="","",IF(A26<>"",A26,#REF!)) | C26: =IF(B26="","",IF(C26<>"",C26,NOW())) | I26: =LEN(H26) -> 0 | K26: =LEN(J26) -> 0 | M26: =LEN(L26) -> 0 | O26: =LEN(N26) -> 0
... A34: =IF(B34="","",IF(A34<>"",A34,#REF!)) | C34: =IF(B34="","",IF(C34<>"",C34,NOW())) | I34: =LEN(H34) -> 0 | K34: =LEN(J34) -> 0 | M34: =LEN(L34) -> 0 | O34: =LEN(N34) -> 0
A35: 模块版本信息
A36: =IF(B36="","",IF(A36<>"",A36,#REF!)) -> #VALUE! | B36: mod_ver | C36: =IF(B36="","",IF(C36<>"",C36,NOW())) -> 44832.439 | D36: 薛宇 | E36: 名词短语 | F36: 模块版本号 | G36: module version | H36: 模块版本号 | I36: =LEN(H36) -> 5 | J36: Module version | K36: =LEN(J36) -> 14 | M36: =LEN(L36) -> 0 | O36: =LEN(N36) -> 0
K37: =LEN(J37) -> 0 | M37: =LEN(L37) -> 0 | O37: =LEN(N37) -> 0
A38: =IF(B38="","",IF(A38<>"",A38,#REF!)) | C38: =IF(B38="","",IF(C38<>"",C38,NOW())) | I38: =LEN(H38) -> 0 | K38: =LEN(J38) -> 0 | M38: =LEN(L38) -> 0 | O38: =LEN(N38) -> 0
A39: =IF(B39="","",IF(A39<>"",A39,#REF!)) | C39: =IF(B39="","",IF(C39<>"",C39,NOW())) | I39: =LEN(H39) -> 0 | K39: =LEN(J39) -> 0 | M39: =LEN(L39) -> 0 | O39: =LEN(N39) -> 0
A40: =IF(B40="","",IF(A40<>"",A40,#REF!)) | C40: =IF(B40="","",IF(C40<>"",C40,NOW())) | I40: =LEN(H40) -> 0 | K40: =LEN(J40) -> 0 | M40: =LEN(L40) -> 0 | O40: =LEN(N40) -> 0
A41: =IF(B41="","",IF(A41<>"",A41,#REF!)) | C41: =IF(B41="","",IF(C41<>"",C41,NOW())) | I41: =LEN(H41) -> 0 | K41: =LEN(J41) -> 0 | M41: =LEN(L41) -> 0 | O41: =LEN(N41) -> 0
A42: =IF(B42="","",IF(A42<>"",A42,#REF!)) | C42: =IF(B42="","",IF(C42<>"",C42,NOW())) | I42: =LEN(H42) -> 0 | K42: =LEN(J42) -> 0 | M42: =LEN(L42) -> 0 | O42: =LEN(N42) -> 0
A43: =IF(B43="","",IF(A43<>"",A43,#REF!)) | C43: =IF(B43="","",IF(C43<>"",C43,NOW())) | I43: =LEN(H43) -> 0 | K43: =LEN(J43) -> 0 | M43: =LEN(L43) -> 0 | O43: =LEN(N43) -> 0
A44: =IF(B44="","",IF(A44<>"",A44,#REF!)) | C44: =IF(B44="","",IF(C44<>"",C44,NOW())) | I44: =LEN(H44) -> 0 | K44: =LEN(J44) -> 0 | M44: =LEN(L44) -> 0 | O44: =LEN(N44) -> 0
A45: =IF(B45="","",IF(A45<>"",A45,#REF!)) | C45: =IF(B45="","",IF(C45<>"",C45,NOW())) | I45: =LEN(H45) -> 0 | K45: =LEN(J45) -> 0 | M45: =LEN(L45) -> 0 | O45: =LEN(N45) -> 0
A46: =IF(B46="","",IF(A46<>"",A46,#REF!)) | C46: =IF(B46="","",IF(C46<>"",C46,NOW())) | I46: =LEN(H46) -> 0 | K46: =LEN(J46) -> 0 | M46: =LEN(L46) -> 0 | O46: =LEN(N46) -> 0
A47: =IF(B47="","",IF(A47<>"",A47,#REF!)) | C47: =IF(B47="","",IF(C47<>"",C47,NOW())) | I47: =LEN(H47) -> 0 | K47: =LEN(J47) -> 0 | M47: =LEN(L47) -> 0 | O47: =LEN(N47) -> 0
...

Sheet 间隔
A1: 版本 | B1: Abbr | C1: 创建日期 | D1: 创建人 | E1: 词性备注 | F1: 术语中文释义 | G1: 术语英文释义 | H1: 中文术语 | J1: 英文术语 | L1: 西文术语 | N1: 俄文术语
H2: 术语 | I2: 字符数 | J2: 术语 | K2: 字符数 | L2: 术语 | M2: 字符数 | N2: 术语 | O2: 字符数
A3: 统称
A4: =IF(B4="","",IF(A4<>"",A4,#REF!)) -> #VALUE! | B4: bay | C4: =IF(B4="","",IF(C4<>"",C4,NOW())) -> 0 | D4: 刘龙 | E4: 名词短语 | G4: substation bay | H4: 间隔 | I4: =LEN(H4) -> 2 | J4: Bay | K4: =LEN(J4) -> 3 | M4: =LEN(L4) -> 0 | O4: =LEN(N4) -> 0
A5: =IF(B5="","",IF(A5<>"",A5,#REF!)) | C5: =IF(B5="","",IF(C5<>"",C5,NOW())) | I5: =LEN(H5) -> 0 | K5: =LEN(J5) -> 0 | M5: =LEN(L5) -> 0 | O5: =LEN(N5) -> 0
A6: 线路
A7: =IF(B7="","",IF(A7<>"",A7,#REF!)) -> #VALUE! | B7: line | C7: =IF(B7="","",IF(C7<>"",C7,NOW())) -> 0 | D7: 鲍凯鹏 | E7: 名词短语 | G7: line | H7: 线路 | I7: =LEN(H7) -> 2 | J7: Line | K7: =LEN(J7) -> 4 | M7: =LEN(L7) -> 0 | O7: =LEN(N7) -> 0
K8: =LEN(J8) -> 0 | M8: =LEN(L8) -> 0 | O8: =LEN(N8) -> 0
K9: =LEN(J9) -> 0 | M9: =LEN(L9) -> 0 | O9: =LEN(N9) -> 0
A10: =IF(B10="","",IF(A10<>"",A10,#REF!)) | C10: =IF(B10="","",IF(C10<>"",C10,NOW())) | I10: =LEN(H10) -> 0 | K10: =LEN(J10) -> 0 | M10: =LEN(L10) -> 0 | O10: =LEN(N10) -> 0
A11: 断路器
A12: =IF(B12="","",IF(A12<>"",A12,#REF!)) -> #VALUE! | B12: breaker | C12: =IF(B12="","",IF(C12<>"",C12,NOW())) -> 0 | D12: 鲍凯鹏 | E12: 名词短语 | G12: breaker | H12: 断路器 | I12: =LEN(H12) -> 3 | J12: Breaker | K12: =LEN(J12) -> 7 | M12: =LEN(L12) -> 0 | O12: =LEN(N12) -> 0
A13: =IF(B13="","",IF(A13<>"",A13,#REF!)) | C13: =IF(B13="","",IF(C13<>"",C13,NOW())) | I13: =LEN(H13) -> 0 | K13: =LEN(J13) -> 0 | M13: =LEN(L13) -> 0 | O13: =LEN(N13) -> 0
A14: =IF(B14="","",IF(A14<>"",A14,#REF!)) | C14: =IF(B14="","",IF(C14<>"",C14,NOW())) | I14: =LEN(H14) -> 0 | K14: =LEN(J14) -> 0 | M14: =LEN(L14) -> 0 | O14: =LEN(N14) -> 0
A15: =IF(B15="","",IF(A15<>"",A15,#REF!)) | C15: =IF(B15="","",IF(C15<>"",C15,NOW())) | I15: =LEN(H15) -> 0 | K15: =LEN(J15) -> 0 | M15: =LEN(L15) -> 0 | O15: =LEN(N15) -> 0
A16: =IF(B16="","",IF(A16<>"",A16,#REF!)) | C16: =IF(B16="","",IF(C16<>"",C16,NOW())) | I16: =LEN(H16) -> 0 | K16: =LEN(J16) -> 0 | M16: =LEN(L16) -> 0 | O16: =LEN(N16) -> 0
A17: =IF(B17="","",IF(A17<>"",A17,#REF!)) | C17: =IF(B17="","",IF(C17<>"",C17,NOW())) | I17: =LEN(H17) -> 0 | K17: =LEN(J17) -> 0 | M17: =LEN(L17) -> 0 | O17: =LEN(N17) -> 0
A18: =IF(B18="","",IF(A18<>"",A18,#REF!)) | C18: =IF(B18="","",IF(C18<>"",C18,NOW())) | I18: =LEN(H18) -> 0 | K18: =LEN(J18) -> 0 | M18: =LEN(L18) -> 0 | O18: =LEN(N18) -> 0
A19: =IF(B19="","",IF(A19<>"",A19,#REF!)) | C19: =IF(B19="","",IF(C19<>"",C19,NOW())) | I19: =LEN(H19) -> 0 | K19: =LEN(J19) -> 0 | M19: =LEN(L19) -> 0 | O19: =LEN(N19) -> 0
A20: =IF(B20="","",IF(A20<>"",A20,#REF!)) | C20: =IF(B20="","",IF(C20<>"",C20,NOW())) | I20: =LEN(H20) -> 0 | K20: =LEN(J20) -> 0 | M20: =LEN(L20) -> 0 | O20: =LEN(N20) -> 0
A21: =IF(B21="","",IF(A21<>"",A21,#REF!)) | C21: =IF(B21="","",IF(C21<>"",C21,NOW())) | I21: =LEN(H21) -> 0 | K21: =LEN(J21) -> 0 | M21: =LEN(L21) -> 0 | O21: =LEN(N21) -> 0
A22: 刀闸
A23: =IF(B23="","",IF(A23<>"",A23,#REF!)) -> #VALUE! | B23: isolator | C23: =IF(B23="","",IF(C23<>"",C23,NOW())) -> 0 | D23: 鲍凯鹏 | E23: 名词短语 | G23: isolator | H23: 隔离刀闸 | I23: =LEN(H23) -> 4 | J23: Disconnector | K23: =LEN(J23) -> 12 | M23: =LEN(L23) -> 0 | O23: =LEN(N23) -> 0
A24: =IF(B24="","",IF(A24<>"",A24,#REF!)) | C24: =IF(B24="","",IF(C24<>"",C24,NOW())) | I24: =LEN(H24) -> 0 | K24: =LEN(J24) -> 0 | M24: =LEN(L24) -> 0 | O24: =LEN(N24) -> 0
A25: =IF(B25="","",IF(A25<>"",A25,#REF!)) | C25: =IF(B25="","",IF(C25<>"",C25,NOW())) | I25: =LEN(H25) -> 0 | K25: =LEN(J25) -> 0 | M25: =LEN(L25) -> 0 | O25: =LEN(N25) -> 0
A26: =IF(B26="","",IF(A26<>"",A26,#REF!)) | C26: =IF(B26="","",IF(C26<>"",C26,NOW())) | I26: =LEN(H26) -> 0 | K26: =LEN(J26) -> 0 | M26: =LEN(L26) -> 0 | O26: =LEN(N26) -> 0
A27: =IF(B27="","",IF(A27<>"",A27,#REF!)) | C27: =IF(B27="","",IF(C27<>"",C27,NOW())) | I27: =LEN(H27) -> 0 | K27: =LEN(J27) -> 0 | M27: =LEN(L27) -> 0 | O27: =LEN(N27) -> 0
A28: =IF(B28="","",IF(A28<>"",A28,#REF!)) | C28: =IF(B28="","",IF(C28<>"",C28,NOW())) | I28: =LEN(H28) -> 0 | K28: =LEN(J28) -> 0 | M28: =LEN(L28) -> 0 | O28: =LEN(N28) -> 0
A29: =IF(B29="","",IF(A29<>"",A29,#REF!)) | C29: =IF(B29="","",IF(C29<>"",C29,NOW())) | I29: =LEN(H29) -> 0 | K29: =LEN(J29) -> 0 | M29: =LEN(L29) -> 0 | O29: =LEN(N29) -> 0
A30: =IF(B30="","",IF(A30<>"",A30,#REF!)) | C30: =IF(B30="","",IF(C30<>"",C30,NOW())) | I30: =LEN(H30) -> 0 | K30: =LEN(J30) -> 0 | M30: =LEN(L30) -> 0 | O30: =LEN(N30) -> 0
A31: =IF(B31="","",IF(A31<>"",A31,#REF!)) | C31: =IF(B31="","",IF(C31<>"",C31,NOW())) | I31: =LEN(H31) -> 0 | K31: =LEN(J31) -> 0 | M31: =LEN(L31) -> 0 | O31: =LEN(N31) -> 0
A32: =IF(B32="","",IF(A32<>"",A32,#REF!)) | C32: =IF(B32="","",IF(C32<>"",C32,NOW())) | I32: =LEN(H32) -> 0 | K32: =LEN(J32) -> 0 | M32: =LEN(L32) -> 0 | O32: =LEN(N32) -> 0
A33: =IF(B33="","",IF(A33<>"",A33,#REF!)) | C33: =IF(B33="","",IF(C33<>"",C33,NOW())) | I33: =LEN(H33) -> 0 | K33: =LEN(J33) -> 0 | M33: =LEN(L33) -> 0 | O33: =LEN(N33) -> 0
A34: 母线
A35: =IF(B35="","",IF(A35<>"",A35,#REF!)) -> #VALUE! | B35: busbar | C35: =IF(B35="","",IF(C35<>"",C35,NOW())) -> 0 | D35: 鲍凯鹏 | E35: 名词短语 | G35: busbar | H35: 母线 | I35: =LEN(H35) -> 2 | J35: Busbar | K35: =LEN(J35) -> 6 | M35: =LEN(L35) -> 0 | O35: =LEN(N35) -> 0
A36: =IF(B36="","",IF(A36<>"",A36,#REF!)) | C36: =IF(B36="","",IF(C36<>"",C36,NOW())) | I36: =LEN(H36) -> 0 | K36: =LEN(J36) -> 0 | M36: =LEN(L36) -> 0 | O36: =LEN(N36) -> 0
A37: =IF(B37="","",IF(A37<>"",A37,#REF!)) | C37: =IF(B37="","",IF(C37<>"",C37,NOW())) | I37: =LEN(H37) -> 0 | K37: =LEN(J37) -> 0 | M37: =LEN(L37) -> 0 | O37: =LEN(N37) -> 0
A38: =IF(B38="","",IF(A38<>"",A38,#REF!)) | C38: =IF(B38="","",IF(C38<>"",C38,NOW())) | I38: =LEN(H38) -> 0 | K38: =LEN(J38) -> 0 | M38: =LEN(L38) -> 0 | O38: =LEN(N38) -> 0
A39: =IF(B39="","",IF(A39<>"",A39,#REF!)) | C39: =IF(B39="","",IF(C39<>"",C39,NOW())) | I39: =LEN(H39) -> 0 | K39: =LEN(J39) -> 0 | M39: =LEN(L39) -> 0 | O39: =LEN(N39) -> 0
A40: =IF(B40="","",IF(A40<>"",A40,#REF!)) | C40: =IF(B40="","",IF(C40<>"",C40,NOW())) | I40: =LEN(H40) -> 0 | K40: =LEN(J40) -> 0 | M40: =LEN(L40) -> 0 | O40: =LEN(N40) -> 0
...

Sheet 功能名
A1: 版本 | B1: Abbr | C1: 创建日期 | D1: 创建人 | E1: 词性备注 | F1: 术语中文释义 | G1: 术语英文释义 | H1: 中文术语 | J1: 英文术语 | L1: 西文术语 | N1: 俄文术语
H2: 术语 | I2: 字符数 | J2: 术语 | K2: 字符数 | L2: 术语 | M2: 字符数 | N2: 术语 | O2: 字符数
A3: 通用模块
B4: I3PM | C4: 44648 | D4: 罗琴琴 | E4: 名词短语 | G4: three phase current module | H4: 三相电流模块 | I4: =LEN(H4) -> 6 | J4: I3PM | K4: =LEN(功能名!J4) -> 4 | M4: 0 | O4: 0
K5: =LEN(功能名!J5) -> 0 | M5: 0 | O5: 0
K6: =LEN(功能名!J6) -> 0 | M6: 0 | O6: 0
K7: =LEN(功能名!J7) -> 0 | M7: 0 | O7: 0
K8: =LEN(功能名!J8) -> 0 | M8: 0 | O8: 0
K9: =LEN(功能名!J9) -> 0 | M9: 0 | O9: 0
K10: =LEN(功能名!J10) -> 0 | M10: 0 | O10: 0
K11: =LEN(功能名!J11) -> 0 | M11: 0 | O11: 0
I12: =LEN(H12) -> 0 | K12: =LEN(功能名!J12) -> 0 | M12: 0 | O12: 0
I13: =LEN(H13) -> 0 | K13: =LEN(功能名!J13) -> 0 | M13: 0 | O13: 0
I14: =LEN(H14) -> 0 | K14: =LEN(功能名!J14) -> 0 | M14: 0 | O14: 0
I15: =LEN(H15) -> 0 | K15: =LEN(功能名!J15) -> 0 | M15: 0 | O15: 0
I16: =LEN(H16) -> 0 | K16: =LEN(功能名!J16) -> 0 | M16: 0 | O16: 0
I17: =LEN(H17) -> 0 | K17: =LEN(功能名!J17) -> 0 | M17: 0 | O17: 0
I18: =LEN(H18) -> 0 | K18: =LEN(功能名!J18) -> 0 | M18: 0 | O18: 0
I19: =LEN(H19) -> 0 | K19: =LEN(功能名!J19) -> 0 | M19: 0 | O19: 0
I20: =LEN(H20) -> 0 | K20: =LEN(功能名!J20) -> 0 | M20: 0 | O20: 0
I21: =LEN(H21) -> 0 | K21: =LEN(功能名!J21) -> 0 | M21: 0 | O21: 0
A22: 保护功能 | K22: =LEN(功能名!J22) -> 0
A23: 1 | B23: RBRF_50BF | C23: 44630.581 | D23: 刘龙 | E23: 名词短语 | G23: circuit-breaker failure protection | H23: 失灵保护 | I23: =LEN(H23) -> 4 | J23: RBRF_50BF | K23: =LEN(功能名!J23) -> 9 | M23: 0 | O23: 0
K24: =LEN(功能名!J24) -> 0 | M24: 0 | O24: 0
K25: =LEN(功能名!J25) -> 0 | M25: 0 | O25: 0
K26: =LEN(功能名!J26) -> 0 | M26: 0 | O26: 0
K27: =LEN(功能名!J27) -> 0 | M27: 0 | O27: 0
K28: =LEN(功能名!J28) -> 0 | M28: 0 | O28: 0
K29: =LEN(功能名!J29) -> 0 | M29: 0 | O29: 0
K30: =LEN(功能名!J30) -> 0 | M30: 0 | O30: 0
K31: =LEN(功能名!J31) -> 0 | M31: 0 | O31: 0
K32: =LEN(功能名!J32) -> 0 | M32: 0 | O32: 0
K33: =LEN(功能名!J33) -> 0 | M33: 0 | O33: 0
K34: =LEN(功能名!J34) -> 0 | M34: 0 | O34: 0
K35: =LEN(功能名!J35) -> 0 | M35: 0 | O35: 0
K36: =LEN(功能名!J36) -> 0
I37: =LEN(H37) -> 0 | K37: =LEN(功能名!J37) -> 0
A38: 测量功能 | K38: =LEN(功能名!J38) -> 0
K39: =LEN(功能名!J39) -> 0 | M39: 0 | O39: 0
K40: =LEN(功能名!J40) -> 0 | M40: 0 | O40: 0
...

Sheet BI
A1: 版本 | B1: Abbr | C1: 创建日期 | D1: 创建人 | E1: 词性备注 | F1: 术语中文释义 | G1: 术语英文释义 | H1: 中文术语 | J1: 英文术语
H2: 术语 | I2: 字符数 | J2: 术语 | K2: 字符数
A3: 软硬压板
K4: =LEN(J4) -> 0
K5: =LEN(J5) -> 0
K6: =LEN(J6) -> 0
K7: =LEN(J7) -> 0
K8: =LEN(J8) -> 0
A9: =IF(B9="","",IF(A9<>"",A9,#REF!)) | C9: =IF(B9="","",IF(C9<>"",C9,NOW())) | I9: =LEN(H9) -> 0 | K9: =LEN(J9) -> 0
A10: =IF(B10="","",IF(A10<>"",A10,#REF!)) | C10: =IF(B10="","",IF(C10<>"",C10,NOW())) | I10: =LEN(H10) -> 0 | K10: =LEN(J10) -> 0
A11: =IF(B11="","",IF(A11<>"",A11,#REF!)) | C11: =IF(B11="","",IF(C11<>"",C11,NOW())) | I11: =LEN(H11) -> 0 | K11: =LEN(J11) -> 0
A12: =IF(B12="","",IF(A12<>"",A12,#REF!)) | C12: =IF(B12="","",IF(C12<>"",C12,NOW())) | I12: =LEN(H12) -> 0 | K12: =LEN(J12) -> 0
A13: =IF(B13="","",IF(A13<>"",A13,#REF!)) | C13: =IF(B13="","",IF(C13<>"",C13,NOW())) | I13: =LEN(H13) -> 0 | K13: =LEN(J13) -> 0
A14: =IF(B14="","",IF(A14<>"",A14,#REF!)) | C14: =IF(B14="","",IF(C14<>"",C14,NOW())) | I14: =LEN(H14) -> 0 | K14: =LEN(J14) -> 0
A15: 遥信
K16: =LEN(J16) -> 0
K17: =LEN(J17) -> 0
K18: =LEN(J18) -> 0
K19: =LEN(J19) -> 0
K20: =LEN(J20) -> 0
K21: =LEN(J21) -> 0
K22: =LEN(J22) -> 0
K23: =LEN(J23) -> 0
K24: =LEN(J24) -> 0
K25: =LEN(J25) -> 0
K26: =LEN(J26) -> 0
K27: =LEN(J27) -> 0
... K35: =LEN(J35) -> 0
A36: =IF(B36="","",IF(A36<>"",A36,#REF!)) | C36: =IF(B36="","",IF(C36<>"",C36,NOW())) | I36: =LEN(H36) -> 0 | K36: =LEN(J36) -> 0
A37: =IF(B37="","",IF(A37<>"",A37,#REF!)) | C37: =IF(B37="","",IF(C37<>"",C37,NOW())) | I37: =LEN(H37) -> 0 | K37: =LEN(J37) -> 0
A38: 通用保护开入
K39: =LEN(J39) -> 0
K40: =LEN(J40) -> 0
K41: =LEN(J41) -> 0
A42: =IF(B42="","",IF(A42<>"",A42,#REF!)) | C42: =IF(B42="","",IF(C42<>"",C42,NOW())) | I42: =LEN(H42) -> 0 | K42: =LEN(J42) -> 0
A43: =IF(B43="","",IF(A43<>"",A43,#REF!)) | C43: =IF(B43="","",IF(C43<>"",C43,NOW())) | I43: =LEN(H43) -> 0 | K43: =LEN(J43) -> 0
A44: =IF(B44="","",IF(A44<>"",A44,#REF!)) | C44: =IF(B44="","",IF(C44<>"",C44,NOW())) | I44: =LEN(H44) -> 0 | K44: =LEN(J44) -> 0
A45: =IF(B45="","",IF(A45<>"",A45,#REF!)) | C45: =IF(B45="","",IF(C45<>"",C45,NOW())) | I45: =LEN(H45) -> 0 | K45: =LEN(J45) -> 0
A46: =IF(B46="","",IF(A46<>"",A46,#REF!)) | C46: =IF(B46="","",IF(C46<>"",C46,NOW())) | I46: =LEN(H46) -> 0 | K46: =LEN(J46) -> 0
A47: =IF(B47="","",IF(A47<>"",A47,#REF!)) | C47: =IF(B47="","",IF(C47<>"",C47,NOW())) | I47: =LEN(H47) -> 0 | K47: =LEN(J47) -> 0
...

Sheet BO
A1: 版本 | B1: Abbr | C1: 创建日期 | D1: 创建人 | E1: 词性备注 | F1: 术语中文释义 | G1: 术语英文释义 | H1: 中文术语 | J1: 英文术语
H2: 术语 | I2: 字符数 | J2: 术语 | K2: 字符数
A3: 自检信息
K4: =LEN(J4) -> 0
K5: =LEN(J5) -> 0
K6: =LEN(J6) -> 0
K7: =LEN(J7) -> 0
K8: =LEN(J8) -> 0
K9: =LEN(J9) -> 0
K10: =LEN(J10) -> 0
K11: =LEN(J11) -> 0
K12: =LEN(J12) -> 0
K13: =LEN(J13) -> 0
K14: =LEN(J14) -> 0
K15: =LEN(J15) -> 0
... K30: =LEN(J30) -> 0
A31: =IF(B31="","",IF(A31<>"",A31,#REF!)) | C31: =IF(B31="","",IF(C31<>"",C31,NOW())) | I31: =LEN(H31) -> 0 | K31: =LEN(J31) -> 0
A32: =IF(B32="","",IF(A32<>"",A32,#REF!)) | C32: =IF(B32="","",IF(C32<>"",C32,NOW())) | I32: =LEN(H32) -> 0 | K32: =LEN(J32) -> 0
A33: =IF(B33="","",IF(A33<>"",A33,#REF!)) | C33: =IF(B33="","",IF(C33<>"",C33,NOW())) | I33: =LEN(H33) -> 0 | K33: =LEN(J33) -> 0
A34: 变位信息
A35: =IF(B35="","",IF(A35<>"",A35,#REF!)) -> #VALUE! | B35: flg_module_enable | C35: 44688.789 | D35: 赵琦 | E35: 状态 | G35: function of module enable | H35: 模块功能投入 | I35: =LEN(H35) -> 6 | J35: Function enabled | K35: =LEN(J35) -> 16
I87: 0 | K87: =LEN(J87) -> 0
I88: 0 | K88: =LEN(J88) -> 0
I89: 0 | K89: =LEN(J89) -> 0
I90: 0 | K90: =LEN(J90) -> 0
I91: 0 | K91: =LEN(J91) -> 0
I92: 0 | K92: =LEN(J92) -> 0
I93: 0 | K93: =LEN(J93) -> 0
I94: 0 | K94: =LEN(J94) -> 0
A95: =IF(B95="","",IF(A95<>"",A95,#REF!)) | C95: =IF(B95="","",IF(C95<>"",C95,NOW())) | I95: =LEN(H95) -> 0 | K95: =LEN(J95) -> 0
A96: =IF(B96="","",IF(A96<>"",A96,#REF!)) | C96: =IF(B96="","",IF(C96<>"",C96,NOW())) | I96: =LEN(H96) -> 0 | K96: =LEN(J96) -> 0
A97: 动作信息
A98: =IF(B98="","",IF(A98<>"",A98,#REF!)) -> #VALUE! | B98: relay_start | C98: =IF(B98="","",IF(C98<>"",C98,NOW())) -> 0 | D98: 鲍凯鹏 | E98: 动词短语 | G98: relay start | H98: 启动 | I98: =LEN(H98) -> 2 | J98: Start | K98: =LEN(J98) -> 5
I134: =LEN(H134) -> 0 | K134: =LEN(J134) -> 0
I135: =LEN(H135) -> 0 | K135: =LEN(J135) -> 0
I136: =LEN(H136) -> 0 | K136: =LEN(J136) -> 0
A137: 操作报告
A142: =IF(B142="","",IF(A142<>"",A142,#REF!)) -> #VALUE! | B142: gear_stop | C142: 44640 | D142: 赵琦 | E142: 动词短语 | G142: gear stop | H142: 急停 | I142: 2 | J142: Stop tap | K142: =LEN(J142) -> 8
A143: =IF(B143="","",IF(A143<>"",A143,#REF!)) | C143: =IF(B143="","",IF(C143<>"",C143,NOW())) | I143: =LEN(H143) -> 0 | K143: =LEN(J143) -> 0
A144: =IF(B144="","",IF(A144<>"",A144,#REF!)) | C144: =IF(B144="","",IF(C144<>"",C144,NOW())) | I144: =LEN(H144) -> 0 | K144: =LEN(J144) -> 0
...

Sheet AI
A1: 版本 | B1: Abbr | C1: 创建日期 | D1: 创建人 | E1: 词性备注 | F1: 术语中文释义 | G1: 术语英文释义 | H1: 中文术语 | J1: 英文术语
H2: 术语 | I2: 字符数 | J2: 术语 | K2: 字符数
A3: 电压
A4: 1.0 | B4: in_u3p | C4: =IF(B4="","",IF(C4<>"",C4,NOW())) -> 0 | D4: 薛宇 | E4: 名词短语 | F4: 三相电压输入模块 | G4: 3-phase voltage input module | H4: 三相电压输入 | I4: =LEN(H4) -> 6 | J4: U3ph | K4: =LEN(J4) -> 4
A16: =IF(B16="","",IF(A16<>"",A16,#REF!)) | C16: =IF(B16="","",IF(C16<>"",C16,NOW())) | I16: =LEN(H16) -> 0 | K16: =LEN(J16) -> 0
A17: 电流
A26: =IF(B26="","",IF(A26<>"",A26,#REF!)) | C26: =IF(B26="","",IF(C26<>"",C26,NOW())) | I26: =LEN(H26) -> 0 | K26: =LEN(J26) -> 0
A27: =IF(B27="","",IF(A27<>"",A27,#REF!)) | C27: =IF(B27="","",IF(C27<>"",C27,NOW())) | I27: =LEN(H27) -> 0 | K27: =LEN(J27) -> 0
A28: =IF(B28="","",IF(A28<>"",A28,#REF!)) | C28: =IF(B28="","",IF(C28<>"",C28,NOW())) | I28: =LEN(H28) -> 0 | K28: =LEN(J28) -> 0
A29: 其他
A57: =IF(B57="","",IF(A57<>"",A57,#REF!)) | C57: =IF(B57="","",IF(C57<>"",C57,NOW())) | I57: =LEN(H57) -> 0 | K57: =LEN(J57) -> 0
A58: =IF(B58="","",IF(A58<>"",A58,#REF!)) | C58: =IF(B58="","",IF(C58<>"",C58,NOW())) | I58: =LEN(H58) -> 0 | K58: =LEN(J58) -> 0
A59: =IF(B59="","",IF(A59<>"",A59,#REF!)) | C59: =IF(B59="","",IF(C59<>"",C59,NOW())) | I59: =LEN(H59) -> 0 | K59: =LEN(J59) -> 0
A60: =IF(B60="","",IF(A60<>"",A60,#REF!)) | C60: =IF(B60="","",IF(C60<>"",C60,NOW())) | I60: =LEN(H60) -> 0 | K60: =LEN(J60) -> 0
A61: =IF(B61="","",IF(A61<>"",A61,#REF!)) | C61: =IF(B61="","",IF(C61<>"",C61,NOW())) | I61: =LEN(H61) -> 0 | K61: =LEN(J61) -> 0
A62: =IF(B62="","",IF(A62<>"",A62,#REF!)) | C62: =IF(B62="","",IF(C62<>"",C62,NOW())) | I62: =LEN(H62) -> 0 | K62: =LEN(J62) -> 0
A63: =IF(B63="","",IF(A63<>"",A63,#REF!)) | C63: =IF(B63="","",IF(C63<>"",C63,NOW())) | I63: =LEN(H63) -> 0 | K63: =LEN(J63) -> 0
A64: =IF(B64="","",IF(A64<>"",A64,#REF!)) | C64: =IF(B64="","",IF(C64<>"",C64,NOW())) | I64: =LEN(H64) -> 0 | K64: =LEN(J64) -> 0
A65: =IF(B65="","",IF(A65<>"",A65,#REF!)) | C65: =IF(B65="","",IF(C65<>"",C65,NOW())) | I65: =LEN(H65) -> 0 | K65: =LEN(J65) -> 0
A66: =IF(B66="","",IF(A66<>"",A66,#REF!)) | C66: =IF(B66="","",IF(C66<>"",C66,NOW())) | I66: =LEN(H66) -> 0 | K66: =LEN(J66) -> 0
A67: =IF(B67="","",IF(A67<>"",A67,#REF!)) | C67: =IF(B67="","",IF(C67<>"",C67,NOW())) | I67: =LEN(H67) -> 0 | K67: =LEN(J67) -> 0
A68: =IF(B68="","",IF(A68<>"",A68,#REF!)) | C68: =IF(B68="","",IF(C68<>"",C68,NOW())) | I68: =LEN(H68) -> 0 | K68: =LEN(J68) -> 0
... A1144: =IF(B1144="","",IF(A1144<>"",A1144,#REF!)) | C1144: =IF(B1144="","",IF(C1144<>"",C1144,NOW())) | I1144: =LEN(H1144) -> 0 | K1144: =LEN(J1144) -> 0
C1145: =IF(B1145="","",IF(C1145<>"",C1145,NOW())) | I1145: =LEN(H1145) -> 0 | K1145: =LEN(J1145) -> 0
I1146: =LEN(H1146) -> 0 | K1146: =LEN(J1146) -> 0
I1147: =LEN(H1147) -> 0 | K1147: =LEN(J1147) -> 0
I1148: =LEN(H1148) -> 0 | K1148: =LEN(J1148) -> 0

Sheet AO
A1: 版本 | B1: Abbr | C1: 创建日期 | D1: 创建人 | E1: 词性备注 | F1: 术语中文释义 | G1: 术语英文释义 | H1: 中文术语 | J1: 英文术语 | L1: ABB类全驼峰 | N1: 展开（缩写采用单驼峰,首字母大写） | P1: 单多驼峰搭配下划线（继保类似）
H2: 术语 | I2: 字符数 | J2: 术语 | K2: 字符数 | L2: 术语 | M2: 字符数 | N2: 术语 | O2: 字符数 | P2: 术语 | Q2: 字符数
A3: 频率
A4: 1.0 | B4: freq | C4: =IF(B4="","",IF(C4<>"",C4,NOW())) -> 44832.439 | D4: 赵琦 | E4: 名词短语 | G4: frequency | H4: 频率 | I4: =LEN(H4) -> 2 | J4: f | K4: =LEN(J4) -> 1 | L4: f | M4: =LEN(L4) -> 1 | N4: Frequency | O4: =LEN(N4) -> 9 | P4: f | Q4: =LEN(P4) -> 1
A9: 电压
A39: 电流
A65: 相角
A80: =IF(B80="","",IF(A80<>"",A80,#REF!)) | C80: =IF(B80="","",IF(C80<>"",C80,NOW())) | I80: =LEN(H80) -> 0 | K80: =LEN(J80) -> 0 | M80: =LEN(L80) -> 0 | O80: =LEN(N80) -> 0 | Q80: =LEN(P80) -> 0
A81: =IF(B81="","",IF(A81<>"",A81,#REF!)) | C81: =IF(B81="","",IF(C81<>"",C81,NOW())) | I81: =LEN(H81) -> 0 | K81: =LEN(J81) -> 0 | M81: =LEN(L81) -> 0 | O81: =LEN(N81) -> 0 | Q81: =LEN(P81) -> 0
A82: =IF(B82="","",IF(A82<>"",A82,#REF!)) | C82: =IF(B82="","",IF(C82<>"",C82,NOW())) | I82: =LEN(H82) -> 0 | K82: =LEN(J82) -> 0 | M82: =LEN(L82) -> 0 | O82: =LEN(N82) -> 0 | Q82: =LEN(P82) -> 0
A83: =IF(B83="","",IF(A83<>"",A83,#REF!)) | C83: =IF(B83="","",IF(C83<>"",C83,NOW())) | I83: =LEN(H83) -> 0 | K83: =LEN(J83) -> 0 | M83: =LEN(L83) -> 0 | O83: =LEN(N83) -> 0 | Q83: =LEN(P83) -> 0
A84: =IF(B84="","",IF(A84<>"",A84,#REF!)) | C84: =IF(B84="","",IF(C84<>"",C84,NOW())) | I84: =LEN(H84) -> 0 | K84: =LEN(J84) -> 0 | M84: =LEN(L84) -> 0 | O84: =LEN(N84) -> 0 | Q84: =LEN(P84) -> 0
A85: =IF(B85="","",IF(A85<>"",A85,#REF!)) | C85: =IF(B85="","",IF(C85<>"",C85,NOW())) | I85: =LEN(H85) -> 0 | K85: =LEN(J85) -> 0 | M85: =LEN(L85) -> 0 | O85: =LEN(N85) -> 0 | Q85: =LEN(P85) -> 0
A86: =IF(B86="","",IF(A86<>"",A86,#REF!)) | C86: =IF(B86="","",IF(C86<>"",C86,NOW())) | I86: =LEN(H86) -> 0 | K86: =LEN(J86) -> 0 | M86: =LEN(L86) -> 0 | O86: =LEN(N86) -> 0 | Q86: =LEN(P86) -> 0
A87: =IF(B87="","",IF(A87<>"",A87,#REF!)) | C87: =IF(B87="","",IF(C87<>"",C87,NOW())) | I87: =LEN(H87) -> 0 | K87: =LEN(J87) -> 0 | M87: =LEN(L87) -> 0 | O87: =LEN(N87) -> 0 | Q87: =LEN(P87) -> 0
A88: =IF(B88="","",IF(A88<>"",A88,#REF!)) | C88: =IF(B88="","",IF(C88<>"",C88,NOW())) | I88: =LEN(H88) -> 0 | K88: =LEN(J88) -> 0 | M88: =LEN(L88) -> 0 | O88: =LEN(N88) -> 0 | Q88: =LEN(P88) -> 0
A89: =IF(B89="","",IF(A89<>"",A89,#REF!)) | C89: =IF(B89="","",IF(C89<>"",C89,NOW())) | I89: =LEN(H89) -> 0 | K89: =LEN(J89) -> 0 | M89: =LEN(L89) -> 0 | O89: =LEN(N89) -> 0 | Q89: =LEN(P89) -> 0
A90: =IF(B90="","",IF(A90<>"",A90,#REF!)) | C90: =IF(B90="","",IF(C90<>"",C90,NOW())) | I90: =LEN(H90) -> 0 | K90: =LEN(J90) -> 0 | M90: =LEN(L90) -> 0 | O90: =LEN(N90) -> 0 | Q90: =LEN(P90) -> 0
A91: =IF(B91="","",IF(A91<>"",A91,#REF!)) | C91: =IF(B91="","",IF(C91<>"",C91,NOW())) | I91: =LEN(H91) -> 0 | K91: =LEN(J91) -> 0 | M91: =LEN(L91) -> 0 | O91: =LEN(N91) -> 0 | Q91: =LEN(P91) -> 0
A92: =IF(B92="","",IF(A92<>"",A92,#REF!)) | C92: =IF(B92="","",IF(C92<>"",C92,NOW())) | I92: =LEN(H92) -> 0 | K92: =LEN(J92) -> 0 | M92: =LEN(L92) -> 0 | O92: =LEN(N92) -> 0 | Q92: =LEN(P92) -> 0
A93: 功率
A118: =IF(B118="","",IF(A118<>"",A118,#REF!)) | C118: =IF(B118="","",IF(C118<>"",C118,NOW())) | I118: =LEN(H118) -> 0 | K118: =LEN(J118) -> 0 | M118: =LEN(L118) -> 0 | O118: =LEN(N118) -> 0 | Q118: =LEN(P118) -> 0
A119: =IF(B119="","",IF(A119<>"",A119,#REF!)) | C119: =IF(B119="","",IF(C119<>"",C119,NOW())) | I119: =LEN(H119) -> 0 | K119: =LEN(J119) -> 0 | M119: =LEN(L119) -> 0 | O119: =LEN(N119) -> 0 | Q119: =LEN(P119) -> 0
A120: =IF(B120="","",IF(A120<>"",A120,#REF!)) | C120: =IF(B120="","",IF(C120<>"",C120,NOW())) | I120: =LEN(H120) -> 0 | K120: =LEN(J120) -> 0 | M120: =LEN(L120) -> 0 | O120: =LEN(N120) -> 0 | Q120: =LEN(P120) -> 0
A121: 电量
A145: =IF(B145="","",IF(A145<>"",A145,#REF!)) | C145: =IF(B145="","",IF(C145<>"",C145,NOW())) | K145: =LEN(J145) -> 0 | M145: =LEN(L145) -> 0 | O145: =LEN(N145) -> 0 | Q145: =LEN(P145) -> 0
A146: =IF(B146="","",IF(A146<>"",A146,#REF!)) | C146: =IF(B146="","",IF(C146<>"",C146,NOW())) | K146: =LEN(J146) -> 0 | M146: =LEN(L146) -> 0 | O146: =LEN(N146) -> 0 | Q146: =LEN(P146) -> 0
A147: 保护控制功能输出
A156: =IF(B156="","",IF(A156<>"",A156,#REF!)) | C156: =IF(B156="","",IF(C156<>"",C156,NOW())) | I156: =LEN(H156) -> 0 | K156: =LEN(J156) -> 0 | M156: =LEN(L156) -> 0 | O156: =LEN(N156) -> 0 | Q156: =LEN(P156) -> 0
A157: =IF(B157="","",IF(A157<>"",A157,#REF!)) | C157: =IF(B157="","",IF(C157<>"",C157,NOW())) | I157: =LEN(H157) -> 0 | K157: =LEN(J157) -> 0 | M157: =LEN(L157) -> 0 | O157: =LEN(N157) -> 0 | Q157: =LEN(P157) -> 0
A158: =IF(B158="","",IF(A158<>"",A158,#REF!)) | C158: =IF(B158="","",IF(C158<>"",C158,NOW())) | I158: =LEN(H158) -> 0 | K158: =LEN(J158) -> 0 | M158: =LEN(L158) -> 0 | O158: =LEN(N158) -> 0 | Q158: =LEN(P158) -> 0
A160: =IF(B160="","",IF(A160<>"",A160,#REF!)) | C160: =IF(B160="","",IF(C160<>"",C160,NOW())) | I160: =LEN(H160) -> 0 | K160: =LEN(J160) -> 0 | M160: =LEN(L160) -> 0 | O160: =LEN(N160) -> 0 | Q160: =LEN(P160) -> 0
A161: =IF(B161="","",IF(A161<>"",A161,#REF!)) | C161: =IF(B161="","",IF(C161<>"",C161,NOW())) | I161: =LEN(H161) -> 0 | K161: =LEN(J161) -> 0 | M161: =LEN(L161) -> 0 | O161: =LEN(N161) -> 0 | Q161: =LEN(P161) -> 0
I162: =LEN(H162) -> 0 | K162: =LEN(J162) -> 0 | M162: =LEN(L162) -> 0 | O162: =LEN(N162) -> 0 | Q162: =LEN(P162) -> 0
I163: =LEN(H163) -> 0 | K163: =LEN(J163) -> 0 | M163: =LEN(L163) -> 0 | O163: =LEN(N163) -> 0 | Q163: =LEN(P163) -> 0
I164: =LEN(H164) -> 0 | K164: =LEN(J164) -> 0 | M164: =LEN(L164) -> 0 | O164: =LEN(N164) -> 0 | Q164: =LEN(P164) -> 0
I165: =LEN(H165) -> 0 | K165: =LEN(J165) -> 0 | M165: =LEN(L165) -> 0 | O165: =LEN(N165) -> 0 | Q165: =LEN(P165) -> 0
I166: =LEN(H166) -> 0 | K166: =LEN(J166) -> 0 | M166: =LEN(L166) -> 0 | O166: =LEN(N166) -> 0 | Q166: =LEN(P166) -> 0
I167: =LEN(H167) -> 0 | K167: =LEN(J167) -> 0 | M167: =LEN(L167) -> 0 | O167: =LEN(N167) -> 0 | Q167: =LEN(P167) -> 0
A168: =IF(B168="","",IF(A168<>"",A168,#REF!)) | C168: =IF(B168="","",IF(C168<>"",C168,NOW())) | I168: =LEN(H168) -> 0 | K168: =LEN(J168) -> 0 | M168: =LEN(L168) -> 0 | O168: =LEN(N168) -> 0 | Q168: =LEN(P168) -> 0
...

Sheet 功能定值
A1: 版本 | B1: Abbr | C1: 创建日期 | D1: 创建人 | E1: 词性备注 | F1: 术语中文释义 | G1: 术语英文释义 | H1: 中文术语 | J1: 英文术语 | L1: ABB类全驼峰 | N1: 展开（缩写采用单驼峰,首字母大写） | P1: 单多驼峰搭配下划线（继保类似） | R1: 展开（缩写可采用单/多驼峰）
H2: 术语 | I2: 字符数 | J2: 术语 | K2: 字符数 | L2: 术语 | M2: 字符数 | N2: 术语 | O2: 字符数 | P2: 术语 | Q2: 字符数 | R2: 术语 | S2: 字符数
A3: 装置参数
O4: =LEN(N4) -> 0 | Q4: =LEN(P4) -> 0 | S4: =LEN(R4) -> 0
O5: =LEN(N5) -> 0 | Q5: =LEN(P5) -> 0 | S5: =LEN(R5) -> 0
O6: =LEN(N6) -> 0 | Q6: =LEN(P6) -> 0 | S6: =LEN(R6) -> 0
O7: =LEN(N7) -> 0 | Q7: =LEN(P7) -> 0 | S7: =LEN(R7) -> 0
O8: =LEN(N8) -> 0 | Q8: =LEN(P8) -> 0 | S8: =LEN(R8) -> 0
O9: =LEN(N9) -> 0 | Q9: =LEN(P9) -> 0 | S9: =LEN(R9) -> 0
O10: =LEN(N10) -> 0 | Q10: =LEN(P10) -> 0 | S10: =LEN(R10) -> 0
O11: =LEN(N11) -> 0 | Q11: =LEN(P11) -> 0 | S11: =LEN(R11) -> 0
O12: =LEN(N12) -> 0 | Q12: =LEN(P12) -> 0 | S12: =LEN(R12) -> 0
O13: =LEN(N13) -> 0 | Q13: =LEN(P13) -> 0 | S13: =LEN(R13) -> 0
O14: =LEN(N14) -> 0 | Q14: =LEN(P14) -> 0 | S14: =LEN(R14) -> 0
O15: =LEN(N15) -> 0 | Q15: =LEN(P15) -> 0 | S15: =LEN(R15) -> 0
... O17: =LEN(N17) -> 0 | Q17: =LEN(P17) -> 0 | S17: =LEN(R17) -> 0
A18: =IF(B18="","",IF(A18<>"",A18,#REF!)) | C18: =IF(B18="","",IF(C18<>"",C18,NOW())) | I18: =LEN(H18) -> 0 | K18: =LEN(J18) -> 0 | M18: =LEN(L18) -> 0 | O18: =LEN(N18) -> 0 | Q18: =LEN(P18) -> 0 | S18: =LEN(R18) -> 0
A19: =IF(B19="","",IF(A19<>"",A19,#REF!)) | C19: =IF(B19="","",IF(C19<>"",C19,NOW())) | I19: =LEN(H19) -> 0 | K19: =LEN(J19) -> 0 | M19: =LEN(L19) -> 0 | O19: =LEN(N19) -> 0 | Q19: =LEN(P19) -> 0 | S19: =LEN(R19) -> 0
A20: 设备参数
A35: =IF(B35="","",IF(A35<>"",A35,#REF!)) | C35: =IF(B35="","",IF(C35<>"",C35,NOW())) | I35: =LEN(H35) -> 0 | K35: =LEN(J35) -> 0 | M35: =LEN(L35) -> 0 | O35: =LEN(N35) -> 0 | Q35: =LEN(P35) -> 0 | S35: =LEN(R35) -> 0
A36: 通用
I59: 0 | K59: =LEN(J59) -> 0 | M59: =LEN(L59) -> 0 | O59: =LEN(N59) -> 0 | Q59: =LEN(P59) -> 0 | S59: =LEN(R59) -> 0
A60: =IF(B60="","",IF(A60<>"",A60,#REF!)) | C60: =IF(B60="","",IF(C60<>"",C60,NOW())) | I60: =LEN(H60) -> 0 | K60: =LEN(J60) -> 0 | M60: =LEN(L60) -> 0 | O60: =LEN(N60) -> 0 | Q60: =LEN(P60) -> 0 | S60: =LEN(R60) -> 0
A61: 过流保护
A62: 1.0 | B62: set_harmblk_ratio | C62: =IF(B62="","",IF(C62<>"",C62,NOW())) -> 44832.439 | D62: 赵成虎 | E62: 名词短语 | G62: second harmonic blocking value | H62: 谐波闭锁定值 | I62: =LEN(H62) -> 6 | J62: Hm2> block value | K62: =LEN(J62) -> 16 | L62: BlkValOverHm2 | M62: =LEN(功能定值!L62) -> 13 | N62: Hm2> Block Value | O62: =LEN(N62) -> 16 | P62: BlkVal_OverHm2 | Q62: =LEN(P62) -> 14 | R62: Hm2> BlockValue | S62: =LEN(R62) -> 15
I89: =LEN(H89) -> 0 | K89: =LEN(J89) -> 0 | M89: =LEN(L89) -> 0 | O89: =LEN(N89) -> 0 | Q89: =LEN(P89) -> 0 | S89: =LEN(R89) -> 0
A90: 过压/欠压保护
A91: =IF(B91="","",IF(A91<>"",A91,#REF!)) -> #VALUE! | B91: set_voltsel | C91: =IF(B91="","",IF(C91<>"",C91,NOW())) -> 44832.439 | D91: 曹义 | G91: select phase or phase to phase voltage | H91: 相/线选择 | I91: =LEN(H91) -> 5 | J91: Option of measured value | K91: =LEN(J91) -> 24 | L91: OptionMeasuredValue | M91: =LEN(L91) -> 19 | N91: Option of Meas Value | O91: =LEN(N91) -> 20 | P91: Option_MeasValue | Q91: =LEN(P91) -> 16 | R91: Option of MeasValue | S91: =LEN(R91) -> 19
S92: =LEN(R92) -> 0
S93: =LEN(R93) -> 0
S94: =LEN(R94) -> 0
S95: =LEN(R95) -> 0
S96: =LEN(R96) -> 0
S97: =LEN(R97) -> 0
A98: =IF(B98="","",IF(A98<>"",A98,#REF!)) | I98: =LEN(H98) -> 0 | K98: =LEN(J98) -> 0 | M98: =LEN(L98) -> 0 | O98: =LEN(N98) -> 0 | Q98: =LEN(P98) -> 0 | S98: =LEN(R98) -> 0
A99: 热过负荷保护
S100: =LEN(R100) -> 0
S101: =LEN(R101) -> 0
S102: =LEN(R102) -> 0
S103: =LEN(R103) -> 0
...

Sheet 应用申请的菜单
A1: 版本 | B1: Abbr | C1: 创建日期 | D1: 创建人 | E1: 词性备注 | F1: 术语中文释义 | G1: 术语英文释义 | H1: 中文术语 | J1: 英文术语 | L1: 西文术语 | N1: 俄文术语
H2: 术语 | I2: 字符数 | J2: 术语 | K2: 字符数 | L2: 术语 | M2: 字符数 | N2: 术语 | O2: 字符数
M3: =LEN(L3) -> 0 | O3: =LEN(N3) -> 0
M4: =LEN(L4) -> 0 | O4: =LEN(N4) -> 0
M5: =LEN(L5) -> 0 | O5: =LEN(N5) -> 0
M6: =LEN(L6) -> 0 | O6: =LEN(N6) -> 0
M7: =LEN(L7) -> 0 | O7: =LEN(N7) -> 0
M8: =LEN(L8) -> 0 | O8: =LEN(N8) -> 0
M9: =LEN(L9) -> 0 | O9: =LEN(N9) -> 0
M10: =LEN(L10) -> 0 | O10: =LEN(N10) -> 0
M11: =LEN(L11) -> 0 | O11: =LEN(N11) -> 0
M12: =LEN(L12) -> 0 | O12: =LEN(N12) -> 0
M13: =LEN(L13) -> 0 | O13: =LEN(N13) -> 0
M14: =LEN(L14) -> 0 | O14: =LEN(N14) -> 0
... M89: =LEN(L89) -> 0 | O89: =LEN(N89) -> 0
A90: =IF(B90="","",IF(A90<>"",A90,#REF!)) | C90: =IF(B90="","",IF(C90<>"",C90,NOW())) | I90: =LEN(H90) -> 0 | K90: =LEN(J90) -> 0 | M90: =LEN(L90) -> 0 | O90: =LEN(N90) -> 0
A91: =IF(B91="","",IF(A91<>"",A91,#REF!)) | C91: =IF(B91="","",IF(C91<>"",C91,NOW())) | I91: =LEN(H91) -> 0 | K91: =LEN(J91) -> 0 | M91: =LEN(L91) -> 0 | O91: =LEN(N91) -> 0
A92: =IF(B92="","",IF(A92<>"",A92,#REF!)) | C92: =IF(B92="","",IF(C92<>"",C92,NOW())) | I92: =LEN(H92) -> 0 | K92: =LEN(J92) -> 0 | M92: =LEN(L92) -> 0 | O92: =LEN(N92) -> 0
A93: =IF(B93="","",IF(A93<>"",A93,#REF!)) | C93: =IF(B93="","",IF(C93<>"",C93,NOW())) | I93: =LEN(H93) -> 0 | K93: =LEN(J93) -> 0 | M93: =LEN(L93) -> 0 | O93: =LEN(N93) -> 0
A94: =IF(B94="","",IF(A94<>"",A94,#REF!)) | C94: =IF(B94="","",IF(C94<>"",C94,NOW())) | I94: =LEN(H94) -> 0 | K94: =LEN(J94) -> 0 | M94: =LEN(L94) -> 0 | O94: =LEN(N94) -> 0
A95: =IF(B95="","",IF(A95<>"",A95,#REF!)) | C95: =IF(B95="","",IF(C95<>"",C95,NOW())) | I95: =LEN(H95) -> 0 | K95: =LEN(J95) -> 0 | M95: =LEN(L95) -> 0 | O95: =LEN(N95) -> 0
A96: =IF(B96="","",IF(A96<>"",A96,#REF!)) | C96: =IF(B96="","",IF(C96<>"",C96,NOW())) | I96: =LEN(H96) -> 0 | K96: =LEN(J96) -> 0 | M96: =LEN(L96) -> 0 | O96: =LEN(N96) -> 0
A97: =IF(B97="","",IF(A97<>"",A97,#REF!)) | C97: =IF(B97="","",IF(C97<>"",C97,NOW())) | I97: =LEN(H97) -> 0 | K97: =LEN(J97) -> 0 | M97: =LEN(L97) -> 0 | O97: =LEN(N97) -> 0
A98: =IF(B98="","",IF(A98<>"",A98,#REF!)) | C98: =IF(B98="","",IF(C98<>"",C98,NOW())) | I98: =LEN(H98) -> 0 | K98: =LEN(J98) -> 0 | M98: =LEN(L98) -> 0 | O98: =LEN(N98) -> 0
A99: =IF(B99="","",IF(A99<>"",A99,#REF!)) | C99: =IF(B99="","",IF(C99<>"",C99,NOW())) | I99: =LEN(H99) -> 0 | K99: =LEN(J99) -> 0 | M99: =LEN(L99) -> 0 | O99: =LEN(N99) -> 0
A100: =IF(B100="","",IF(A100<>"",A100,#REF!)) | C100: =IF(B100="","",IF(C100<>"",C100,NOW())) | I100: =LEN(H100) -> 0 | K100: =LEN(J100) -> 0 | M100: =LEN(L100) -> 0 | O100: =LEN(N100) -> 0
A101: =IF(B101="","",IF(A101<>"",A101,#REF!)) | C101: =IF(B101="","",IF(C101<>"",C101,NOW())) | I101: =LEN(H101) -> 0 | K101: =LEN(J101) -> 0 | M101: =LEN(L101) -> 0 | O101: =LEN(N101) -> 0
... A1198: =IF(B1198="","",IF(A1198<>"",A1198,#REF!)) | C1198: =IF(B1198="","",IF(C1198<>"",C1198,NOW())) | I1198: =LEN(H1198) -> 0 | K1198: =LEN(J1198) -> 0 | M1198: =LEN(L1198) -> 0 | O1198: =LEN(N1198) -> 0
C1199: =IF(B1199="","",IF(C1199<>"",C1199,NOW())) | I1199: =LEN(H1199) -> 0 | K1199: =LEN(J1199) -> 0 | M1199: =LEN(L1199) -> 0 | O1199: =LEN(N1199) -> 0
I1200: =LEN(H1200) -> 0 | K1200: =LEN(J1200) -> 0 | M1200: =LEN(L1200) -> 0 | O1200: =LEN(N1200) -> 0
I1201: =LEN(H1201) -> 0 | K1201: =LEN(J1201) -> 0 | M1201: =LEN(L1201) -> 0 | O1201: =LEN(N1201) -> 0
I1202: =LEN(H1202) -> 0 | K1202: =LEN(J1202) -> 0 | M1202: =LEN(L1202) -> 0 | O1202: =LEN(N1202) -> 0

Sheet 枚举量
A1: 版本 | B1: Abbr | C1: 创建日期 | D1: 创建人 | E1: 词性备注 | F1: 术语中文释义 | G1: 术语英文释义 | H1: 中文术语 | J1: 小写英文术语（不含缩写） | L1: ABB类全驼峰 | N1: 展开（缩写采用单驼峰,首字母大写）
H2: 术语 | I2: 字符数 | J2: 术语 | K2: 字符数 | L2: 术语 | M2: 字符数 | N2: 术语 | O2: 字符数
A3: 参数/定值枚举量 | I3: 0 | K3: 0 | M3: 0 | O3: 0
I4: =LEN(H4) -> 0 | K4: =LEN(J4) -> 0 | M4: 0 | O4: =LEN(N4) -> 0
O5: =LEN(N5) -> 0
O6: =LEN(N6) -> 0
O7: =LEN(N7) -> 0
O8: =LEN(N8) -> 0
O9: =LEN(N9) -> 0
O10: =LEN(N10) -> 0
O11: =LEN(N11) -> 0
O12: =LEN(N12) -> 0
O13: =LEN(N13) -> 0
O14: =LEN(N14) -> 0
O15: =LEN(N15) -> 0
O16: =LEN(N16) -> 0
... O143: =LEN(N143) -> 0
A144: BI/BO枚举量 | I144: 0 | K144: 0 | M144: =LEN(L144) -> 0 | O144: 0
I145: 0 | K145: 0 | M145: =LEN(L145) -> 0 | O145: 0
I146: 0 | K146: 0 | M146: =LEN(L146) -> 0 | O146: 0
I147: 0 | K147: 0 | M147: =LEN(L147) -> 0 | O147: 0
I148: 0 | K148: 0 | M148: =LEN(L148) -> 0 | O148: 0
I149: 0 | K149: 0 | M149: =LEN(L149) -> 0 | O149: 0
I150: 0 | K150: 0 | M150: =LEN(L150) -> 0 | O150: 0
I151: 0 | K151: 0 | M151: =LEN(L151) -> 0 | O151: 0
I152: 0 | K152: 0 | M152: =LEN(L152) -> 0 | O152: 0
I153: 0 | K153: 0 | M153: =LEN(L153) -> 0 | O153: 0
I154: 0 | K154: 0 | M154: =LEN(L154) -> 0 | O154: 0
I155: 0 | K155: 0 | M155: =LEN(L155) -> 0 | O155: 0
I156: 0 | K156: 0 | M156: =LEN(L156) -> 0 | O156: 0
I157: 0 | K157: 0 | M157: 0 | O157: 0
I158: 0 | K158: 0 | M158: 0 | O158: 0
I159: 0 | K159: 0 | M159: 0 | O159: 0
I160: 0 | K160: 0 | M160: 0 | O160: 0
I161: 0 | K161: 0 | M161: 0 | O161: 0
I162: 0 | K162: 0 | M162: 0 | O162: 0
I163: 0 | K163: 0 | M163: 0 | O163: 0
I164: 0 | K164: 0 | M164: 0 | O164: 0
I165: 0 | K165: 0 | M165: 0 | O165: 0
I166: 0 | K166: 0 | M166: 0 | O166: 0
...

Sheet 品质位
A1: 版本 | B1: Abbr | C1: 创建日期 | D1: 创建人 | E1: 词性备注 | F1: 术语中文释义 | G1: 术语英文释义 | H1: 中文术语 | J1: 英文术语 | L1: 西文术语 | N1: 俄文术语
H2: 术语 | I2: 字符数 | J2: 术语 | K2: 字符数 | L2: 术语 | M2: 字符数 | N2: 术语 | O2: 字符数
A3: =IF(B3="","",IF(A3<>"",A3,#REF!)) | C3: =IF(B3="","",IF(C3<>"",C3,NOW())) | I3: =LEN(H3) -> 0 | K3: =LEN(J3) -> 0 | M3: =LEN(L3) -> 0 | O3: =LEN(N3) -> 0
A4: =IF(B4="","",IF(A4<>"",A4,#REF!)) | C4: =IF(B4="","",IF(C4<>"",C4,NOW())) | I4: =LEN(H4) -> 0 | K4: =LEN(J4) -> 0 | M4: =LEN(L4) -> 0 | O4: =LEN(N4) -> 0
A5: =IF(B5="","",IF(A5<>"",A5,#REF!)) | C5: =IF(B5="","",IF(C5<>"",C5,NOW())) | I5: =LEN(H5) -> 0 | K5: =LEN(J5) -> 0 | M5: =LEN(L5) -> 0 | O5: =LEN(N5) -> 0
A6: =IF(B6="","",IF(A6<>"",A6,#REF!)) | C6: =IF(B6="","",IF(C6<>"",C6,NOW())) | I6: =LEN(H6) -> 0 | K6: =LEN(J6) -> 0 | M6: =LEN(L6) -> 0 | O6: =LEN(N6) -> 0
A7: =IF(B7="","",IF(A7<>"",A7,#REF!)) | C7: =IF(B7="","",IF(C7<>"",C7,NOW())) | I7: =LEN(H7) -> 0 | K7: =LEN(J7) -> 0 | M7: =LEN(L7) -> 0 | O7: =LEN(N7) -> 0
A8: =IF(B8="","",IF(A8<>"",A8,#REF!)) | C8: =IF(B8="","",IF(C8<>"",C8,NOW())) | I8: =LEN(H8) -> 0 | K8: =LEN(J8) -> 0 | M8: =LEN(L8) -> 0 | O8: =LEN(N8) -> 0
A9: =IF(B9="","",IF(A9<>"",A9,#REF!)) | C9: =IF(B9="","",IF(C9<>"",C9,NOW())) | I9: =LEN(H9) -> 0 | K9: =LEN(J9) -> 0 | M9: =LEN(L9) -> 0 | O9: =LEN(N9) -> 0
A10: =IF(B10="","",IF(A10<>"",A10,#REF!)) | C10: =IF(B10="","",IF(C10<>"",C10,NOW())) | I10: =LEN(H10) -> 0 | K10: =LEN(J10) -> 0 | M10: =LEN(L10) -> 0 | O10: =LEN(N10) -> 0
A11: =IF(B11="","",IF(A11<>"",A11,#REF!)) | C11: =IF(B11="","",IF(C11<>"",C11,NOW())) | I11: =LEN(H11) -> 0 | K11: =LEN(J11) -> 0 | M11: =LEN(L11) -> 0 | O11: =LEN(N11) -> 0
A12: =IF(B12="","",IF(A12<>"",A12,#REF!)) | C12: =IF(B12="","",IF(C12<>"",C12,NOW())) | I12: =LEN(H12) -> 0 | K12: =LEN(J12) -> 0 | M12: =LEN(L12) -> 0 | O12: =LEN(N12) -> 0
A13: =IF(B13="","",IF(A13<>"",A13,#REF!)) | C13: =IF(B13="","",IF(C13<>"",C13,NOW())) | I13: =LEN(H13) -> 0 | K13: =LEN(J13) -> 0 | M13: =LEN(L13) -> 0 | O13: =LEN(N13) -> 0
A14: =IF(B14="","",IF(A14<>"",A14,#REF!)) | C14: =IF(B14="","",IF(C14<>"",C14,NOW())) | I14: =LEN(H14) -> 0 | K14: =LEN(J14) -> 0 | M14: =LEN(L14) -> 0 | O14: =LEN(N14) -> 0
... A1198: =IF(B1198="","",IF(A1198<>"",A1198,#REF!)) | C1198: =IF(B1198="","",IF(C1198<>"",C1198,NOW())) | I1198: =LEN(H1198) -> 0 | K1198: =LEN(J1198) -> 0 | M1198: =LEN(L1198) -> 0 | O1198: =LEN(N1198) -> 0
C1199: =IF(B1199="","",IF(C1199<>"",C1199,NOW())) | I1199: =LEN(H1199) -> 0 | K1199: =LEN(J1199) -> 0 | M1199: =LEN(L1199) -> 0 | O1199: =LEN(N1199) -> 0
I1200: =LEN(H1200) -> 0 | K1200: =LEN(J1200) -> 0 | M1200: =LEN(L1200) -> 0 | O1200: =LEN(N1200) -> 0
I1201: =LEN(H1201) -> 0 | K1201: =LEN(J1201) -> 0 | M1201: =LEN(L1201) -> 0 | O1201: =LEN(N1201) -> 0
I1202: =LEN(H1202) -> 0 | K1202: =LEN(J1202) -> 0 | M1202: =LEN(L1202) -> 0 | O1202: =LEN(N1202) -> 0

Sheet 统计信息
A1: 版本 | B1: Abbr | C1: 创建日期 | D1: 创建人 | E1: 词性备注 | F1: 术语中文释义 | G1: 术语英文释义 | H1: 中文术语 | J1: 英文术语 | L1: 西文术语 | N1: 俄文术语
H2: 术语 | I2: 字符数 | J2: 术语 | K2: 字符数 | L2: 术语 | M2: 字符数 | N2: 术语 | O2: 字符数
A3: =IF(B3="","",IF(A3<>"",A3,#REF!)) | C3: =IF(B3="","",IF(C3<>"",C3,NOW())) | I3: =LEN(H3) -> 0 | K3: =LEN(J3) -> 0 | M3: =LEN(L3) -> 0 | O3: =LEN(N3) -> 0
A4: =IF(B4="","",IF(A4<>"",A4,#REF!)) | C4: =IF(B4="","",IF(C4<>"",C4,NOW())) | I4: =LEN(H4) -> 0 | K4: =LEN(J4) -> 0 | M4: =LEN(L4) -> 0 | O4: =LEN(N4) -> 0
A5: =IF(B5="","",IF(A5<>"",A5,#REF!)) | C5: =IF(B5="","",IF(C5<>"",C5,NOW())) | I5: =LEN(H5) -> 0 | K5: =LEN(J5) -> 0 | M5: =LEN(L5) -> 0 | O5: =LEN(N5) -> 0
A6: =IF(B6="","",IF(A6<>"",A6,#REF!)) | C6: =IF(B6="","",IF(C6<>"",C6,NOW())) | I6: =LEN(H6) -> 0 | K6: =LEN(J6) -> 0 | M6: =LEN(L6) -> 0 | O6: =LEN(N6) -> 0
A7: =IF(B7="","",IF(A7<>"",A7,#REF!)) | C7: =IF(B7="","",IF(C7<>"",C7,NOW())) | I7: =LEN(H7) -> 0 | K7: =LEN(J7) -> 0 | M7: =LEN(L7) -> 0 | O7: =LEN(N7) -> 0
A8: =IF(B8="","",IF(A8<>"",A8,#REF!)) | C8: =IF(B8="","",IF(C8<>"",C8,NOW())) | I8: =LEN(H8) -> 0 | K8: =LEN(J8) -> 0 | M8: =LEN(L8) -> 0 | O8: =LEN(N8) -> 0
A9: =IF(B9="","",IF(A9<>"",A9,#REF!)) | C9: =IF(B9="","",IF(C9<>"",C9,NOW())) | I9: =LEN(H9) -> 0 | K9: =LEN(J9) -> 0 | M9: =LEN(L9) -> 0 | O9: =LEN(N9) -> 0
A10: =IF(B10="","",IF(A10<>"",A10,#REF!)) | C10: =IF(B10="","",IF(C10<>"",C10,NOW())) | I10: =LEN(H10) -> 0 | K10: =LEN(J10) -> 0 | M10: =LEN(L10) -> 0 | O10: =LEN(N10) -> 0
A11: =IF(B11="","",IF(A11<>"",A11,#REF!)) | C11: =IF(B11="","",IF(C11<>"",C11,NOW())) | I11: =LEN(H11) -> 0 | K11: =LEN(J11) -> 0 | M11: =LEN(L11) -> 0 | O11: =LEN(N11) -> 0
A12: =IF(B12="","",IF(A12<>"",A12,#REF!)) | C12: =IF(B12="","",IF(C12<>"",C12,NOW())) | I12: =LEN(H12) -> 0 | K12: =LEN(J12) -> 0 | M12: =LEN(L12) -> 0 | O12: =LEN(N12) -> 0
A13: =IF(B13="","",IF(A13<>"",A13,#REF!)) | C13: =IF(B13="","",IF(C13<>"",C13,NOW())) | I13: =LEN(H13) -> 0 | K13: =LEN(J13) -> 0 | M13: =LEN(L13) -> 0 | O13: =LEN(N13) -> 0
A14: =IF(B14="","",IF(A14<>"",A14,#REF!)) | C14: =IF(B14="","",IF(C14<>"",C14,NOW())) | I14: =LEN(H14) -> 0 | K14: =LEN(J14) -> 0 | M14: =LEN(L14) -> 0 | O14: =LEN(N14) -> 0
... A1198: =IF(B1198="","",IF(A1198<>"",A1198,#REF!)) | C1198: =IF(B1198="","",IF(C1198<>"",C1198,NOW())) | I1198: =LEN(H1198) -> 0 | K1198: =LEN(J1198) -> 0 | M1198: =LEN(L1198) -> 0 | O1198: =LEN(N1198) -> 0
C1199: =IF(B1199="","",IF(C1199<>"",C1199,NOW())) | I1199: =LEN(H1199) -> 0 | K1199: =LEN(J1199) -> 0 | M1199: =LEN(L1199) -> 0 | O1199: =LEN(N1199) -> 0
I1200: =LEN(H1200) -> 0 | K1200: =LEN(J1200) -> 0 | M1200: =LEN(L1200) -> 0 | O1200: =LEN(N1200) -> 0
I1201: =LEN(H1201) -> 0 | K1201: =LEN(J1201) -> 0 | M1201: =LEN(L1201) -> 0 | O1201: =LEN(N1201) -> 0
I1202: =LEN(H1202) -> 0 | K1202: =LEN(J1202) -> 0 | M1202: =LEN(L1202) -> 0 | O1202: =LEN(N1202) -> 0

Sheet 量纲
A1: 版本 | B1: Abbr | C1: 创建日期 | D1: 创建人 | E1: 词性备注 | F1: 术语中文释义 | G1: 术语英文释义 | H1: 中文术语 | J1: 英文术语 | L1: 西文术语 | N1: 俄文术语
H2: 术语 | I2: 字符数 | J2: 术语 | K2: 字符数 | L2: 术语 | M2: 字符数 | N2: 术语 | O2: 字符数
A3: =IF(B3="","",IF(A3<>"",A3,#REF!)) | C3: =IF(B3="","",IF(C3<>"",C3,NOW())) | I3: =LEN(H3) -> 0 | K3: =LEN(J3) -> 0 | M3: =LEN(L3) -> 0 | O3: =LEN(N3) -> 0
A4: =IF(B4="","",IF(A4<>"",A4,#REF!)) | C4: =IF(B4="","",IF(C4<>"",C4,NOW())) | I4: =LEN(H4) -> 0 | K4: =LEN(J4) -> 0 | M4: =LEN(L4) -> 0 | O4: =LEN(N4) -> 0
A5: =IF(B5="","",IF(A5<>"",A5,#REF!)) | C5: =IF(B5="","",IF(C5<>"",C5,NOW())) | I5: =LEN(H5) -> 0 | K5: =LEN(J5) -> 0 | M5: =LEN(L5) -> 0 | O5: =LEN(N5) -> 0
A6: =IF(B6="","",IF(A6<>"",A6,#REF!)) | C6: =IF(B6="","",IF(C6<>"",C6,NOW())) | I6: =LEN(H6) -> 0 | K6: =LEN(J6) -> 0 | M6: =LEN(L6) -> 0 | O6: =LEN(N6) -> 0
A7: =IF(B7="","",IF(A7<>"",A7,#REF!)) | C7: =IF(B7="","",IF(C7<>"",C7,NOW())) | I7: =LEN(H7) -> 0 | K7: =LEN(J7) -> 0 | M7: =LEN(L7) -> 0 | O7: =LEN(N7) -> 0
A8: =IF(B8="","",IF(A8<>"",A8,#REF!)) | C8: =IF(B8="","",IF(C8<>"",C8,NOW())) | I8: =LEN(H8) -> 0 | K8: =LEN(J8) -> 0 | M8: =LEN(L8) -> 0 | O8: =LEN(N8) -> 0
A9: =IF(B9="","",IF(A9<>"",A9,#REF!)) | C9: =IF(B9="","",IF(C9<>"",C9,NOW())) | I9: =LEN(H9) -> 0 | K9: =LEN(J9) -> 0 | M9: =LEN(L9) -> 0 | O9: =LEN(N9) -> 0
A10: =IF(B10="","",IF(A10<>"",A10,#REF!)) | C10: =IF(B10="","",IF(C10<>"",C10,NOW())) | I10: =LEN(H10) -> 0 | K10: =LEN(J10) -> 0 | M10: =LEN(L10) -> 0 | O10: =LEN(N10) -> 0
A11: =IF(B11="","",IF(A11<>"",A11,#REF!)) | C11: =IF(B11="","",IF(C11<>"",C11,NOW())) | I11: =LEN(H11) -> 0 | K11: =LEN(J11) -> 0 | M11: =LEN(L11) -> 0 | O11: =LEN(N11) -> 0
A12: =IF(B12="","",IF(A12<>"",A12,#REF!)) | C12: =IF(B12="","",IF(C12<>"",C12,NOW())) | I12: =LEN(H12) -> 0 | K12: =LEN(J12) -> 0 | M12: =LEN(L12) -> 0 | O12: =LEN(N12) -> 0
A13: =IF(B13="","",IF(A13<>"",A13,#REF!)) | C13: =IF(B13="","",IF(C13<>"",C13,NOW())) | I13: =LEN(H13) -> 0 | K13: =LEN(J13) -> 0 | M13: =LEN(L13) -> 0 | O13: =LEN(N13) -> 0
A14: =IF(B14="","",IF(A14<>"",A14,#REF!)) | C14: =IF(B14="","",IF(C14<>"",C14,NOW())) | I14: =LEN(H14) -> 0 | K14: =LEN(J14) -> 0 | M14: =LEN(L14) -> 0 | O14: =LEN(N14) -> 0
... A1198: =IF(B1198="","",IF(A1198<>"",A1198,#REF!)) | C1198: =IF(B1198="","",IF(C1198<>"",C1198,NOW())) | I1198: =LEN(H1198) -> 0 | K1198: =LEN(J1198) -> 0 | M1198: =LEN(L1198) -> 0 | O1198: =LEN(N1198) -> 0
C1199: =IF(B1199="","",IF(C1199<>"",C1199,NOW())) | I1199: =LEN(H1199) -> 0 | K1199: =LEN(J1199) -> 0 | M1199: =LEN(L1199) -> 0 | O1199: =LEN(N1199) -> 0
I1200: =LEN(H1200) -> 0 | K1200: =LEN(J1200) -> 0 | M1200: =LEN(L1200) -> 0 | O1200: =LEN(N1200) -> 0
I1201: =LEN(H1201) -> 0 | K1201: =LEN(J1201) -> 0 | M1201: =LEN(L1201) -> 0 | O1201: =LEN(N1201) -> 0
I1202: =LEN(H1202) -> 0 | K1202: =LEN(J1202) -> 0 | M1202: =LEN(L1202) -> 0 | O1202: =LEN(N1202) -> 0

Sheet 画图文本类
A1: 版本 | B1: Abbr | C1: 创建日期 | D1: 创建人 | E1: 词性备注 | F1: 术语中文释义 | G1: 术语英文释义 | H1: 中文术语 | J1: 英文术语 | L1: 西文术语 | N1: 俄文术语
H2: 术语 | I2: 字符数 | J2: 术语 | K2: 字符数 | L2: 术语 | M2: 字符数 | N2: 术语 | O2: 字符数
A3: =IF(B3="","",IF(A3<>"",A3,#REF!)) | C3: =IF(B3="","",IF(C3<>"",C3,NOW())) | I3: =LEN(H3) -> 0 | K3: =LEN(J3) -> 0 | M3: =LEN(L3) -> 0 | O3: =LEN(N3) -> 0
A4: =IF(B4="","",IF(A4<>"",A4,#REF!)) | C4: =IF(B4="","",IF(C4<>"",C4,NOW())) | I4: =LEN(H4) -> 0 | K4: =LEN(J4) -> 0 | M4: =LEN(L4) -> 0 | O4: =LEN(N4) -> 0
A5: =IF(B5="","",IF(A5<>"",A5,#REF!)) | C5: =IF(B5="","",IF(C5<>"",C5,NOW())) | I5: =LEN(H5) -> 0 | K5: =LEN(J5) -> 0 | M5: =LEN(L5) -> 0 | O5: =LEN(N5) -> 0
A6: =IF(B6="","",IF(A6<>"",A6,#REF!)) | C6: =IF(B6="","",IF(C6<>"",C6,NOW())) | I6: =LEN(H6) -> 0 | K6: =LEN(J6) -> 0 | M6: =LEN(L6) -> 0 | O6: =LEN(N6) -> 0
A7: =IF(B7="","",IF(A7<>"",A7,#REF!)) | C7: =IF(B7="","",IF(C7<>"",C7,NOW())) | I7: =LEN(H7) -> 0 | K7: =LEN(J7) -> 0 | M7: =LEN(L7) -> 0 | O7: =LEN(N7) -> 0
A8: =IF(B8="","",IF(A8<>"",A8,#REF!)) | C8: =IF(B8="","",IF(C8<>"",C8,NOW())) | I8: =LEN(H8) -> 0 | K8: =LEN(J8) -> 0 | M8: =LEN(L8) -> 0 | O8: =LEN(N8) -> 0
A9: =IF(B9="","",IF(A9<>"",A9,#REF!)) | C9: =IF(B9="","",IF(C9<>"",C9,NOW())) | I9: =LEN(H9) -> 0 | K9: =LEN(J9) -> 0 | M9: =LEN(L9) -> 0 | O9: =LEN(N9) -> 0
A10: =IF(B10="","",IF(A10<>"",A10,#REF!)) | C10: =IF(B10="","",IF(C10<>"",C10,NOW())) | I10: =LEN(H10) -> 0 | K10: =LEN(J10) -> 0 | M10: =LEN(L10) -> 0 | O10: =LEN(N10) -> 0
A11: =IF(B11="","",IF(A11<>"",A11,#REF!)) | C11: =IF(B11="","",IF(C11<>"",C11,NOW())) | I11: =LEN(H11) -> 0 | K11: =LEN(J11) -> 0 | M11: =LEN(L11) -> 0 | O11: =LEN(N11) -> 0
A12: =IF(B12="","",IF(A12<>"",A12,#REF!)) | C12: =IF(B12="","",IF(C12<>"",C12,NOW())) | I12: =LEN(H12) -> 0 | K12: =LEN(J12) -> 0 | M12: =LEN(L12) -> 0 | O12: =LEN(N12) -> 0
A13: =IF(B13="","",IF(A13<>"",A13,#REF!)) | C13: =IF(B13="","",IF(C13<>"",C13,NOW())) | I13: =LEN(H13) -> 0 | K13: =LEN(J13) -> 0 | M13: =LEN(L13) -> 0 | O13: =LEN(N13) -> 0
A14: =IF(B14="","",IF(A14<>"",A14,#REF!)) | C14: =IF(B14="","",IF(C14<>"",C14,NOW())) | I14: =LEN(H14) -> 0 | K14: =LEN(J14) -> 0 | M14: =LEN(L14) -> 0 | O14: =LEN(N14) -> 0
... A1198: =IF(B1198="","",IF(A1198<>"",A1198,#REF!)) | C1198: =IF(B1198="","",IF(C1198<>"",C1198,NOW())) | I1198: =LEN(H1198) -> 0 | K1198: =LEN(J1198) -> 0 | M1198: =LEN(L1198) -> 0 | O1198: =LEN(N1198) -> 0
C1199: =IF(B1199="","",IF(C1199<>"",C1199,NOW())) | I1199: =LEN(H1199) -> 0 | K1199: =LEN(J1199) -> 0 | M1199: =LEN(L1199) -> 0 | O1199: =LEN(N1199) -> 0
I1200: =LEN(H1200) -> 0 | K1200: =LEN(J1200) -> 0 | M1200: =LEN(L1200) -> 0 | O1200: =LEN(N1200) -> 0
I1201: =LEN(H1201) -> 0 | K1201: =LEN(J1201) -> 0 | M1201: =LEN(L1201) -> 0 | O1201: =LEN(N1201) -> 0
I1202: =LEN(H1202) -> 0 | K1202: =LEN(J1202) -> 0 | M1202: =LEN(L1202) -> 0 | O1202: =LEN(N1202) -> 0

Sheet SV
A1: 版本 | B1: Abbr | C1: 创建日期 | D1: 创建人 | E1: 词性备注 | F1: 术语中文释义 | G1: 术语英文释义 | H1: 中文术语 | J1: 英文术语 | L1: 西文术语 | N1: 俄文术语
H2: 术语 | I2: 字符数 | J2: 术语 | K2: 字符数 | L2: 术语 | M2: 字符数 | N2: 术语 | O2: 字符数
A3: =IF(B3="","",IF(A3<>"",A3,#REF!)) | C3: =IF(B3="","",IF(C3<>"",C3,NOW())) | I3: =LEN(H3) -> 0 | K3: =LEN(J3) -> 0 | M3: =LEN(L3) -> 0 | O3: =LEN(N3) -> 0
A4: =IF(B4="","",IF(A4<>"",A4,#REF!)) | C4: =IF(B4="","",IF(C4<>"",C4,NOW())) | I4: =LEN(H4) -> 0 | K4: =LEN(J4) -> 0 | M4: =LEN(L4) -> 0 | O4: =LEN(N4) -> 0
A5: =IF(B5="","",IF(A5<>"",A5,#REF!)) | C5: =IF(B5="","",IF(C5<>"",C5,NOW())) | I5: =LEN(H5) -> 0 | K5: =LEN(J5) -> 0 | M5: =LEN(L5) -> 0 | O5: =LEN(N5) -> 0
A6: =IF(B6="","",IF(A6<>"",A6,#REF!)) | C6: =IF(B6="","",IF(C6<>"",C6,NOW())) | I6: =LEN(H6) -> 0 | K6: =LEN(J6) -> 0 | M6: =LEN(L6) -> 0 | O6: =LEN(N6) -> 0
A7: =IF(B7="","",IF(A7<>"",A7,#REF!)) | C7: =IF(B7="","",IF(C7<>"",C7,NOW())) | I7: =LEN(H7) -> 0 | K7: =LEN(J7) -> 0 | M7: =LEN(L7) -> 0 | O7: =LEN(N7) -> 0
A8: =IF(B8="","",IF(A8<>"",A8,#REF!)) | C8: =IF(B8="","",IF(C8<>"",C8,NOW())) | I8: =LEN(H8) -> 0 | K8: =LEN(J8) -> 0 | M8: =LEN(L8) -> 0 | O8: =LEN(N8) -> 0
A9: =IF(B9="","",IF(A9<>"",A9,#REF!)) | C9: =IF(B9="","",IF(C9<>"",C9,NOW())) | I9: =LEN(H9) -> 0 | K9: =LEN(J9) -> 0 | M9: =LEN(L9) -> 0 | O9: =LEN(N9) -> 0
A10: =IF(B10="","",IF(A10<>"",A10,#REF!)) | C10: =IF(B10="","",IF(C10<>"",C10,NOW())) | I10: =LEN(H10) -> 0 | K10: =LEN(J10) -> 0 | M10: =LEN(L10) -> 0 | O10: =LEN(N10) -> 0
A11: =IF(B11="","",IF(A11<>"",A11,#REF!)) | C11: =IF(B11="","",IF(C11<>"",C11,NOW())) | I11: =LEN(H11) -> 0 | K11: =LEN(J11) -> 0 | M11: =LEN(L11) -> 0 | O11: =LEN(N11) -> 0
A12: =IF(B12="","",IF(A12<>"",A12,#REF!)) | C12: =IF(B12="","",IF(C12<>"",C12,NOW())) | I12: =LEN(H12) -> 0 | K12: =LEN(J12) -> 0 | M12: =LEN(L12) -> 0 | O12: =LEN(N12) -> 0
A13: =IF(B13="","",IF(A13<>"",A13,#REF!)) | C13: =IF(B13="","",IF(C13<>"",C13,NOW())) | I13: =LEN(H13) -> 0 | K13: =LEN(J13) -> 0 | M13: =LEN(L13) -> 0 | O13: =LEN(N13) -> 0
A14: =IF(B14="","",IF(A14<>"",A14,#REF!)) | C14: =IF(B14="","",IF(C14<>"",C14,NOW())) | I14: =LEN(H14) -> 0 | K14: =LEN(J14) -> 0 | M14: =LEN(L14) -> 0 | O14: =LEN(N14) -> 0
... A1198: =IF(B1198="","",IF(A1198<>"",A1198,#REF!)) | C1198: =IF(B1198="","",IF(C1198<>"",C1198,NOW())) | I1198: =LEN(H1198) -> 0 | K1198: =LEN(J1198) -> 0 | M1198: =LEN(L1198) -> 0 | O1198: =LEN(N1198) -> 0
C1199: =IF(B1199="","",IF(C1199<>"",C1199,NOW())) | I1199: =LEN(H1199) -> 0 | K1199: =LEN(J1199) -> 0 | M1199: =LEN(L1199) -> 0 | O1199: =LEN(N1199) -> 0
I1200: =LEN(H1200) -> 0 | K1200: =LEN(J1200) -> 0 | M1200: =LEN(L1200) -> 0 | O1200: =LEN(N1200) -> 0
I1201: =LEN(H1201) -> 0 | K1201: =LEN(J1201) -> 0 | M1201: =LEN(L1201) -> 0 | O1201: =LEN(N1201) -> 0
I1202: =LEN(H1202) -> 0 | K1202: =LEN(J1202) -> 0 | M1202: =LEN(L1202) -> 0 | O1202: =LEN(N1202) -> 0

Sheet GOOSE
A1: 版本 | B1: Abbr | C1: 创建日期 | D1: 创建人 | E1: 词性备注 | F1: 术语中文释义 | G1: 术语英文释义 | H1: 中文术语 | J1: 英文术语 | L1: 西文术语 | N1: 俄文术语
H2: 术语 | I2: 字符数 | J2: 术语 | K2: 字符数 | L2: 术语 | M2: 字符数 | N2: 术语 | O2: 字符数
A3: =IF(B3="","",IF(A3<>"",A3,#REF!)) | C3: =IF(B3="","",IF(C3<>"",C3,NOW())) | I3: =LEN(H3) -> 0 | K3: =LEN(J3) -> 0 | M3: =LEN(L3) -> 0 | O3: =LEN(N3) -> 0
A4: =IF(B4="","",IF(A4<>"",A4,#REF!)) | C4: =IF(B4="","",IF(C4<>"",C4,NOW())) | I4: =LEN(H4) -> 0 | K4: =LEN(J4) -> 0 | M4: =LEN(L4) -> 0 | O4: =LEN(N4) -> 0
A5: =IF(B5="","",IF(A5<>"",A5,#REF!)) | C5: =IF(B5="","",IF(C5<>"",C5,NOW())) | I5: =LEN(H5) -> 0 | K5: =LEN(J5) -> 0 | M5: =LEN(L5) -> 0 | O5: =LEN(N5) -> 0
A6: =IF(B6="","",IF(A6<>"",A6,#REF!)) | C6: =IF(B6="","",IF(C6<>"",C6,NOW())) | I6: =LEN(H6) -> 0 | K6: =LEN(J6) -> 0 | M6: =LEN(L6) -> 0 | O6: =LEN(N6) -> 0
A7: =IF(B7="","",IF(A7<>"",A7,#REF!)) | C7: =IF(B7="","",IF(C7<>"",C7,NOW())) | I7: =LEN(H7) -> 0 | K7: =LEN(J7) -> 0 | M7: =LEN(L7) -> 0 | O7: =LEN(N7) -> 0
A8: =IF(B8="","",IF(A8<>"",A8,#REF!)) | C8: =IF(B8="","",IF(C8<>"",C8,NOW())) | I8: =LEN(H8) -> 0 | K8: =LEN(J8) -> 0 | M8: =LEN(L8) -> 0 | O8: =LEN(N8) -> 0
A9: =IF(B9="","",IF(A9<>"",A9,#REF!)) | C9: =IF(B9="","",IF(C9<>"",C9,NOW())) | I9: =LEN(H9) -> 0 | K9: =LEN(J9) -> 0 | M9: =LEN(L9) -> 0 | O9: =LEN(N9) -> 0
A10: =IF(B10="","",IF(A10<>"",A10,#REF!)) | C10: =IF(B10="","",IF(C10<>"",C10,NOW())) | I10: =LEN(H10) -> 0 | K10: =LEN(J10) -> 0 | M10: =LEN(L10) -> 0 | O10: =LEN(N10) -> 0
A11: =IF(B11="","",IF(A11<>"",A11,#REF!)) | C11: =IF(B11="","",IF(C11<>"",C11,NOW())) | I11: =LEN(H11) -> 0 | K11: =LEN(J11) -> 0 | M11: =LEN(L11) -> 0 | O11: =LEN(N11) -> 0
A12: =IF(B12="","",IF(A12<>"",A12,#REF!)) | C12: =IF(B12="","",IF(C12<>"",C12,NOW())) | I12: =LEN(H12) -> 0 | K12: =LEN(J12) -> 0 | M12: =LEN(L12) -> 0 | O12: =LEN(N12) -> 0
A13: =IF(B13="","",IF(A13<>"",A13,#REF!)) | C13: =IF(B13="","",IF(C13<>"",C13,NOW())) | I13: =LEN(H13) -> 0 | K13: =LEN(J13) -> 0 | M13: =LEN(L13) -> 0 | O13: =LEN(N13) -> 0
A14: =IF(B14="","",IF(A14<>"",A14,#REF!)) | C14: =IF(B14="","",IF(C14<>"",C14,NOW())) | I14: =LEN(H14) -> 0 | K14: =LEN(J14) -> 0 | M14: =LEN(L14) -> 0 | O14: =LEN(N14) -> 0
... A1198: =IF(B1198="","",IF(A1198<>"",A1198,#REF!)) | C1198: =IF(B1198="","",IF(C1198<>"",C1198,NOW())) | I1198: =LEN(H1198) -> 0 | K1198: =LEN(J1198) -> 0 | M1198: =LEN(L1198) -> 0 | O1198: =LEN(N1198) -> 0
C1199: =IF(B1199="","",IF(C1199<>"",C1199,NOW())) | I1199: =LEN(H1199) -> 0 | K1199: =LEN(J1199) -> 0 | M1199: =LEN(L1199) -> 0 | O1199: =LEN(N1199) -> 0
I1200: =LEN(H1200) -> 0 | K1200: =LEN(J1200) -> 0 | M1200: =LEN(L1200) -> 0 | O1200: =LEN(N1200) -> 0
I1201: =LEN(H1201) -> 0 | K1201: =LEN(J1201) -> 0 | M1201: =LEN(L1201) -> 0 | O1201: =LEN(N1201) -> 0
I1202: =LEN(H1202) -> 0 | K1202: =LEN(J1202) -> 0 | M1202: =LEN(L1202) -> 0 | O1202: =LEN(N1202) -> 0

Sheet 备用术语（在一体化工具和装置上不出现）
A1: 版本 | B1: Abbr | C1: 创建日期 | D1: 创建人 | E1: 词性备注 | F1: 术语中文释义 | G1: 术语英文释义 | H1: 中文术语 | J1: 英文术语 | L1: 西文术语 | N1: 俄文术语
H2: 术语 | I2: 字符数 | J2: 术语 | K2: 字符数 | L2: 术语 | M2: 字符数 | N2: 术语 | O2: 字符数
I3: 0 | K3: 0 | M3: 0 | O3: 0
I4: 0 | K4: 0 | M4: 0 | O4: 0
I5: 0 | K5: 0 | M5: 0 | O5: 0
I6: 0 | K6: 0 | M6: 0 | O6: 0
I7: 0 | K7: 0 | M7: 0 | O7: 0
I8: 0 | K8: 0 | M8: 0 | O8: 0
I9: 0 | K9: 0 | M9: 0 | O9: 0
I10: 0 | K10: 0 | M10: 0 | O10: 0
I11: 0 | K11: 0 | M11: 0 | O11: 0
I12: 0 | K12: 0 | M12: 0 | O12: 0
I13: 0 | K13: 0 | M13: 0 | O13: 0
I14: 0 | K14: 0 | M14: 0 | O14: 0
... I1200: 0 | K1200: 0 | M1200: 0 | O1200: 0
I1201: =LEN(H1201) -> 0 | K1201: =LEN(J1201) -> 0 | M1201: =LEN(L1201) -> 0 | O1201: =LEN(N1201) -> 0
I1202: =LEN(H1202) -> 0 | K1202: =LEN(J1202) -> 0 | M1202: =LEN(L1202) -> 0 | O1202: =LEN(N1202) -> 0
