Workbook

Sheet 应用申请的菜单(25）
A1: 版本 | B1: Abbr | C1: 创建日期 | D1: 创建人 | E1: 术语中文释义 | F1: 术语英文释义 | G1: 中文术语 | I1: 英文术语 | K1: 西文术语 | M1: 俄文术语
G2: 术语 | H2: 字符数 | I2: 术语 | J2: 字符数 | K2: 术语 | L2: 字符数 | M2: 术语 | N2: 字符数
A3: 测量
A4: 1.0 | B4: measurements | C4: =IF(B4="","",IF(C4<>"",C4,NOW())) -> 0 | D4: 薛宇 | E4: 1 | F4: Measurements | G4: 测量 | H4: =LEN(G4) -> 3 | I4: Measurements | J4: =LEN(I4) -> 12
A5: 1.0 | B5: general | C5: =IF(B5="","",IF(C5<>"",C5,NOW())) -> 0 | D5: 薛宇 | E5: 2:: 测量/ | F5: General | G5: 通用 | H5: =LEN(G5) -> 3 | I5: General | J5: =LEN(I5) -> 7
A6: 1.0 | B6: sq_comp | C6: =IF(B6="","",IF(C6<>"",C6,NOW())) -> 0 | D6: 薛宇 | E6: 2: 测量/ | F6: Sequence components | G6: 序分量 | H6: =LEN(G6) -> 3 | I6: Sequence Components | J6: =LEN(I6) -> 19
A7: 1.0 | B7: harmonic | C7: =IF(B7="","",IF(C7<>"",C7,NOW())) -> 0 | D7: 薛宇 | E7: 2: 测量/ | F7: Harmonic | G7: 谐波 | H7: =LEN(G7) -> 3 | I7: Harmonic | J7: =LEN(I7) -> 8
A8: 1.0 | B8: angle | C8: =IF(B8="","",IF(C8<>"",C8,NOW())) -> 0 | D8: 薛宇 | E8: 2: 测量/ | F8: Angle | G8: 角度 | H8: =LEN(G8) -> 3 | I8: Angle | J8: =LEN(I8) -> 5
A9: 1.0 | B9: frequency | C9: =IF(B9="","",IF(C9<>"",C9,NOW())) -> 0 | D9: 薛宇 | E9: 2: 测量/ | F9: Frequency | G9: 频率 | H9: =LEN(G9) -> 3 | I9: Frequency | J9: =LEN(I9) -> 9
A10: 1.0 | B10: sync_mea | C10: =IF(B10="","",IF(C10<>"",C10,NOW())) -> 0 | D10: 薛宇 | E10: 2: 测量/ | F10: Synchronization measurements | G10: 同期测量 | H10: =LEN(G10) -> 5 | I10: Synchrocheck Values | J10: =LEN(I10) -> 19
A11: 1.0 | B11: power | C11: =IF(B11="","",IF(C11<>"",C11,NOW())) -> 0 | D11: 薛宇 | E11: 2: 测量/ | F11: Power | G11: 功率 | H11: =LEN(G11) -> 3 | I11: Power | J11: =LEN(I11) -> 5
A12: 1.0 | B12: energy | C12: =IF(B12="","",IF(C12<>"",C12,NOW())) -> 0 | D12: 薛宇 | E12: 2: 测量/ | F12: Energy | G12: 电能量 | H12: =LEN(G12) -> 4 | I12: Energy | J12: =LEN(I12) -> 6
A13: 1.0 | B13: power_qua | C13: =IF(B13="","",IF(C13<>"",C13,NOW())) -> 0 | D13: 薛宇 | E13: 2: 测量/ | F13: Power quality | G13: 电能质量 | H13: =LEN(G13) -> 5 | I13: Power Quality | J13: =LEN(I13) -> 13
A14: 1.0 | B14: trans_val | C14: =IF(B14="","",IF(C14<>"",C14,NOW())) -> 0 | D14: 薛宇 | E14: 2: 测量/ | F14: Transducer values | G14: 传感器 | H14: =LEN(G14) -> 4 | I14: Transducer Values | J14: =LEN(I14) -> 17
A15: 1.0 | B15: dc_val | C15: =IF(B15="","",IF(C15<>"",C15,NOW())) -> 0 | D15: 薛宇 | E15: 2: 测量/ | F15: DC output values | G15: 直流输出 | H15: =LEN(G15) -> 5 | I15: DC Outputs | J15: =LEN(I15) -> 10
A16: 1.0 | B16: ad2_mea | C16: =IF(B16="","",IF(C16<>"",C16,NOW())) -> 0 | D16: 薛宇 | E16: 2: 测量/ | F16: AD group 2 measurements | G16: 第二组AD测量 | H16: =LEN(G16) -> 7 | I16: Group 2 AD Measurements | J16: =LEN(I16) -> 23
A17: 状态
A18: 1.0 | B18: status | C18: =IF(B18="","",IF(C18<>"",C18,NOW())) -> 0 | D18: 薛宇 | E18: 1 | F18: Status | G18: 状态 | H18: =LEN(G18) -> 3 | I18: State | J18: =LEN(I18) -> 5
A19: 1.0 | B19: bi_in | C19: =IF(B19="","",IF(C19<>"",C19,NOW())) -> 0 | D19: 薛宇 | E19: 2: 状态/ | F19: Binary inputs | G19: 输入 | H19: =LEN(G19) -> 3 | I19: Inputs | J19: =LEN(I19) -> 6
A20: 1.0 | B20: gen_in | C20: =IF(B20="","",IF(C20<>"",C20,NOW())) -> 0 | D20: 薛宇 | E20: 3: 状态/输入/ | F20: general inputs | G20: 通用开入 | H20: =LEN(G20) -> 4 | I20: General Inputs | J20: =LEN(I20) -> 14
A21: 1.0 | B21: tap_pos | C21: =IF(B21="","",IF(C21<>"",C21,NOW())) -> 0 | D21: 薛宇 | E21: 3: 状态/输入/ | F21: Tap position | G21: 档位 | H21: =LEN(G21) -> 3 | I21: Tap Position | J21: =LEN(I21) -> 12
A22: 1.0 | B22: goose_in | C22: =IF(B22="","",IF(C22<>"",C22,NOW())) -> 0 | D22: 薛宇 | E22: 3: 状态/输入/ | F22: GOOSE inputs | G22: GOOSE输入 | H22: =LEN(G22) -> 8 | I22: GOOSE Inputs | J22: =LEN(I22) -> 12
A23: 1.0 | B23: bi_out | C23: =IF(B23="","",IF(C23<>"",C23,NOW())) -> 0 | D23: 薛宇 | E23: 2 状态/ | F23: Binary outputs | G23: 输出 | H23: =LEN(G23) -> 3 | I23: Outputs | J23: =LEN(I23) -> 7
A24: 1.0 | B24: actions | C24: =IF(B24="","",IF(C24<>"",C24,NOW())) -> 0 | D24: 薛宇 | E24: 3: 状态/输出/ | F24: Actions | G24: 动作状态 | H24: =LEN(G24) -> 4 | I24: Actions | J24: =LEN(I24) -> 7
A25: 1.0 | B25: intlock_info | C25: =IF(B25="","",IF(C25<>"",C25,NOW())) -> 0 | D25: 薛宇 | E25: 3: 状态/输出/ | F25: Interlock information | G25: 联闭锁状态 | H25: =LEN(G25) -> 5 | I25: Interlock State | J25: =LEN(I25) -> 15
A26: 1.0 | B26: dpos_sta | C26: =IF(B26="","",IF(C26<>"",C26,NOW())) -> 0 | D26: 薛宇 | E26: 3: 状态/输出/ | F26: Double position | G26: 双位置状态 | H26: =LEN(G26) -> 5 | I26: Double Position | J26: =LEN(I26) -> 15
A27: 1.0 | B27: self_chk | C27: =IF(B27="","",IF(C27<>"",C27,NOW())) -> 0 | D27: 薛宇 | E27: 2: 状态/ | F27: Selfcheck information | G27: 自检状态 | H27: =LEN(G27) -> 4 | I27: Supervision State | J27: =LEN(I27) -> 17
A28: 1.0 | B28: run_sta | C28: =IF(B28="","",IF(C28<>"",C28,NOW())) -> 0 | D28: 薛宇 | E28: 2: 状态/ | F28: Operational status | G28: 运行状态 | H28: =LEN(G28) -> 5 | I28: Running State | J28: =LEN(I28) -> 13
A29: 1.0 | B29: comm_sta | C29: =IF(B29="","",IF(C29<>"",C29,NOW())) -> 0 | D29: 薛宇 | E29: 2: 状态/ | F29: Communication status | G29: 通信状态 | H29: =LEN(G29) -> 5 | I29: Communication State | J29: =LEN(I29) -> 19
A30: 1.0 | B30: goose_out | C30: =IF(B30="","",IF(C30<>"",C30,NOW())) -> 0 | D30: 薛宇 | E30: 3: 状态/输出/ | F30: GOOSE outputs | G30: GOOSE输出 | H30: =LEN(G30) -> 7 | I30: GOOSE Outputs | J30: =LEN(I30) -> 13
A31: 日志
A32: 1.0 | B32: logs | C32: =IF(B32="","",IF(C32<>"",C32,NOW())) -> 0 | D32: 薛宇 | E32: 1 | F32: Logs | G32: 日志 | H32: =LEN(G32) -> 3 | I32: Logs | J32: =LEN(I32) -> 4
A33: 1.0 | B33: bi_chg_log | C33: =IF(B33="","",IF(C33<>"",C33,NOW())) -> 0 | D33: 薛宇 | E33: 2: 日志/ | F33: Binary change information | G33: 变位日志 | H33: =LEN(G33) -> 5 | I33: Binary Change Logs | J33: =LEN(I33) -> 18
A34: 1.0 | B34: self_chk_log | C34: =IF(B34="","",IF(C34<>"",C34,NOW())) -> 0 | D34: 薛宇 | E34: 2: 日志/ | F34: Selfcheck log | G34: 自检日志 | H34: =LEN(G34) -> 5 | I34: Supervision logs | J34: =LEN(I34) -> 16
A35: 1.0 | B35: fault_log | C35: =IF(B35="","",IF(C35<>"",C35,NOW())) -> 0 | D35: 薛宇 | E35: 2: 日志/ | F35: Fault log | G35: 故障日志 | H35: =LEN(G35) -> 5 | I35: Fault Logs | J35: =LEN(I35) -> 10
A36: 1.0 | B36: oper_log | C36: =IF(B36="","",IF(C36<>"",C36,NOW())) -> 0 | D36: 薛宇 | E36: 2: 日志/ | F36: Operate log | G36: 操作日志 | H36: =LEN(G36) -> 5 | I36: Operating Logs | J36: =LEN(I36) -> 14
A37: 1.0 | B37: dev_log | C37: =IF(B37="","",IF(C37<>"",C37,NOW())) -> 0 | D37: 薛宇 | E37: 2: 日志/ | F37: Device log | G37: 装置日志 | H37: =LEN(G37) -> 5 | I37: Device Running Logs | J37: =LEN(I37) -> 19
A38: 1.0 | B38: audit_log | C38: =IF(B38="","",IF(C38<>"",C38,NOW())) -> 0 | D38: 薛宇 | E38: 2: 日志/ | F38: audit log | G38: 审计日志 | H38: =LEN(G38) -> 4 | I38: Audit Logs | J38: =LEN(I38) -> 10
A39: 1.0 | B39: soe_log | C39: =IF(B39="","",IF(C39<>"",C39,NOW())) -> 0 | D39: 薛宇 | E39: 2: 日志/ | F39: SOE | G39: SOE | H39: =LEN(G39) -> 3 | I39: SOE | J39: =LEN(I39) -> 3
A40: 定值
...

Sheet 硬件（19）
A1: 版本 | B1: Abbr | C1: 创建日期 | D1: 创建人 | E1: 术语中文释义 | F1: 术语英文释义 | G1: 中文术语 | I1: 英文术语 | K1: 西文术语 | M1: 俄文术语
G2: 术语 | H2: 字符数 | I2: 术语 | J2: 字符数 | K2: 术语 | L2: 字符数 | M2: 术语 | N2: 字符数
A3: 模块
A4: 1.0 | B4: cpu_module | C4: =IF(B4="","",IF(C4<>"",C4,NOW())) -> 0 | D4: 鲍凯鹏 | F4: CPU module | G4: CPU模块 | H4: =LEN(G4) -> 5 | I4: CPU_Module | J4: =LEN(I4) -> 10
A5: 1.0 | B5: ai_module | C5: =IF(B5="","",IF(C5<>"",C5,NOW())) -> 0 | D5: 鲍凯鹏 | F5: Analog input module | G5: 模拟量输入模块 | H5: =LEN(G5) -> 7 | I5: AI _Module | J5: =LEN(I5) -> 10
A6: 1.0 | B6: bi_module | C6: =IF(B6="","",IF(C6<>"",C6,NOW())) -> 0 | D6: 鲍凯鹏 | F6: Binary input module | G6: 开关量输入模块 | H6: =LEN(G6) -> 7 | I6: BI_Module | J6: =LEN(I6) -> 9
A7: 1.0 | B7: bo_module | C7: =IF(B7="","",IF(C7<>"",C7,NOW())) -> 0 | D7: 鲍凯鹏 | F7: Binary output module | G7: 开关量输出模块 | H7: =LEN(G7) -> 7 | I7: BO_Module | J7: =LEN(I7) -> 9
A8: 1.0 | B8: bio_module | C8: =IF(B8="","",IF(C8<>"",C8,NOW())) -> 0 | D8: 鲍凯鹏 | F8: Binary input&output module | G8: 开关量输入输出模块 | H8: =LEN(G8) -> 9 | I8: IO_Module | J8: =LEN(I8) -> 9
A9: 1.0 | B9: pwr_module | C9: =IF(B9="","",IF(C9<>"",C9,NOW())) -> 0 | D9: 鲍凯鹏 | F9: Power module | G9: 电源模块 | H9: =LEN(G9) -> 4 | I9: PWR_Module | J9: =LEN(I9) -> 10
A10: 1.0 | B10: ao_module | C10: =IF(B10="","",IF(C10<>"",C10,NOW())) -> 0 | D10: 鲍凯鹏 | F10: Analog output module | G10: 模拟量输出模块 | H10: =LEN(G10) -> 7 | I10: AO_Module | J10: =LEN(I10) -> 9
A11: 1.0 | B11: process_module | C11: =IF(B11="","",IF(C11<>"",C11,NOW())) -> 0 | D11: 鲍凯鹏 | F11: Process level comunication module | G11: 过程层通讯模块 | H11: =LEN(G11) -> 7 | I11: COM_Module | J11: =LEN(I11) -> 10
A13: 板卡
A14: 1.0 | B14: board | D14: 冯志翔 | E14: 板卡，序号另建 | F14: board | G14: 板卡 | I14: B | J14: =LEN(I14) -> 1
A16: 机箱
A17: 1.0 | B17: rack | C17: =IF(B17="","",IF(C17<>"",C17,NOW())) -> 0 | D17: 鲍凯鹏 | F17: Rack | G17: 机箱 | H17: =LEN(G17) -> 2 | I17: Rack | J17: =LEN(I17) -> 4 | N17: =LEN(M17) -> 0
H18: =LEN(G18) -> 0 | N18: 0
H19: =LEN(G19) -> 0 | N19: 0
H21: =LEN(G21) -> 0 | N21: 0
H22: =LEN(G22) -> 0 | N22: 0
H23: =LEN(G23) -> 0 | N23: 0
H24: =LEN(G24) -> 0 | N24: 0
H25: =LEN(G25) -> 0 | N25: 0
H26: =LEN(G26) -> 0 | N26: 0
H27: =LEN(G27) -> 0 | N27: 0
H28: =LEN(G28) -> 0 | N28: 0
H29: =LEN(G29) -> 0 | N29: 0
H30: =LEN(G30) -> 0 | N30: 0
... H51: =LEN(G51) -> 0 | N51: 0
H52: 0 | N52: 0
H53: 0 | N53: 0
H54: 0 | N54: 0
H55: 0 | N55: 0
H56: 0 | N56: 0
H57: 0 | N57: 0
H58: 0 | N58: 0
H59: 0 | N59: 0
H60: 0 | N60: 0
H61: 0 | N61: 0
H62: 0 | N62: 0
H63: 0 | N63: 0
...

Sheet 间隔（19）
A1: 版本 | B1: Abbr | C1: 创建日期 | D1: 创建人 | E1: 术语中文释义 | F1: 术语英文释义 | G1: 中文术语 | I1: 英文术语 | K1: 西文术语 | M1: 俄文术语
G2: 术语 | H2: 字符数 | I2: 术语 | J2: 字符数 | K2: 术语 | L2: 字符数 | M2: 术语 | N2: 字符数
A3: 统称
A4: 1.0 | B4: bay | C4: =IF(B4="","",IF(C4<>"",C4,NOW())) -> 0 | D4: 刘龙 | F4: substation bay | G4: 间隔 | H4: =LEN(G4) -> 2 | I4: Bay | J4: =LEN(I4) -> 3
A5: 线路
A6: 1.0 | B6: line_bay | C6: =IF(B6="","",IF(C6<>"",C6,NOW())) -> 0 | D6: 鲍凯鹏 | F6: line | G6: 线路 | H6: =LEN(G6) -> 2 | I6: Line | J6: =LEN(I6) -> 4
A7: 1.0 | B7: feeder | C7: =IF(B7="","",IF(C7<>"",C7,NOW())) -> 0 | D7: 鲍凯鹏 | F7: feeder | G7: 馈线 | H7: =LEN(G7) -> 2 | I7: Feed | J7: =LEN(I7) -> 4
A8: 1.0 | B8: transmission line | C8: =IF(B8="","",IF(C8<>"",C8,NOW())) -> 0 | D8: 鲍凯鹏 | F8: transmission line | G8: 传输线 | H8: =LEN(G8) -> 3 | I8: TransLine | J8: =LEN(I8) -> 9
A9: =IF(B9="","",IF(A9<>"",A9,#REF!)) | C9: =IF(B9="","",IF(C9<>"",C9,NOW()))
A10: 断路器
A11: 1.0 | B11: breaker | C11: =IF(B11="","",IF(C11<>"",C11,NOW())) -> 0 | D11: 鲍凯鹏 | F11: breaker | G11: 断路器 | H11: =LEN(G11) -> 3 | I11: CB | J11: =LEN(I11) -> 2
A12: =IF(B12="","",IF(A12<>"",A12,#REF!)) | C12: =IF(B12="","",IF(C12<>"",C12,NOW()))
A13: 刀闸
A14: 1.0 | B14: isolator | C14: =IF(B14="","",IF(C14<>"",C14,NOW())) -> 0 | D14: 鲍凯鹏 | F14: isolator,disconnector switch | G14: 隔离刀闸 | H14: =LEN(G14) -> 4 | I14: DS | J14: =LEN(I14) -> 2
A15: =IF(B15="","",IF(A15<>"",A15,#REF!)) | C15: =IF(B15="","",IF(C15<>"",C15,NOW()))
A16: 母线
A17: 1.0 | B17: busbar | C17: =IF(B17="","",IF(C17<>"",C17,NOW())) -> 0 | D17: 鲍凯鹏 | F17: busbar | G17: 母线 | H17: =LEN(G17) -> 2 | I17: Bus | J17: =LEN(I17) -> 3
A18: =IF(B18="","",IF(A18<>"",A18,#REF!)) | C18: =IF(B18="","",IF(C18<>"",C18,NOW()))
A19: 母联
A20: 1.0 | B20: bus_coupler | C20: =IF(B20="","",IF(C20<>"",C20,NOW())) -> 0 | D20: 鲍凯鹏 | F20: bus_coupler | G20: 母联 | H20: =LEN(G20) -> 2 | I20: BusCoupler | J20: =LEN(I20) -> 10
A21: 1.0 | B21: bus_section | C21: =IF(B21="","",IF(C21<>"",C21,NOW())) -> 0 | D21: 鲍凯鹏 | F21: bus_section | G21: 分段 | H21: =LEN(G21) -> 2 | I21: BusSection | J21: =LEN(I21) -> 10
A22: =IF(B22="","",IF(A22<>"",A22,#REF!)) | C22: =IF(B22="","",IF(C22<>"",C22,NOW()))
A23: 变压器各侧
A24: 1.0 | B24: high_voltage_side | C24: =IF(B24="","",IF(C24<>"",C24,NOW())) -> 0 | D24: 鲍凯鹏 | F24: high_voltage_side | G24: 高压侧 | H24: =LEN(G24) -> 3 | I24: HVS | J24: =LEN(I24) -> 3
A25: 1.0 | B25: middle_voltage_side | C25: =IF(B25="","",IF(C25<>"",C25,NOW())) -> 0 | D25: 鲍凯鹏 | F25: middle_voltage_side | G25: 中压侧 | H25: =LEN(G25) -> 3 | I25: MVS | J25: =LEN(I25) -> 3
A26: 1.0 | B26: low_voltage_side | C26: =IF(B26="","",IF(C26<>"",C26,NOW())) -> 0 | D26: 鲍凯鹏 | F26: low_voltage_side | G26: 低压侧 | H26: =LEN(G26) -> 3 | I26: LVS | J26: =LEN(I26) -> 3
A27: 1.0 | B27: low_voltage_side_1 | C27: =IF(B27="","",IF(C27<>"",C27,NOW())) -> 0 | D27: 鲍凯鹏 | F27: low_voltage_side_1 | G27: 低压侧1分支 | H27: =LEN(G27) -> 6 | I27: LVS1 | J27: =LEN(I27) -> 4
A28: 1.0 | B28: low_voltage_side_2 | C28: =IF(B28="","",IF(C28<>"",C28,NOW())) -> 0 | D28: 鲍凯鹏 | F28: low_voltage_side_2 | G28: 低压侧2分支 | H28: =LEN(G28) -> 6 | I28: LVS2 | J28: =LEN(I28) -> 4
A29: 1.0 | B29: low_voltage_side_3 | C29: =IF(B29="","",IF(C29<>"",C29,NOW())) -> 0 | D29: 鲍凯鹏 | F29: low_voltage_side_3 | G29: 低压侧3分支 | H29: =LEN(G29) -> 6 | I29: LVS3 | J29: =LEN(I29) -> 4
A30: =IF(B30="","",IF(A30<>"",A30,#REF!)) | C30: =IF(B30="","",IF(C30<>"",C30,NOW()))
A31: 电容电抗
A32: 1.0 | B32: capacitor | C32: =IF(B32="","",IF(C32<>"",C32,NOW())) -> 0 | D32: 鲍凯鹏 | F32: capacitor | G32: 电容 | H32: =LEN(G32) -> 2 | I32: Capacitor | J32: =LEN(I32) -> 9
A33: 1.0 | B33: reactor | C33: =IF(B33="","",IF(C33<>"",C33,NOW())) -> 0 | D33: 鲍凯鹏 | F33: reactor | G33: 电抗 | H33: =LEN(G33) -> 2 | I33: Reactor | J33: =LEN(I33) -> 7
A34: =IF(B34="","",IF(A34<>"",A34,#REF!)) | C34: =IF(B34="","",IF(C34<>"",C34,NOW()))
A35: =IF(B35="","",IF(A35<>"",A35,#REF!)) | C35: =IF(B35="","",IF(C35<>"",C35,NOW()))
A36: =IF(B36="","",IF(A36<>"",A36,#REF!)) | C36: =IF(B36="","",IF(C36<>"",C36,NOW()))
A37: =IF(B37="","",IF(A37<>"",A37,#REF!)) | C37: =IF(B37="","",IF(C37<>"",C37,NOW()))
A38: =IF(B38="","",IF(A38<>"",A38,#REF!)) | C38: =IF(B38="","",IF(C38<>"",C38,NOW()))
A39: =IF(B39="","",IF(A39<>"",A39,#REF!)) | C39: =IF(B39="","",IF(C39<>"",C39,NOW()))
A40: =IF(B40="","",IF(A40<>"",A40,#REF!)) | C40: =IF(B40="","",IF(C40<>"",C40,NOW()))
...

Sheet 装置通用（lcd显示信息）（28）
A1: 版本 | B1: Abbr | C1: 创建日期 | D1: 创建人 | E1: 术语中文释义 | F1: 术语英文释义 | G1: 中文术语 | I1: 英文术语 | K1: 西文术语 | M1: 俄文术语
G2: 术语 | H2: 字符数 | I2: 术语 | J2: 字符数 | K2: 术语 | L2: 字符数 | M2: 术语 | N2: 字符数
A3: 装置名称
A4: 1.0 | B4: feeder_relay | C4: =IF(B4="","",IF(C4<>"",C4,NOW())) -> 0 | D4: 鲍凯鹏 | F4: Feeder relay | G4: 馈线保护 | H4: =LEN(G4) -> 4 | I4: Feeder relay | J4: =LEN(I4) -> 12
A5: 1.0 | B5: line_relay | C5: =IF(B5="","",IF(C5<>"",C5,NOW())) -> 0 | D5: 鲍凯鹏 | F5: Line relay | G5: 线路保护 | H5: =LEN(G5) -> 4 | I5: Line relay | J5: =LEN(I5) -> 10
A6: 1.0 | B6: transformer_relay | C6: =IF(B6="","",IF(C6<>"",C6,NOW())) -> 0 | D6: 鲍凯鹏 | F6: Transformer relay | G6: 变压器保护 | H6: =LEN(G6) -> 5 | I6: Transformer relay | J6: =LEN(I6) -> 17
A7: 1.0 | B7: busbar_relay | C7: =IF(B7="","",IF(C7<>"",C7,NOW())) -> 0 | D7: 鲍凯鹏 | F7: Busbar relay | G7: 母线保护 | H7: =LEN(G7) -> 4 | I7: Busbar relay | J7: =LEN(I7) -> 12
A8: 1.0 | B8: capacitor_relay | C8: =IF(B8="","",IF(C8<>"",C8,NOW())) -> 0 | D8: 鲍凯鹏 | F8: Capacitor relay | G8: 电容器保护 | H8: =LEN(G8) -> 5 | I8: Capacitor relay | J8: =LEN(I8) -> 15
A9: 1.0 | B9: bus_coupler_relay | C9: =IF(B9="","",IF(C9<>"",C9,NOW())) -> 0 | D9: 鲍凯鹏 | F9: Bus coupler relay | G9: 母联保护 | H9: =LEN(G9) -> 4 | I9: Bus-coupler relay | J9: =LEN(I9) -> 17
A10: =IF(B10="","",IF(A10<>"",A10,#REF!)) | C10: =IF(B10="","",IF(C10<>"",C10,NOW()))
A11: =IF(B11="","",IF(A11<>"",A11,#REF!)) | C11: =IF(B11="","",IF(C11<>"",C11,NOW()))
A12: =IF(B12="","",IF(A12<>"",A12,#REF!)) | C12: =IF(B12="","",IF(C12<>"",C12,NOW()))
A13: =IF(B13="","",IF(A13<>"",A13,#REF!)) | C13: =IF(B13="","",IF(C13<>"",C13,NOW()))
A14: 装置识别码
A15: 1.0 | B15: device_version | C15: =IF(B15="","",IF(C15<>"",C15,NOW())) | G15: 程序版本 | H15: =LEN(G15) -> 4 | I15: Program version | J15: =LEN(I15) -> 15
A16: =IF(B16="","",IF(A16<>"",A16,#REF!)) | C16: =IF(B16="","",IF(C16<>"",C16,NOW()))
A17: =IF(B17="","",IF(A17<>"",A17,#REF!)) | C17: =IF(B17="","",IF(C17<>"",C17,NOW()))
A18: 模块版本信息
A19: 1.0 | B19: mod_ver | C19: =IF(B19="","",IF(C19<>"",C19,NOW())) -> 0 | D19: 薛宇 | E19: 模块版本号 | F19: module version | G19: 模块版本号 | H19: =LEN(G19) -> 5 | I19: Module version | J19: =LEN(I19) -> 14
A21: =IF(B21="","",IF(A21<>"",A21,#REF!)) | C21: =IF(B21="","",IF(C21<>"",C21,NOW()))
A22: =IF(B22="","",IF(A22<>"",A22,#REF!)) | C22: =IF(B22="","",IF(C22<>"",C22,NOW()))
A23: =IF(B23="","",IF(A23<>"",A23,#REF!)) | C23: =IF(B23="","",IF(C23<>"",C23,NOW()))
A24: =IF(B24="","",IF(A24<>"",A24,#REF!)) | C24: =IF(B24="","",IF(C24<>"",C24,NOW()))
A25: =IF(B25="","",IF(A25<>"",A25,#REF!)) | C25: =IF(B25="","",IF(C25<>"",C25,NOW()))
A26: =IF(B26="","",IF(A26<>"",A26,#REF!)) | C26: =IF(B26="","",IF(C26<>"",C26,NOW()))
A27: =IF(B27="","",IF(A27<>"",A27,#REF!)) | C27: =IF(B27="","",IF(C27<>"",C27,NOW()))
A28: =IF(B28="","",IF(A28<>"",A28,#REF!)) | C28: =IF(B28="","",IF(C28<>"",C28,NOW()))
A29: =IF(B29="","",IF(A29<>"",A29,#REF!)) | C29: =IF(B29="","",IF(C29<>"",C29,NOW()))
A30: =IF(B30="","",IF(A30<>"",A30,#REF!)) | C30: =IF(B30="","",IF(C30<>"",C30,NOW()))
A31: =IF(B31="","",IF(A31<>"",A31,#REF!)) | C31: =IF(B31="","",IF(C31<>"",C31,NOW()))
A32: =IF(B32="","",IF(A32<>"",A32,#REF!)) | C32: =IF(B32="","",IF(C32<>"",C32,NOW()))
... A1161: =IF(B1161="","",IF(A1161<>"",A1161,#REF!)) | C1161: =IF(B1161="","",IF(C1161<>"",C1161,NOW()))
C1162: =IF(B1162="","",IF(C1162<>"",C1162,NOW()))

Sheet 功能名（19）
A1: 版本 | B1: Abbr | C1: 创建日期 | D1: 创建人 | E1: 术语中文释义 | F1: 术语英文释义 | G1: 中文术语 | I1: 英文术语 | K1: 西文术语 | M1: 俄文术语
G2: 术语 | H2: 字符数 | I2: 术语 | J2: 字符数 | K2: 术语 | L2: 字符数 | M2: 术语 | N2: 字符数
A3: 通用模块
A4: 1.0 | B4: I3PM | C4: 44648 | D4: 罗琴琴 | F4: three phase current module | G4: 三相电流模块 | H4: =LEN(G4) -> 6 | I4: I3PM | J4: =LEN('功能名（19）'!I4) -> 4
A5: 1.0 | B5: U3PM | C5: 44648 | D5: 罗琴琴 | F5: three phase voltage module | G5: 三相电压模块 | H5: =LEN(G5) -> 6 | I5: U3PM | J5: =LEN('功能名（19）'!I5) -> 4
A6: 1.0 | B6: I1PM | C6: 44648 | D6: 罗琴琴 | F6: single phase current module | G6: 单相电流模块 | H6: =LEN(G6) -> 6 | I6: I1PM | J6: =LEN('功能名（19）'!I6) -> 4
A7: 1.0 | B7: U1PM | C7: 44648 | D7: 罗琴琴 | F7: single phase voltage module | G7: 单相电压模块 | H7: =LEN(G7) -> 6 | I7: U1PM | J7: =LEN('功能名（19）'!I7) -> 4
A8: 1.0 | B8: TANG | C8: 44723.659 | D8: 罗琴琴 | F8: calculation of angle | G8: 角度计算 | H8: =LEN(G8) -> 4 | I8: TANG | J8: =LEN('功能名（19）'!I8) -> 4
A9: 1.0 | B9: FREQM | C9: 44648 | D9: 罗琴琴 | F9: calculation of frequency | G9: 频率计算 | H9: =LEN(G9) -> 4 | I9: FreqM | J9: =LEN('功能名（19）'!I9) -> 5
A10: 1.0 | B10: TRIPBay | C10: 44708 | D10: 孙启锐 | F10: line trip module | G10: 线路保护跳闸模块 | H10: =LEN(G10) -> 8 | I10: TripBay | J10: =LEN('功能名（19）'!I10) -> 7
A11: 1.0 | B11: TRIPCB | C11: 44708 | D11: 孙启锐 | F11: general trip module | G11: 通用元件跳闸模块 | H11: =LEN(G11) -> 8 | I11: TripCB | J11: =LEN('功能名（19）'!I11) -> 6
A13: 保护功能
A14: 1.0 | B14: RBRF_50BF | C14: 44630.581 | D14: 刘龙 | F14: circuit-breaker failure protection | G14: 失灵保护 | H14: =LEN(G14) -> 4 | I14: RBRF_50BF | J14: =LEN('功能名（19）'!I14) -> 9
A15: 1.0 | B15: PTOC_50_51P | D15: 赵成虎 | F15: phase overcurrent protection | G15: 相过流保护 | H15: =LEN(G15) -> 5 | I15: PTOC_50/51P | J15: =LEN('功能名（19）'!I15) -> 11
A16: 1.0 | B16: PDIR | D16: 赵成虎 | F16: phase overcurrent directional element | G16: 相电流方向元件 | H16: =LEN(G16) -> 7 | I16: PDIR | J16: =LEN('功能名（19）'!I16) -> 4
A17: 1.0 | B17: PTOC_50_51G | D17: 赵成虎 | F17: zero-sequence overcurrent protection | G17: 零序过流保护 | H17: =LEN(G17) -> 6 | I17: PTOC_50/51G | J17: =LEN('功能名（19）'!I17) -> 11
A18: 1.0 | B18: I0DIR | D18: 赵成虎 | F18: zero-sequence overcurrent directional element | G18: 零序电流方向元件 | H18: =LEN(G18) -> 8 | I18: I0DIR | J18: =LEN('功能名（19）'!I18) -> 5
A19: 1.0 | B19: PTTR_49 | D19: 余培懿 | F19: thermal overload protection | G19: 热过负荷保护 | H19: =LEN(G19) -> 6 | I19: PTTR_49 | J19: =LEN('功能名（19）'!I19) -> 7
A20: 1.0 | B20: PTOV_59P | C20: 44653 | D20: 曹义 | F20: over voltage protection | G20: 过电压保护 | H20: =LEN(G20) -> 5 | I20: PTOV_59P | J20: =LEN('功能名（19）'!I20) -> 8
A21: 1.0 | B21: PTUV_27P | C21: 44653 | D21: 曹义 | F21: under voltage protection | G21: 低电压保护 | H21: =LEN(G21) -> 5 | I21: PTUV_27P | J21: =LEN('功能名（19）'!I21) -> 8
A22: 1.0 | B22: PTOF_81O | C22: 44642 | D22: 薛宇 | F22: over frequency protection | G22: 过频保护 | H22: =LEN(G22) -> 4 | I22: PTOF_81O | J22: =LEN('功能名（19）'!I22) -> 8
A23: 1.0 | B23: PTUF_81U | C23: 44642 | D23: 薛宇 | F23: under frequency protection | G23: 低频保护 | H23: =LEN(G23) -> 4 | I23: PTUF_81U | J23: =LEN('功能名（19）'!I23) -> 8
A24: 1.0 | B24: PTOC_50PD | D24: 余培懿 | F24: pole discrepancy protection | G24: 非全相保护 | H24: =LEN(G24) -> 5 | I24: PTOC_50PD | J24: =LEN('功能名（19）'!I24) -> 9
A25: 1.0 | B25: RREC_79 | C25: 44638 | D25: 宋丹丹 | F25: automatic reclosure | G25: 自动重合闸 | H25: =LEN(G25) -> 5 | I25: RREC_79 | J25: =LEN('功能名（19）'!I25) -> 7
A26: 1.0 | B26: RSYN_25 | D26: 苗文彬 | F26: synchronization check | G26: 同期检测 | H26: =LEN(G26) -> 4 | I26: RSYN_25 | J26: =LEN('功能名（19）'!I26) -> 7
A27: 1.0 | B27: PTOC_46BC | D27: 孙启锐 | F27: broken conductor protection | G27: 断线保护 | H27: =LEN(G27) -> 4 | I27: PTOC_46BC | J27: =LEN('功能名（19）'!I27) -> 9
A28: 1.0 | B28: PTOC_50PSOTF | D28: 冯志翔 | F28: switch onto fault protection with phase current | G28: 相过流加速保护 | H28: =LEN(G28) -> 7 | I28: PTOC_50PSOTF | J28: =LEN('功能名（19）'!I28) -> 12
A29: 1.0 | B29: PTOC_50GSOTF | D29: 冯志翔 | F29: switch onto fault protection with zero-sequence current | G29: 零序过流加速保护 | H29: =LEN(G29) -> 8 | I29: PTOC_50GSOTF | J29: =LEN('功能名（19）'!I29) -> 12
A30: 1.0 | B30: SOTF | D30: 冯志翔 | F30: switch onto fault protection | G30: 加速保护 | H30: =LEN(G30) -> 4 | I30: SOTF
J31: =LEN('功能名（19）'!I31) -> 0
A32: 测量功能 | J32: =LEN('功能名（19）'!I32) -> 0
A33: 1.0 | B33: MEAS_PQ | D33: 马国威 | G33: 功率计算 | I33: MEAS_PQ | J33: =LEN('功能名（19）'!I33) -> 7
A34: 1.0 | B34: MEAS_PWR | D34: 马国威 | G34: 计量计算 | I34: MEAS_PWR | J34: =LEN('功能名（19）'!I34) -> 8
A35: 控制功能
A36: 1.0 | B36: CTRL | D36: 赵琦 | F36: equipment control | G36: 设备控制 | H36: =LEN(G36) -> 4 | I36: CTRL | J36: =LEN('功能名（19）'!I36) -> 4
A37: 1.0 | B37: CILO | D37: 赵琦 | F37: interlock | G37: 联锁 | H37: =LEN(G37) -> 2 | I37: CILO | J37: =LEN('功能名（19）'!I37) -> 4
A38: 1.0 | B38: CSEQ | D38: 赵琦 | F38: equipment sequence control | G38: 序列控制 | H38: =LEN(G38) -> 4 | I38: CSEQ | J38: =LEN('功能名（19）'!I38) -> 4
A41: 其他模块
A42: 1.0 | B42: XCBR | D42: 李逸星 | G42: 开关位置模块 | H42: =LEN(G42) -> 6 | I42: XCBR | J42: =LEN('功能名（19）'!I42) -> 4
A43: 1.0 | B43: XSWI | D43: 刘龙 | G43: 刀闸模块 | H43: =LEN(G43) -> 4 | I43: XSWI | J43: =LEN('功能名（19）'!I43) -> 4
...

Sheet 外部输入信号(中26，外22)
A1: 版本 | B1: Abbr | C1: 创建日期 | D1: 创建人 | E1: 术语中文释义 | F1: 术语英文释义 | G1: 中文术语 | I1: 英文术语 | K1: 西文术语 | M1: 俄文术语
G2: 术语 | H2: 字符数 | I2: 术语 | J2: 字符数 | K2: 术语 | L2: 字符数 | M2: 术语 | N2: 字符数
A3: 遥信
A4: 1.0 | B4: in_mcb | C4: =IF(B4="","",IF(C4<>"",C4,NOW())) -> 0 | D4: 薛宇 | E4: 互感器就地端子箱空开位置 | F4: NC (normally closed) contact of MCB | G4: VT MCB打开 | H4: =LEN(G4) -> 8 | I4: NC_MCB | J4: =LEN(I4) -> 6
A5: 1.0 | B5: in_line1_pt_mcb | C5: =IF(B5="","",IF(C5<>"",C5,NOW())) -> 0 | D5: 冯志翔 | E5: 线路1电压的 MCB接点，接入MCB常闭接点，即MCB打开时闭合 | F5: NC (normally closed) contact of MCB of VT on line1 | G5: 线路1VT MCB打开 | H5: =LEN(G5) -> 11 | I5: NC_MCB_Line1 | J5: =LEN(I5) -> 12
A6: 1.0 | B6: in_line2_pt_mcb | C6: =IF(B6="","",IF(C6<>"",C6,NOW())) -> 0 | D6: 冯志翔 | E6: 线路2电压的 MCB接点，接入MCB常闭接点，即MCB打开时闭合 | F6: NC (normally closed) contact of MCB of VT on line2 | G6: 线路2VT MCB打开 | H6: =LEN(G6) -> 11 | I6: NC_MCB_Line2 | J6: =LEN(I6) -> 12
A7: 1.0 | B7: in_bus1_pt_mcb | C7: =IF(B7="","",IF(C7<>"",C7,NOW())) -> 0 | D7: 冯志翔 | E7: 母线1电压的 MCB接点，接入MCB常闭接点，即MCB打开时闭合 | F7: NC (normally closed) contact of MCB of VT on bus1 | G7: 母线1VT MCB打开 | H7: =LEN(G7) -> 11 | I7: NC_MCB_Bus1 | J7: =LEN(I7) -> 11
A8: 1.0 | B8: in_bus2_pt_mcb | C8: =IF(B8="","",IF(C8<>"",C8,NOW())) -> 0 | D8: 冯志翔 | E8: 母线2电压的 MCB接点，接入MCB常闭接点，即MCB打开时闭合 | F8: NC (normally closed) contact of MCB of VT on bus2 | G8: 母线2VT MCB打开 | H8: =LEN(G8) -> 11 | I8: NC_MCB_Bus2 | J8: =LEN(I8) -> 11
A9: 1.0 | B9: in_ref_pt_mcb | D9: 冯志翔 | E9: 参考侧电压的MCB接点，接入MCB常闭接点，即MCB打开时闭合 | F9: NC (normally closed) contact of MCB of VT at reference side | G9: 参考侧VT MCB打开 | H9: =LEN(G9) -> 11 | I9: NC_MCB_RefSide | J9: =LEN(I9) -> 14
A10: 1.0 | B10: in_syn_pt_mcb | D10: 冯志翔 | E10: 同期侧电压的MCB接点，接入MCB常闭接点，即MCB打开时闭合 | F10: NC (normally closed) contact of MCB of VT at synchronization side | G10: 同期侧VT MCB打开 | H10: =LEN(G10) -> 11 | I10: NC_MCB_SynSide | J10: =LEN(I10) -> 14
A11: 1.0 | B11: in_cb_52a | C11: =IF(B11="","",IF(C11<>"",C11,NOW())) -> 0 | D11: 李逸星 | F11: A normally open contact of circuit breaker | G11: 开关常开触点 | H11: =LEN(G11) -> 6 | I11: 52a | J11: =LEN(I11) -> 3
A12: 1.0 | B12: in_cb_52b | C12: =IF(B12="","",IF(C12<>"",C12,NOW())) -> 0 | D12: 李逸星 | F12: A normally closed contact of circuit breaker | G12: 开关常闭触点 | H12: =LEN(G12) -> 6 | I12: 52b | J12: =LEN(I12) -> 3
A13: 1.0 | B13: in_cb_pha_52a | C13: =IF(B13="","",IF(C13<>"",C13,NOW())) -> 0 | D13: 李逸星 | F13: A normally open contact of circuit breaker phase A | G13: 开关A相常开触点 | H13: =LEN(G13) -> 8 | I13: 52a_PhA | J13: =LEN(I13) -> 7
A14: 1.0 | B14: in_cb_pha_52b | C14: =IF(B14="","",IF(C14<>"",C14,NOW())) -> 0 | D14: 李逸星 | F14: A normally closed contact of circuit breaker phase A | G14: 开关A相常闭触点 | H14: =LEN(G14) -> 8 | I14: 52b_PhA | J14: =LEN(I14) -> 7
A15: 1.0 | B15: in_cb_phb_52a | C15: =IF(B15="","",IF(C15<>"",C15,NOW())) -> 0 | D15: 李逸星 | F15: A normally open contact of circuit breaker phase B | G15: 开关B相常开触点 | H15: =LEN(G15) -> 8 | I15: 52a_PhB | J15: =LEN(I15) -> 7
A16: 1.0 | B16: in_cb_phb_52b | C16: =IF(B16="","",IF(C16<>"",C16,NOW())) -> 0 | D16: 李逸星 | F16: A normally closed contact of circuit breaker phase B | G16: 开关B相常闭触点 | H16: =LEN(G16) -> 8 | I16: 52b_PhB | J16: =LEN(I16) -> 7
A17: 1.0 | B17: in_cb_phc_52a | C17: =IF(B17="","",IF(C17<>"",C17,NOW())) -> 0 | D17: 李逸星 | F17: A normally open contact of circuit breaker phase C | G17: 开关C相常开触点 | H17: =LEN(G17) -> 8 | I17: 52a_PhC | J17: =LEN(I17) -> 7
A18: 1.0 | B18: in_cb_phc_52b | C18: =IF(B18="","",IF(C18<>"",C18,NOW())) -> 0 | D18: 李逸星 | F18: A normally closed contact of circuit breaker phase C | G18: 开关C相常闭触点 | H18: =LEN(G18) -> 8 | I18: 52b_PhC | J18: =LEN(I18) -> 7
A19: 1.0 | B19: bypass_swi_89a | C19: =IF(B19="","",IF(C19<>"",C19,NOW())) -> 0 | D19: 刘龙 | F19: A normally open contact of bypass switch | G19: 旁路刀闸常开触点 | H19: =LEN(G19) -> 8 | I19: 89a_Bypass | J19: =LEN(I19) -> 10
A20: 1.0 | B20: bypass_swi_89b | C20: =IF(B20="","",IF(C20<>"",C20,NOW())) -> 0 | D20: 刘龙 | F20: A normally closed contact of bypass switch | G20: 旁路刀闸常闭触点 | H20: =LEN(G20) -> 8 | I20: 89b_Bypass | J20: =LEN(I20) -> 10
A21: 1.0 | B21: bus1_swi_89a | C21: =IF(B21="","",IF(C21<>"",C21,NOW())) -> 0 | D21: 刘龙 | F21: A normally open contact of bus1 switch | G21: 母线1刀闸常开触点 | H21: =LEN(G21) -> 9 | I21: 89a_Bus1 | J21: =LEN(I21) -> 8
A22: 1.0 | B22: bus1_swi_89b | D22: 刘龙 | F22: A normally closed contact of bus1 switch | G22: 母线1刀闸常闭触点 | H22: =LEN(G22) -> 9 | I22: 89b_Bus1 | J22: =LEN(I22) -> 8
A23: 1.0 | B23: bus2_swi_89a | D23: 刘龙 | F23: A normally open contact of bus2 switch | G23: 母线2刀闸常开触点 | H23: =LEN(G23) -> 9 | I23: 89a_Bus2 | J23: =LEN(I23) -> 8
A24: 1.0 | B24: bus2_swi_89b | D24: 刘龙 | F24: A normally closed contact of bus2 switch | G24: 母线2刀闸常闭触点 | H24: =LEN(G24) -> 9 | I24: 89b_Bus2 | J24: =LEN(I24) -> 8
A25: 1.0 | B25: in_swi_89a | D25: 冯志翔 | F25: A normally open contact of switch | G25: 刀闸常开触点 | H25: =LEN(G25) -> 6 | I25: 89a | J25: =LEN(I25) -> 3
A26: 1.0 | B26: in_swi_89b | D26: 冯志翔 | F26: A normally closed contact of switch | G26: 刀闸常闭触点 | H26: =LEN(G26) -> 6 | I26: 89b | J26: =LEN(I26) -> 3
A28: 硬压板
A29: 1.0 | B29: in_en | C29: =IF(B29="","",IF(C29<>"",C29,NOW())) -> 0 | D29: 刘龙 | E29: 功能投入输入 | F29: enable function | G29: 功能投入开入 | H29: =LEN(G29) -> 6 | I29: Enable | J29: =LEN(I29) -> 6
A30: 1.0 | B30: in_blk | C30: =IF(B30="","",IF(C30<>"",C30,NOW())) -> 0 | D30: 刘龙 | E30: 功能闭锁输入 | F30: block function | G30: 闭锁开入 | H30: =LEN(G30) -> 4 | I30: Block | J30: =LEN(I30) -> 5
A31: 1.0 | B31: in_off | C31: =IF(B31="","",IF(C31<>"",C31,NOW())) -> 0 | D31: 宋丹丹 | E31: 功能退出输入，默认状态为退出 | F31: turnoff function | G31: 功能退出开入 | H31: =LEN(G31) -> 6 | I31: Disable | J31: =LEN(I31) -> 7
A33: =IF(B33="","",IF(A33<>"",A33,#REF!)) | C33: =IF(B33="","",IF(C33<>"",C33,NOW()))
A34: 通用保护开入
A35: 1.0 | B35: in_reset | C35: =IF(B35="","",IF(C35<>"",C35,NOW())) -> 0 | D35: 宋丹丹 | E35: 复归 | F35: input of reset | G35: 复归命令 | H35: =LEN(G35) -> 4 | I35: ResetSignal | J35: =LEN(I35) -> 11
A38: 保护开入
A39: 1.0 | B39: bfi_ph3 | C39: 44630.607 | D39: 刘龙 | E39: 外部信号，启动失灵 | F39: initiate BF (breaker failure protection) for 3 phases from external devices | G39: 外部三相启失灵开入 | H39: 7 | I39: ExtInit_BF_3Ph | J39: =LEN(I39) -> 14
A40: 1.0 | B40: bfi_ph3_ch2 | C40: 44630.607 | D40: 刘龙 | E40: 外部信号，启动失灵 | F40: initiate BF (breaker failure protection) for 3 phases from external devices, group 2 | G40: 外部三相启失灵开入2 | H40: 7 | I40: ExtInit_BF_3Ph_2 | J40: =LEN(I40) -> 16
A41: 1.0 | B41: bfi_phA | C41: 44630.607 | D41: 刘龙 | E41: 外部信号，启动失灵 | F41: initiate BF (breaker failure protection) for phase A from external devices | G41: 外部A相启失灵开入 | H41: 7 | I41: ExtInit_BF_PhA | J41: =LEN(I41) -> 14
A42: 1.0 | B42: bfi_phB | C42: 44630.607 | D42: 刘龙 | E42: 外部信号，启动失灵 | F42: initiate BF (breaker failure protection) for phase B from external devices | G42: 外部B相启失灵开入 | H42: 7 | I42: ExtInit_BF_PhB | J42: =LEN(I42) -> 14
A43: 1.0 | B43: bfi_phC | C43: 44630.607 | D43: 刘龙 | E43: 外部信号，启动失灵 | F43: initiate BF (breaker failure protection) for phase C from external devices | G43: 外部C相启失灵开入 | H43: 7 | I43: ExtInit_BF_PhC | J43: =LEN(I43) -> 14
A44: 1.0 | B44: bfi_cont | C44: 44630.607 | D44: 刘龙 | F44: initiate BF (breaker failure protection) by contact position | G44: （判位置）启失灵开入 | H44: 7 | I44: ExtInit_BF_ByPos | J44: =LEN(I44) -> 16
...

Sheet 内部输入信号(中26，外22) 
A1: 版本 | B1: Abbr | C1: 创建日期 | D1: 创建人 | E1: 术语中文释义 | F1: 术语英文释义 | G1: 中文术语 | I1: 英文术语 | K1: 西文术语 | M1: 俄文术语
G2: 术语 | H2: 字符数 | I2: 术语 | J2: 字符数 | K2: 术语 | L2: 字符数 | M2: 术语 | N2: 字符数
A3: 内部输入信号
A4: 1.0 | B4: in_cb_clsd_a | C4: 44694 | D4: 冯志翔 | E4: 开关A相合位 | F4: circuit breaker pole A is closed | G4: 开关A相合位 | H4: =LEN(G4) -> 6 | I4: PoleA_Clsd | J4: =LEN(I4) -> 10
A5: 1.0 | B5: in_cb_opn_a | C5: 44694 | D5: 冯志翔 | E5: 开关A相分位，来自开关模块，当前加速保护用 | F5: circuit breaker pole A is open | G5: 开关A相分位 | H5: =LEN(G5) -> 6 | I5: PoleA_Open | J5: =LEN(I5) -> 10
A6: 1.0 | B6: in_cb_clsd_b | C6: 44694 | D6: 冯志翔 | E6: 开关B相合位 | F6: circuit breaker pole B is closed | G6: 开关B相合位 | H6: =LEN(G6) -> 6 | I6: PoleB_Clsd | J6: =LEN(I6) -> 10
A7: 1.0 | B7: in_cb_opn_b | C7: 44694 | D7: 冯志翔 | E7: 开关B相分位，来自开关模块，当前加速保护用 | F7: circuit breaker pole B is open | G7: 开关B相分位 | H7: =LEN(G7) -> 6 | I7: PoleB_Open | J7: =LEN(I7) -> 10
A8: 1.0 | B8: in_cb_clsd_c | C8: 44694 | D8: 冯志翔 | E8: 开关C相合位 | F8: circuit breaker pole C is closed | G8: 开关C相合位 | H8: =LEN(G8) -> 6 | I8: PoleC_Clsd | J8: =LEN(I8) -> 10
A9: 1.0 | B9: in_cb_opn_c | C9: 44694 | D9: 冯志翔 | E9: 开关C相分位，来自开关模块，当前加速保护用 | F9: circuit breaker pole C is open | G9: 开关C相分位 | H9: =LEN(G9) -> 6 | I9: PoleC_Open | J9: =LEN(I9) -> 10
A10: 1.0 | B10: in_line1_dpos_wj | C10: =IF(B10="","",IF(C10<>"",C10,NOW())) -> 0 | D10: 苗文彬 | E10: 1½接线或双母接线线路1刀闸双位置接点 | F10: Double switch position of line1 | G10: 线路1刀闸双位置 | H10: =LEN(G10) -> 8 | I10: DblPos_Sw_Line1 | J10: =LEN(I10) -> 15
A11: 1.0 | B11: in_line2_dpos_wj | C11: =IF(B11="","",IF(C11<>"",C11,NOW())) -> 0 | D11: 苗文彬 | E11: 1½接线线路2刀闸双位置接点 | F11: Double switch position of line2 | G11: 线路2刀闸双位置 | H11: =LEN(G11) -> 8 | I11: DblPos_Sw_Line2 | J11: =LEN(I11) -> 15
A12: 1.0 | B12: in_bus1_dpos_wj | C12: =IF(B12="","",IF(C12<>"",C12,NOW())) -> 0 | D12: 苗文彬 | E12: 1½接线或双母接线母线1开关双位置接点 | F12: Double switch position bus1 | G12: 母线1开关双位置 | H12: =LEN(G12) -> 8 | I12: DblPos_Sw_Bus1 | J12: =LEN(I12) -> 14
A13: 1.0 | B13: in_bus2_dpos_wj | C13: =IF(B13="","",IF(C13<>"",C13,NOW())) -> 0 | D13: 苗文彬 | E13: 1½接线或双母接线母线2开关双位置接点 | F13: Double switch position bus2 | G13: 母线2开关双位置 | H13: =LEN(G13) -> 8 | I13: DblPos_Sw_Bus2 | J13: =LEN(I13) -> 14
A14: 1.0 | B14: in_middle_dpos_wj | C14: =IF(B14="","",IF(C14<>"",C14,NOW())) -> 0 | D14: 苗文彬 | E14: 1½接线中开关双位置接点 | F14: Double switch position of tie-CB | G14: 中开关双位置 | H14: =LEN(G14) -> 9 | I14: DblPos_TieCB | J14: =LEN(I14) -> 12
A16: 1.0 | B16: bfi_trip3 | C16: =IF(B16="","",IF(C16<>"",C16,NOW())) -> 0 | D16: 刘龙 | E16: 跳闸模块来的内部启动失灵信号 | F16: Initiate BFP (breaker failure protection) from internal relay protection for 3 phases | G16: 内部三相启失灵开入 | H16: =LEN(G16) -> 9 | I16: IntInit_BF_3Ph | J16: =LEN(I16) -> 14
A17: 1.0 | B17: bfi_tripA | C17: 44630.607 | D17: 刘龙 | E17: 跳闸模块来的内部启动失灵信号 | F17: Initiate BFP (breaker failure protection) from internal relay protection for phase A | G17: 内部A相启失灵开入 | H17: 7 | I17: IntInit_BF_PhA | J17: =LEN(I17) -> 14
A18: 1.0 | B18: bfi_tripB | C18: 44630 | D18: 刘龙 | E18: 跳闸模块来的内部启动失灵信号 | F18: Initiate BFP (breaker failure protection) from internal relay protection for phase B | G18: 内部B相启失灵开入 | H18: 7 | I18: IntInit_BF_PhB | J18: =LEN(I18) -> 14
A19: 1.0 | B19: bfi_tripC | C19: 44630.607 | D19: 刘龙 | E19: 跳闸模块来的内部启动失灵信号 | F19: Initiate BFP (breaker failure protection) from internal relay protection for phase C | G19: 内部C相启失灵开入 | H19: 7 | I19: IntInit_BF_PhC | J19: =LEN(I19) -> 14
A20: 1.0
A21: 1.0 | B21: bfi_tripp | C21: =IF(B21="","",IF(C21<>"",C21,NOW())) -> 0 | D21: 刘龙 | E21: 内部其他功能模块启动失灵开入，逻辑为分相或 | F21: BFP initiate input from Internal relay protection, any phase; Internally initiate BF (breaker failure protection) by any phase | G21: 内部启失灵开入 | H21: =LEN(G21) -> 7 | I21: IntInit_BF_Phx | J21: =LEN(I21) -> 14
A22: 1.0 | B22: in_live_ia | C22: =IF(B22="","",IF(C22<>"",C22,NOW())) -> 0 | D22: 李逸星 | E22: A相有流 (>0.04In)，当前用于失灵保护和开关位置模块 | F22: Phase A is on load (with current >0.04In) | G22: A相有流 | H22: =LEN(G22) -> 4 | I22: PhA_OnLoad | J22: =LEN(I22) -> 10
A23: 1.0 | B23: in_live_ib | C23: =IF(B23="","",IF(C23<>"",C23,NOW())) -> 0 | D23: 李逸星 | E23: B相有流(>0.04In)，当前用于失灵保护和开关位置模块 | F23: Phase B is on load (with current) | G23: B相有流 | H23: =LEN(G23) -> 4 | I23: PhB_OnLoad | J23: =LEN(I23) -> 10
A24: 1.0 | B24: in_live_ic | C24: =IF(B24="","",IF(C24<>"",C24,NOW())) -> 0 | D24: 李逸星 | E24: C相有流(>0.04In)，当前用于失灵保护和开关位置模块 | F24: Phase C is on load (with current) | G24: C相有流 | H24: =LEN(G24) -> 4 | I24: PhC_OnLoad | J24: =LEN(I24) -> 10
A25: 1.0 | B25: in_i3p_live_or | C25: =IF(B25="","",IF(C25<>"",C25,NOW())) -> 0 | D25: 李逸星 | E25: 三相电流任一相有流(>0.04In) | F25: Any phase is on load(>0.04In) | G25: 任意一相有流 | H25: =LEN(G25) -> 6 | I25: Phx_OnLoad | J25: =LEN(I25) -> 10
A26: 1.0 | B26: in_i3p_dead_and | C26: =IF(B26="","",IF(C26<>"",C26,NOW())) -> 0 | D26: 冯志翔 | E26: 三相电流均无流,来自电流模块，当前加速保护用 | F26: no current flows on the 3 phases | G26: 三相电流均无流 | H26: =LEN(G26) -> 7 | I26: 3Ph_NoFlow | J26: =LEN(I26) -> 10
A27: 1.0 | B27: in_dead_ia | C27: =IF(B27="","",IF(C27<>"",C27,NOW())) -> 0 | D27: 冯志翔 | E27: A相无流，来自电流模块，当前用于重合闸保护 | F27: Phase A is with no flow | G27: A相无流 | H27: =LEN(G27) -> 4 | I27: PhA_NoFlow | J27: =LEN(I27) -> 10
A28: 1.0 | B28: in_dead_ib | C28: =IF(B28="","",IF(C28<>"",C28,NOW())) -> 0 | D28: 冯志翔 | E28: B相无流，来自电流模块，当前用于重合闸保护 | F28: Phase B is with no flow | G28: B相无流 | H28: =LEN(G28) -> 4 | I28: PhB_NoFlow | J28: =LEN(I28) -> 10
A29: 1.0 | B29: in_dead_ic | C29: =IF(B29="","",IF(C29<>"",C29,NOW())) -> 0 | D29: 冯志翔 | E29: C相无流，来自电流模块，当前用于重合闸保护 | F29: Phase C is with no flow | G29: C相无流 | H29: =LEN(G29) -> 4 | I29: PhC_NoFlow | J29: =LEN(I29) -> 10
A32: 1.0 | B32: in_fwd_dir | D32: 薛宇 | E32: 正方向信号输入，来自方向元件，当前过流保护用 | F32: in forward direction | G32: 正方向信号输入 | I32: In_FwdDir | J32: =LEN(I32) -> 9
A33: 1.0 | B33: in_rvs_dir | D33: 薛宇 | E33: 反方向信号输入，来自方向元件，当前过流保护用 | F33: in reverse direction | G33: 反方向信号输入 | I33: In_RevDir | J33: =LEN(I33) -> 9
A34: 1.0 | B34: in_fwd_dir_a | D34: 薛宇 | E34: A相正方向信号输入，来自方向元件，当前过流保护和加速保护用 | F34: phase A is in forward direction | G34: A相正方向信号输入 | I34: In_FwdDir_PhA | J34: =LEN(I34) -> 13
A35: 1.0 | B35: in_rvs_dir_a | D35: 薛宇 | E35: A相反方向信号输入，来自方向元件，当前过流保护和加速保护用 | F35: phase A is in reverse direction | G35: A相反方向信号输入 | I35: In_RevDir_PhA | J35: =LEN(I35) -> 13
A36: 1.0 | B36: in_vt_en | D36: 薛宇 | F36: local VT is on（in use ） | G36: 本侧VT投入 | I36: LocalVT_On | J36: =LEN(I36) -> 10
A37: 1.0
A38: 1.0
A39: 1.0 | B39: in_1p_mod_valid | C39: 44638.574 | D39: 余培懿 | E39: 单相重合闸模式有效 | F39: 1-pole reclosing mode valid | G39: 单重模式有效 | H39: 6 | I39: 1PoleMode_Valid | J39: =LEN(I39) -> 15
A40: 1.0 | B40: in_50pd_init | C40: 44675 | D40: 余培懿 | E40: 非全相开入标志，是位置和外部开入合成的信号 | F40: Initiate PD | G40: 非全相启动标志 | H40: 7 | I40: Initiate_50PD | J40: =LEN(I40) -> 14
A41: 1.0 | B41: fail_phs_a | D41: 孙启锐 | E41: TripBay选相元件的输出 | F41: Phase A failed | G41: 故障选A相 | H41: =LEN(G41) -> 5 | I41: PhA_Failed | J41: =LEN(I41) -> 10
A42: 1.0 | B42: fail_phs_b | D42: 孙启锐 | E42: TripBay选相元件的输出 | F42: Phase B failed | G42: 故障选B相 | H42: =LEN(G42) -> 5 | I42: PhB_Failed | J42: =LEN(I42) -> 10
A43: 1.0 | B43: fail_phs_c | D43: 孙启锐 | E43: TripBay选相元件的输出 | F43: Phase C failed | G43: 故障选C相 | H43: =LEN(G43) -> 5 | I43: PhC_Failed | J43: =LEN(I43) -> 10
...

Sheet 外部输出信号 (中26，外22)
A1: 版本 | B1: Abbr | C1: 创建日期 | D1: 创建人 | E1: 术语中文释义 | F1: 术语英文释义 | G1: 中文术语 | I1: 英文术语 | K1: 西文术语 | M1: 俄文术语
G2: 术语 | H2: 字符数 | I2: 术语 | J2: 字符数 | K2: 术语 | L2: 字符数 | M2: 术语 | N2: 字符数
A3: 自检信息
A4: 1.0 | B4: flg_set_err | C4: 44688.789 | D4: 赵琦 | F4: parameter setting is error | G4: 参数设置错误 | H4: 6 | I4: Setting_Err | J4: =LEN(I4) -> 11
A5: 1.0 | B5: ct_alm | C5: 44663.694 | D5: 薛宇 | F5: CT disconnection alarm；Alarm of CT failure | G5: CT断线告警 | H5: 6 | I5: Alm_Fail_CT | J5: 0
A6: 1.0 | B6: vt_alm | C6: =IF(B6="","",IF(C6<>"",C6,NOW())) -> 0 | D6: 薛宇 | F6: VT disconnection alarm；Alarm of VT failure | G6: VT断线告警 | H6: =LEN(G6) -> 6 | I6: Alm_Fail_VT | J6: =LEN(I6) -> 11
A7: 1.0 | B7: vt_inst_alm | C7: =IF(B7="","",IF(C7<>"",C7,NOW())) -> 0 | D7: 薛宇 | F7: VT disconnection instant alarm; Instantaneous Alarm of VT failure | G7: VT断线瞬时告警 | H7: =LEN(G7) -> 8 | I7: InstantAlm_Fail_VT | J7: =LEN(I7) -> 18
A8: 1.0 | B8: cb_pd | C8: 44675 | D8: 李逸星 | F8: The synthetic status of pole discrepancy (PD) | G8: 非全相合成标志 | H8: =LEN(G8) -> 7 | I8: SyntheticStatus_PD | J8: =LEN(I8) -> 18
A9: 1.0 | B9: cb_pd_st | C9: 44675 | D9: 李逸星 | F9: Initiate the pole discrepancy(PD) function. | G9: 非全相启动标志 | H9: =LEN(G9) -> 7 | I9: Initiate_50PD | J9: =LEN(I9) -> 13
A10: 1.0 | B10: cb_52a52b_alm | C10: 44675 | D10: 李逸星 | F10: The contact 52a and 52b of circuit breaker is abnormal | G10: 开关触点异常告警 | H10: =LEN(G10) -> 8 | I10: 52a/52b_Abnor | J10: =LEN(I10) -> 13
A11: 1.0 | B11: cb_52b_alm | C11: 44675 | D11: 李逸星 | F11: circuit breaker open state is abnormal | G11: 开关跳位异常告警 | H11: =LEN(G11) -> 8 | I11: OpenState_Abnor_CB | J11: =LEN(I11) -> 18
A12: 1.0 | B12: cb_pd_alm | C12: 44675 | D12: 李逸星 | F12: Alarm of pole discrepancy (PD) by CB position | G12: 开关非全相告警 | H12: =LEN(G12) -> 7 | I12: Alm_PD | J12: =LEN(I12) -> 6
A13: 1.0 | B13: flg_refv_abn | C13: 44658.853 | D13: 苗文彬 | F13: Uref is abnormal | G13: 参考电压异常 | H13: =LEN(G13) -> 6 | I13: RefVolt_Abnor | J13: =LEN(I13) -> 13
A14: 1.0 | B14: flg_synv_abn | C14: 44658.853 | D14: 苗文彬 | F14: Usyn is abnormal | G14: 同期电压异常 | H14: =LEN(G14) -> 6 | I14: SynVolt_Abnor | J14: =LEN(I14) -> 13
A15: 1.0 | B15: flg_volsw_invalid | C15: 44658.853 | D15: 苗文彬 | F15: Voltage selection is invalid | G15: 电压切换无效 | H15: =LEN(G15) -> 6 | I15: VoltSel_Invalid | J15: =LEN(I15) -> 15
A16: 1.0 | B16: alm_init_pd | D16: 余培懿 | E16: 非全相开入有效状态持续一定延时时间后报长期启动告警 | F16: Alarm of PD protection long-term initiation | G16: 非全相长期启动告警 | H16: =LEN(G16) -> 9 | I16: PD_Init_Abnor | J16: =LEN(I16) -> 13
A17: 1.0 | B17: sw_89a89b_alm | C17: 44688.789 | D17: 刘龙 | F17: alarm：auxiliary contact 89a/89b is abnormal | G17: 刀闸触点异常告警 | H17: =LEN(G17) -> 8 | I17: 89a/89b_Abnor | J17: =LEN(I17) -> 13
A18: 1.0 | B18: sw_89b_alm | C18: 44688.789 | D18: 刘龙 | F18: alarm: DS(disconnector switch) auxiliary opening position (89b) is abnormal | G18: 刀闸分位异常告警 | H18: =LEN(G18) -> 8 | I18: DS_OpenState_Abnor | J18: =LEN(I18) -> 18
A19: 1.0 | B19: sw_no_chg_alarm | C19: 44688.789 | D19: 刘龙 | F19: alarm：DS(disconnector switch) position is unconfirmed | G19: 刀闸位置长期未更新告警 | H19: =LEN(G19) -> 11 | I19: DS_Pos_NotConfirmed | J19: =LEN(I19) -> 19
A20: 1.0 | B20: flg_alm_ad_chk_err | C20: =IF(B20="","",IF(C20<>"",C20,NOW())) -> 0 | D20: 孙启锐 | E20: 双采样通道校验出错 | F20: Error of dual-channel data | G20: 双采样通道校验出错 | H20: =LEN(G20) -> 9 | I20: Data_Err_DualCh | J20: =LEN(I20) -> 15
A21: 1.0 | B21: flg_alm_ad_off_err | C21: =IF(B21="","",IF(C21<>"",C21,NOW())) -> 0 | D21: 孙启锐 | F21: alarm of DC bias check | G21: 直流偏置校验异常 | H21: =LEN(G21) -> 8 | I21: Alm_BiasChk_DC | J21: =LEN(I21) -> 14
A22: 1.0 | B22: flg_relay_bsj | C22: =IF(B22="","",IF(C22<>"",C22,NOW())) -> 0 | D22: 薛宇 | F22: failure of device | G22: 装置闭锁 | H22: =LEN(G22) -> 4 | I22: Device_Failed | J22: =LEN(I22) -> 13
A23: 1.0 | B23: flg_bfi_al | C23: 44688.789 | D23: 刘龙 | F23: Alarm of BF(breaker failure) protection external long-term initiation | G23: 外部启失灵开入异常 | H23: =LEN(G23) -> 9 | I23: BF_ExtInit_Abnor | J23: =LEN(I23) -> 16
A24: 1.0 | B24: flg_bfi_ph3_alm | C24: 45656.789 | D24: 冯志翔 | F24: BF external binary initiation of 3phase is abnormal | G24: 三相启失灵开入异常 | H24: =LEN(G24) -> 9 | I24: BF_3PhExtInit_Abnor | J24: =LEN(I24) -> 19
A25: 1.0 | B25: flg_bfi_cont_alm | C25: 45656.789 | D25: 冯志翔 | F25: BF external binary initiation by position is abnormal | G25: （判位置）启失灵开入异常 | H25: =LEN(G25) -> 12 | I25: BF_PosInit_Abnor | J25: =LEN(I25) -> 16
A27: =IF(B27="","",IF(A27<>"",A27,#REF!)) | C27: =IF(B27="","",IF(C27<>"",C27,NOW()))
A28: 变位信息
A29: 1.0 | B29: func_on | C29: 44688.789 | D29: 赵琦 | F29: function of module is enabled | G29: 模块功能投入 | H29: =LEN(G29) -> 6 | I29: FN_On | J29: =LEN(I29) -> 5
A30: 1.0 | B30: func_valid | C30: 44688.789 | D30: 赵琦 | F30: function of module is vaild | G30: 模块功能有效 | H30: =LEN(G30) -> 6 | I30: FN_Valid | J30: =LEN(I30) -> 8
A31: 1.0 | B31: func_blk | C31: 44688.789 | D31: 赵琦 | F31: function of module is blocked | G31: 模块功能闭锁 | H31: =LEN(G31) -> 6 | I31: FN_Blkd | J31: =LEN(I31) -> 7
A32: 1.0 | B32: mod_sta | C32: =IF(B32="","",IF(C32<>"",C32,NOW())) -> 0 | D32: 薛宇 | E32: 模块状态 | F32: module status | G32: 模块状态 | H32: =LEN(G32) -> 4 | I32: ModuleState | J32: =LEN(I32) -> 11 | L32: =LEN(K32) -> 0 | N32: =LEN(M32) -> 0
A33: 1.0 | B33: overhaul | C33: 44640 | D33: 赵琦 | F33: overhaul state:in maintenance | G33: 检修状态 | H33: 4 | I33: In_Maintenance | J33: =LEN(I33) -> 14
A34: 1.0 | B34: flg_u_line1_valid | C34: 44691 | D34: 苗文彬 | E34: 选择线路1电压 | F34: voltage of line1 is valid | G34: UL1有效 | H34: =LEN(G34) -> 5 | I34: Volt_Valid_Line1 | J34: =LEN(I34) -> 16
A35: 1.0 | B35: flg_u_bus1_valid | C35: 44691 | D35: 苗文彬 | E35: 选择母线1电压 | F35: voltage of bus1 is valid | G35: UB1有效 | H35: =LEN(G35) -> 5 | I35: Volt_Valid_Bus1 | J35: =LEN(I35) -> 15
A36: 1.0 | B36: flg_u_line2_valid | C36: 44691 | D36: 苗文彬 | E36: 选择线路2电压 | F36: voltage of line2 is valid | G36: UL2有效 | H36: =LEN(G36) -> 5 | I36: Volt_Valid_Line2 | J36: =LEN(I36) -> 16 | L36: =LEN(K36) -> 0
A37: 1.0 | B37: flg_u_bus2_valid | C37: 44691 | D37: 苗文彬 | E37: 选择母线2电压 | F37: voltage of bus2 is valid | G37: UB2有效 | H37: =LEN(G37) -> 5 | I37: Volt_Valid_Bus2 | J37: =LEN(I37) -> 15 | L37: =LEN(K37) -> 0
A38: 1.0 | B38: flg_u_ref_valid | C38: 44691 | D38: 苗文彬 | E38: 参考侧电压有效 | F38: reference voltage is valid | G38: 参考电压有效 | H38: =LEN(G38) -> 6 | I38: RefVolt_Valid | J38: =LEN(I38) -> 13 | L38: =LEN(K38) -> 0
A39: 1.0 | B39: flg_u_syn_valid | C39: 44691 | D39: 苗文彬 | E39: 同期侧电压有效 | F39: synchronization voltage is valid | G39: 同期电压有效 | H39: =LEN(G39) -> 6 | I39: SynVolt_Valid | J39: =LEN(I39) -> 13 | L39: =LEN(K39) -> 0
A40: 1.0 | B40: flg_syn_ar | C40: 44691 | D40: 苗文彬 | F40: Synchronization check of AR is meet(OK) | G40: 重合同步检测满足 | H40: =LEN(G40) -> 8 | I40: AR_SynChk_OK | J40: =LEN(I40) -> 12 | L40: =LEN(K40) -> 0
A41: 1.0 | B41: flg_syn_sh | C41: 44691 | D41: 苗文彬 | F41: Synchronization check of MC is meet(OK) | G41: 手合同步检测满足 | H41: =LEN(G41) -> 8 | I41: MC_SynChk_OK | J41: =LEN(I41) -> 12
...

Sheet 内部输出信号 (中26，外22) 
A1: 版本 | B1: Abbr | C1: 创建日期 | D1: 创建人 | E1: 术语中文释义 | F1: 术语英文释义 | G1: 中文术语 | I1: 英文术语 | K1: 西文术语 | M1: 俄文术语
G2: 术语 | H2: 字符数 | I2: 术语 | J2: 字符数 | K2: 术语 | L2: 字符数 | M2: 术语 | N2: 字符数
A3: 1.0 | J3: =LEN(I3) -> 0
A4: 1.0 | B4: flg_bf_cont_st | C4: 45259 | D4: 刘龙 | E4: 当前逻辑图都采用内部外部失灵启动，分开了，总述的词条暂时保留 | F4: Started by position criterion | G4: 失灵(判位置)启动 | I4: Initiated_ByPos | J4: =LEN(I4) -> 15
A5: 1.0 | B5: flg_bfA_cur_st | C5: 45259 | D5: 刘龙 | E5: 当前逻辑图都采用内部外部失灵启动，分开了，总述的词条暂时保留 | F5: Started by current criterion, phase A | G5: A相失灵启动 | I5: Initiated_PhA | J5: =LEN(I5) -> 13
A6: 1.0 | B6: flg_bfB_cur_st | C6: 45259 | D6: 刘龙 | E6: 当前逻辑图都采用内部外部失灵启动，分开了，总述的词条暂时保留 | F6: Started by current criterion, phase B | G6: B相失灵启动 | I6: Initiated_PhB | J6: =LEN(I6) -> 13
A7: 1.0 | B7: flg_bfC_cur_st | C7: 45259 | D7: 刘龙 | E7: 当前逻辑图都采用内部外部失灵启动，分开了，总述的词条暂时保留 | F7: Started by current criterion, phase C | G7: C相失灵启动 | I7: Initiated_PhC | J7: =LEN(I7) -> 13
A8: 1.0 | B8: flg_bf3_cur_st | C8: 45259 | D8: 刘龙 | E8: 当前逻辑图都采用内部外部失灵启动，分开了，总述的词条暂时保留 | F8: Started by current criterion, 3-phase | G8: 三相失灵启动 | I8: Initiated_3Ph | J8: =LEN(I8) -> 13
A9: 1.0 | B9: flag_bf_bus_vl | C9: =IF(B9="","",IF(C9<>"",C9,NOW())) -> 0 | D9: 刘龙 | F9: BFP voltage criterion action signal in;Release voltage control | G9: 失灵电压开放 | H9: =LEN(G9) -> 6 | I9: Release_VoltCtrl | J9: =LEN(I9) -> 16
A11: 1.0 | B11: flg_init_bfp | C11: 44664.672 | D11: 薛宇 | F11: starup breaker failure protection; Initiate BF (breaker failure protection） | G11: 启动失灵 | H11: =LEN(G11) -> 4 | I11: Initiate_BF | J11: =LEN(I11) -> 11
A12: 1.0
A13: 1.0
A14: 1.0 | B14: flg_rec_reclaim | C14: 45593 | D14: 冯志翔 | E14: 重合闸的输出信号: 重合闸复归 | F14: reclaim AR | G14: 重合闸复归 | H14: =LEN(G14) -> 5 | I14: Reclaim_AR | J14: =LEN(I14) -> 10
A15: 1.0 | B15: flag_last_rec_op | C15: 45593 | D15: 冯志翔 | E15: 重合闸的输出信号: 最后一次合闸已出口，该次重合闸脉冲后，复归前若再收到重合闸启动命令，则闭锁 | F15: reclosing pulse of last cycle has sent out | G15: 最后一次合闸已出口 | H15: =LEN(G15) -> 9 | I15: LastReclCmd_Out | J15: =LEN(I15) -> 15
A16: 1.0 | B16: flag_wait_str | C16: 45593 | D16: 冯志翔 | E16: 重合闸的输出信号: 重合闸启动处于等待状态 | F16: waiting for reclosure start | G16: 重合闸启动等待出口中 | H16: =LEN(G16) -> 10 | I16: Waiting_to_StartRecl | J16: =LEN(I16) -> 20
A17: 1.0 | B17: flag_1st_rec_op | C17: 45593 | D17: 冯志翔 | E17: 重合闸的输出信号: 第一次重合闸已经动作过了 | F17: AR has operated for 1st reclosing cycle | G17: 第一次重合闸已动作 | H17: =LEN(G17) -> 9 | I17: 1stReclCmd_Out | J17: =LEN(I17) -> 14
A18: 1.0 | B18: flg_trp_1pole | C18: 45593 | D18: 冯志翔 | E18: 重合闸的输出信号：单相跳闸。跳闸信号合成逻辑里的其他信号复用外部输入信号的名称。 | F18: trip 1 pole | G18: 单相跳闸 | H18: =LEN(G18) -> 4 | I18: Trip_1Pole | J18: =LEN(I18) -> 10
A19: 1.0 | B19: flag_permit_slave | C19: 45593 | D19: 冯志翔 | E19: 允许后合经延时后出口 | F19: permit slave | G19: 后合出口允许 | H19: =LEN(G19) -> 6 | I19: Permit_SlaveRecl | J19: =LEN(I19) -> 16
A20: 1.0 | B20: flag_permit_rec | C20: 45593 | D20: 冯志翔 | E20: 允许后合重合闸出口 | F20: permit reclosing | G20: 重合出口允许 | H20: =LEN(G20) -> 6 | I20: Permit_Recl | J20: =LEN(I20) -> 11
A21: 1.0 | B21: flg_1p_qd_trp | C21: 45593 | D21: 冯志翔 | E21: 跳闸信号启动单相重合闸 | F21: trip start 1pole reclosure | G21: 跳闸单重启动 | H21: =LEN(G21) -> 6 | I21: Trip_Start_1PoleRecl | J21: =LEN(I21) -> 20
A22: 1.0 | B22: flg_1p_qd_pos | C22: 45593 | D22: 冯志翔 | E22: 开关位置启动单相重合闸 | F22: CB position start 1pole reclosure | G22: 开关位置单重启动 | H22: =LEN(G22) -> 8 | I22: Pos_Start_1PoleRecl | J22: =LEN(I22) -> 19
A23: 1.0 | B23: flg_3p_qd_trp | C23: 45593 | D23: 冯志翔 | E23: 跳闸信号启动三相重合闸 | F23: trip start 3pole reclosure | G23: 跳闸三重启动 | H23: =LEN(G23) -> 6 | I23: Trip_Start_3PoleRecl | J23: =LEN(I23) -> 20
A24: 1.0 | B24: flg_3p_qd_pos | C24: 45593 | D24: 冯志翔 | E24: 开关位置启动三相重合闸 | F24: CB position start 3pole reclosure | G24: 开关位置三重启动 | H24: =LEN(G24) -> 8 | I24: Pos_Start_3PoleRecl | J24: =LEN(I24) -> 19
A25: 1.0 | B25: flg_1prec_ok | C25: 45593 | D25: 冯志翔 | F25: 1-pole reclosure is prepared | G25: 单重准备出口 | H25: =LEN(G25) -> 6 | I25: 1PoleRecl_Prepared | J25: =LEN(I25) -> 18
A26: 1.0 | B26: flg_3prec_ok | C26: 45593 | D26: 冯志翔 | F26: 3-pole reclosure is prepared | G26: 三重准备出口 | H26: =LEN(G26) -> 6 | I26: 3PoleRecl_Prepared | J26: =LEN(I26) -> 18
A27: 1.0 | B27: flag_ext_delay | C27: 45593 | D27: 冯志翔 | F27: With additional delay | G27: 重合闸额外延时 | H27: =LEN(G27) -> 7 | I27: With_AddDly | J27: =LEN(I27) -> 11
A28: 1.0 | B28: flag_1str_fail | C28: 45593 | D28: 冯志翔 | F28: 1pole reclosure start failed | G28: 单重启动失败 | H28: =LEN(G28) -> 6 | I28: 1PoleStart_Failed | J28: =LEN(I28) -> 17
A29: 1.0 | B29: flag_3str_fail | C29: 45593 | D29: 冯志翔 | F29: 3pole reclosure start failed | G29: 三重启动失败 | H29: =LEN(G29) -> 6 | I29: 3PoleStart_Failed | J29: =LEN(I29) -> 17
A30: 1.0 | B30: flag_ar_str_fail | C30: 45593 | D30: 冯志翔 | F30: reclosure start failed | G30: 重合闸启动失败 | H30: =LEN(G30) -> 7 | I30: ReclStart_Failed | J30: =LEN(I30) -> 16
A31: 1.0 | B31: flag_fail_pos | C31: 45593 | D31: 冯志翔 | F31: reclosure failed, judged by postion criterion | G31: 开关位置判重合失败 | H31: =LEN(G31) -> 10 | I31: Recl_Failed_ByPosChk | J31: =LEN(I31) -> 20
A34: 1.0 | B34: flg_u_kf | D34: 薛宇 | E34: 电压元件动作 | G34: 电压元件开放 | I34: VoltCtrl_Released | J34: =LEN(I34) -> 17
A35: 1.0 | B35: flg_harm_kf | D35: 薛宇 | E35: 谐波元件动作 | G35: 谐波元件开放 | I35: Hm2Ctrl_Released | J35: =LEN(I35) -> 16
A36: 1.0 | B36: flg_dir_kf | D36: 薛宇 | E36: 方向元件动作 | G36: 方向元件开放 | I36: DirCtrl_Released | J36: =LEN(I36) -> 16
A37: 1.0 | B37: flg_u_kf_a | D37: 薛宇 | E37: A相电压元件动作 | G37: A相电压元件开放 | I37: VoltCtrl_Released_PhA | J37: =LEN(I37) -> 21
A38: 1.0 | B38: flg_harm_kf_a | D38: 薛宇 | E38: A相谐波元件动作 | G38: A相谐波元件开放 | I38: Hm2Ctrl_Released_PhA | J38: =LEN(I38) -> 20
A39: 1.0 | B39: flg_dir_kf_a | D39: 薛宇 | E39: A相方向元件动作 | G39: A相方向元件开放 | I39: DirCtrl_Released_PhA | J39: =LEN(I39) -> 20
A40: 1.0 | B40: flg_oc_con | D40: 薛宇 | G40: 电流越限 | I40: Curr_OutOfRange | J40: =LEN(I40) -> 15
A41: 1.0 | B41: flg_oc_con_a | D41: 薛宇 | G41: A相电流越限 | I41: Curr_OutOfRange_PhA | J41: =LEN(I41) -> 19
A42: 1.0 | B42: flg_freq_con | D42: 冯志翔 | E42: 用于过频保护 | F42: frequency is out of range | G42: 频率越限 | I42: Freq_OutOfRange | J42: =LEN(I42) -> 15
A44: 1.0 | B44: flg_vol_on | D44: 曹优勒图 | F44: voltage is ever present | G44: 曾经有压 | I44: Volt_OnceLive | J44: =LEN(I44) -> 13
...

Sheet AI(20）
A1: 版本 | B1: Abbr | C1: 创建日期 | D1: 创建人 | E1: 术语中文释义 | F1: 术语英文释义 | G1: 中文术语 | I1: 英文术语 | K1: 西文术语 | M1: 俄文术语
G2: 术语 | H2: 字符数 | I2: 术语 | J2: 字符数 | K2: 术语 | L2: 字符数 | M2: 术语 | N2: 字符数
A3: 外部电压
A4: 1.0 | B4: in_angle_u3p1 | C4: =IF(B4="","",IF(C4<>"",C4,NOW())) -> 0 | D4: 罗琴琴 | E4: 第一组三相电压输入 | F4: 3-phase voltage input of angle module | G4: 第一组三相电压输入 | H4: =LEN(G4) -> 9 | I4: U3ph_1 | J4: =LEN(I4) -> 6
A5: 1.0 | B5: in_angle_u1p1 | C5: =IF(B5="","",IF(C5<>"",C5,NOW())) -> 0 | D5: 罗琴琴 | E5: 第一组单相电压输入 | F5: single-phase voltage input of angle module | G5: 第一组单相电压输入 | H5: =LEN(G5) -> 9 | I5: U1ph_1 | J5: =LEN(I5) -> 6
A6: 1.0 | B6: in_ua | D6: 孙启锐 | E6: A相电压输入 | F6: voltage input of phase A | G6: A相电压输入 | H6: =LEN(G6) -> 6 | I6: UA | J6: =LEN(I6) -> 2
A7: 1.0 | B7: in_ub | D7: 孙启锐 | E7: B相电压输入 | F7: voltage input of phase B | G7: B相电压输入 | H7: =LEN(G7) -> 6 | I7: UB | J7: =LEN(I7) -> 2
A8: 1.0 | B8: in_uc | D8: 孙启锐 | E8: C相电压输入 | F8: voltage input of phase C | G8: C相电压输入 | H8: =LEN(G8) -> 6 | I8: UC | J8: =LEN(I8) -> 2
A10: 外部电流
A11: 1.0 | B11: in_angle_i3p1 | C11: 44725.877 | D11: 罗琴琴 | E11: 第一组三相电流输入 | F11: 3-phase current input module | G11: 第一组三相电流输入 | H11: =LEN(G11) -> 9 | I11: I3ph_1 | J11: =LEN(I11) -> 6
A12: 1.0 | B12: in_angle_i3p2 | C12: =IF(B12="","",IF(C12<>"",C12,NOW())) -> 0 | D12: 罗琴琴 | E12: 第二组三相电流输入 | F12: 3-phase current input module of angle | G12: 第二组三相电流输入 | H12: =LEN(G12) -> 9 | I12: I3ph_2 | J12: =LEN(I12) -> 6
A13: 1.0 | B13: in_angle_i1p1 | C13: =IF(B13="","",IF(C13<>"",C13,NOW())) -> 0 | D13: 罗琴琴 | E13: 第一组单相电流输入 | F13: single-phase current input module of angle | G13: 第一组单相电流输入 | H13: =LEN(G13) -> 9 | I13: I1ph_1 | J13: =LEN(I13) -> 6
A14: 1.0 | B14: in_ia | C14: =IF(B14="","",IF(C14<>"",C14,NOW())) -> 0 | D14: 孙启锐 | E14: A相电流输入 | F14: current input of phase A | G14: A相电流输入 | H14: =LEN(G14) -> 6 | I14: IA | J14: =LEN(I14) -> 2
A15: 1.0 | B15: in_ib | C15: =IF(B15="","",IF(C15<>"",C15,NOW())) -> 0 | D15: 孙启锐 | E15: B相电流输入 | F15: current input of phase B | G15: B相电流输入 | H15: =LEN(G15) -> 6 | I15: IB | J15: =LEN(I15) -> 2
A16: 1.0 | B16: in_ic | C16: =IF(B16="","",IF(C16<>"",C16,NOW())) -> 0 | D16: 孙启锐 | E16: C相电流输入 | F16: current input of phase C | G16: C相电流输入 | H16: =LEN(G16) -> 6 | I16: IC | J16: =LEN(I16) -> 2
A17: 1.0 | B17: in_i0 | C17: =IF(B17="","",IF(C17<>"",C17,NOW())) -> 0 | D17: 薛宇 | E17: 零序电流输入 | F17: zero-sequence current input | G17: 零序电流输入 | H17: =LEN(G17) -> 6 | I17: 3I0 | J17: =LEN(I17) -> 3
A19: =IF(B19="","",IF(A19<>"",A19,#REF!)) | C19: =IF(B19="","",IF(C19<>"",C19,NOW()))
A21: =IF(B21="","",IF(A21<>"",A21,#REF!)) | C21: =IF(B21="","",IF(C21<>"",C21,NOW()))
A23: 内部信号，AO用于AI，但名称变更
A24: 1.0 | B24: in_line1_u3p | C24: =IF(B24="","",IF(C24<>"",C24,NOW())) -> 0 | D24: 苗文彬 | E24: 三相电压输入 | F24: voltage of line1 | G24: 线路1电压 | H24: =LEN(G24) -> 5 | I24: U_Line1 | J24: =LEN(I24) -> 7
A25: 1.0 | B25: in_bus1_u1p | C25: =IF(B25="","",IF(C25<>"",C25,NOW())) -> 0 | D25: 苗文彬 | E25: 单相电压输入 | F25: voltage of bus1 | G25: 母线1电压 | H25: =LEN(G25) -> 5 | I25: U_Bus1 | J25: =LEN(I25) -> 6
A26: 1.0 | B26: in_line2_u1p | C26: =IF(B26="","",IF(C26<>"",C26,NOW())) -> 0 | D26: 苗文彬 | E26: 单相电压输入 | F26: voltage of line2 | G26: 线路2电压 | H26: =LEN(G26) -> 5 | I26: U_Line2 | J26: =LEN(I26) -> 7
A27: 1.0 | B27: in_bus2_u1p | C27: =IF(B27="","",IF(C27<>"",C27,NOW())) -> 0 | D27: 苗文彬 | E27: 单相电压输入 | F27: voltage of bus2 | G27: 母线2电压 | H27: =LEN(G27) -> 5 | I27: U_Bus2 | J27: =LEN(I27) -> 6
A28: 1.0 | B28: in_ref_u | C28: =IF(B28="","",IF(C28<>"",C28,NOW())) -> 0 | D28: 冯志翔 | E28: 三相电压输入 | F28: voltage at reference side | G28: 参考侧电压 | H28: =LEN(G28) -> 5 | I28: U_Ref | J28: =LEN(I28) -> 5
A29: 1.0 | B29: in_syn_u | C29: =IF(B29="","",IF(C29<>"",C29,NOW())) -> 0 | D29: 冯志翔 | E29: 单相电压输入 | F29: voltage at synchronization side | G29: 同期侧电压 | H29: =LEN(G29) -> 5 | I29: U_Syn | J29: =LEN(I29) -> 5
A30: 1.0 | B30: in_line1_freq | C30: =IF(B30="","",IF(C30<>"",C30,NOW())) -> 0 | D30: 苗文彬 | E30: 三相电压频率输入 | F30: frequency of line1 | G30: 线路1频率 | H30: =LEN(G30) -> 5 | I30: f_Line1 | J30: =LEN(I30) -> 7
A31: 1.0 | B31: in_bus1_freq | C31: =IF(B31="","",IF(C31<>"",C31,NOW())) -> 0 | D31: 苗文彬 | E31: 单相电压频率输入 | F31: frequency of bus1 | G31: 母线1频率 | H31: =LEN(G31) -> 5 | I31: f_Bus1 | J31: =LEN(I31) -> 6
A32: 1.0 | B32: in_line2_freq | C32: =IF(B32="","",IF(C32<>"",C32,NOW())) -> 0 | D32: 苗文彬 | E32: 单相电压频率输入 | F32: frequency of line2 | G32: 线路2频率 | H32: =LEN(G32) -> 5 | I32: f_Line2 | J32: =LEN(I32) -> 7
A33: 1.0 | B33: in_bus2_freq | C33: =IF(B33="","",IF(C33<>"",C33,NOW())) -> 0 | D33: 苗文彬 | E33: 单相电压频率输入 | F33: frequency of bus2 | G33: 母线2频率 | H33: =LEN(G33) -> 5 | I33: f_Bus2 | J33: =LEN(I33) -> 6
A34: 1.0 | B34: in_uref_freq | D34: 冯志翔 | F34: Frequency of reference voltage | G34: 参考电压频率 | H34: =LEN(G34) -> 6 | I34: f_RefVolt | J34: =LEN(I34) -> 9
A35: 1.0 | B35: in_usyn_freq | D35: 冯志翔 | F35: Frequency of syncronization voltage | G35: 同期电压频率 | H35: =LEN(G35) -> 6 | I35: f_SynVolt | J35: =LEN(I35) -> 9
A43: =IF(B43="","",IF(A43<>"",A43,#REF!)) | C43: =IF(B43="","",IF(C43<>"",C43,NOW()))
A44: =IF(B44="","",IF(A44<>"",A44,#REF!)) | C44: =IF(B44="","",IF(C44<>"",C44,NOW()))
A45: =IF(B45="","",IF(A45<>"",A45,#REF!)) | C45: =IF(B45="","",IF(C45<>"",C45,NOW()))
A46: =IF(B46="","",IF(A46<>"",A46,#REF!)) | C46: =IF(B46="","",IF(C46<>"",C46,NOW()))
A47: =IF(B47="","",IF(A47<>"",A47,#REF!)) | C47: =IF(B47="","",IF(C47<>"",C47,NOW()))
A48: =IF(B48="","",IF(A48<>"",A48,#REF!)) | C48: =IF(B48="","",IF(C48<>"",C48,NOW()))
A49: =IF(B49="","",IF(A49<>"",A49,#REF!)) | C49: =IF(B49="","",IF(C49<>"",C49,NOW()))
A50: =IF(B50="","",IF(A50<>"",A50,#REF!)) | C50: =IF(B50="","",IF(C50<>"",C50,NOW()))
A51: =IF(B51="","",IF(A51<>"",A51,#REF!)) | C51: =IF(B51="","",IF(C51<>"",C51,NOW()))
...

Sheet AO(20）
A1: 版本 | B1: Abbr | C1: 创建日期 | D1: 创建人 | E1: 术语中文释义 | F1: 术语英文释义 | G1: 中文术语 | I1: 英文术语 | K1: 西文术语 | M1: 俄文术语
G2: 术语 | H2: 字符数 | I2: 术语 | J2: 字符数 | K2: 术语 | L2: 字符数 | M2: 术语 | N2: 字符数
A3: 频率
A4: 1.0 | B4: freq | C4: =IF(B4="","",IF(C4<>"",C4,NOW())) -> 0 | D4: 赵琦 | F4: frequency | G4: 频率 | H4: =LEN(G4) -> 2 | I4: f | J4: =LEN(I4) -> 1
A5: 1.0 | B5: uref_freq | D5: 苗文彬 | F5: Frequency of reference voltage | G5: 参考电压频率 | H5: =LEN(G5) -> 6 | I5: f_Ref | J5: =LEN(I5) -> 5
A6: 1.0 | B6: usyn_freq | D6: 苗文彬 | F6: Frequency of syncronization voltage | G6: 同期电压频率 | H6: =LEN(G6) -> 6 | I6: f_Syn | J6: =LEN(I6) -> 5
A7: 1.0 | B7: freq_dif | D7: 苗文彬 | F7: Frequency difference of synchronization check | G7: 检同期频差 | H7: =LEN(G7) -> 5 | I7: fDiff_Syn | J7: =LEN(I7) -> 9
A8: 1.0 | B8: dfdt | D8: 孙启锐 | F8: change rate of frequency difference | G8: 频率滑差 | H8: =LEN(G8) -> 4 | I8: d(fDiff)/dt | J8: =LEN(I8) -> 11
A9: 1.0 | B9: u3p_freq | C9: =IF(B9="","",IF(C9<>"",C9,NOW())) | D9: 冯志翔 | F9: frequency of 3phase voltage | G9: 三相电压频率 | H9: =LEN(G9) -> 6 | I9: f_U3ph | J9: =LEN(I9) -> 6
A12: 电压
A13: 1.0 | B13: amp_ua | C13: =IF(B13="","",IF(C13<>"",C13,NOW())) -> 0 | D13: 鲍凯鹏 | F13: voltage phase A | G13: A相电压 | H13: =LEN(G13) -> 4 | I13: UA | J13: =LEN(I13) -> 2
A14: 1.0 | B14: amp_ub | C14: =IF(B14="","",IF(C14<>"",C14,NOW())) -> 0 | D14: 鲍凯鹏 | F14: voltage phase B | G14: B相电压 | H14: =LEN(G14) -> 4 | I14: UB | J14: =LEN(I14) -> 2
A15: 1.0 | B15: amp_uc | C15: =IF(B15="","",IF(C15<>"",C15,NOW())) -> 0 | D15: 鲍凯鹏 | F15: voltage phase C | G15: C相电压 | H15: =LEN(G15) -> 4 | I15: UC | J15: =LEN(I15) -> 2
A16: 1.0 | B16: amp_uab | C16: =IF(B16="","",IF(C16<>"",C16,NOW())) -> 0 | D16: 鲍凯鹏 | F16: between phase A and phase B | G16: AB相间电压 | H16: =LEN(G16) -> 6 | I16: UAB | J16: =LEN(I16) -> 3
A17: 1.0 | B17: amp_ubc | C17: =IF(B17="","",IF(C17<>"",C17,NOW())) -> 0 | D17: 鲍凯鹏 | F17: between phase B and phase C | G17: BC相间电压 | H17: =LEN(G17) -> 6 | I17: UBC | J17: =LEN(I17) -> 3
A18: 1.0 | B18: amp_uac | C18: =IF(B18="","",IF(C18<>"",C18,NOW())) -> 0 | D18: 鲍凯鹏 | F18: between phase C and phase A | G18: CA相间电压 | H18: =LEN(G18) -> 6 | I18: UCA | J18: =LEN(I18) -> 3
A19: 1.0 | B19: amp_upp | C19: =IF(B19="","",IF(C19<>"",C19,NOW())) | D19: 刘龙 | E19: 非实体，构造出来的，失灵保护中对相间电压的统称 | F19: phase-to-phase voltage | G19: 相间电压 | H19: =LEN(G19) -> 4 | I19: Upp | J19: =LEN(I19) -> 3
A20: 1.0 | B20: amp_3u0 | C20: =IF(B20="","",IF(C20<>"",C20,NOW())) -> 0 | D20: 鲍凯鹏 | F20: zero sequence | G20: 零序电压 | H20: =LEN(G20) -> 4 | I20: 3U0 | J20: =LEN(I20) -> 3
A21: 1.0 | B21: amp_u1 | C21: =IF(B21="","",IF(C21<>"",C21,NOW())) -> 0 | D21: 鲍凯鹏 | F21: positive sequence | G21: 正序电压 | H21: =LEN(G21) -> 4 | I21: U1 | J21: =LEN(I21) -> 2
A22: 1.0 | B22: amp_u2 | C22: =IF(B22="","",IF(C22<>"",C22,NOW())) -> 0 | D22: 鲍凯鹏 | F22: negtive sequence | G22: 负序电压 | H22: =LEN(G22) -> 4 | I22: U2 | J22: =LEN(I22) -> 2
A23: 1.0 | B23: amp_upp_min | D23: 赵成虎 | F23: minimum phase-to-phase voltage | G23: 最小线电压 | I23: MinUpp | J23: =LEN(I23) -> 6
A24: 1.0 | B24: amp_upp_max | D24: 赵成虎 | F24: maximum phase-to-phase voltage | G24: 最大线电压 | I24: MaxUpp | J24: =LEN(I24) -> 6
A25: 1.0 | B25: amp_u_min | D25: 赵成虎 | F25: minimum phase voltage | G25: 最小相电压 | I25: MinUph | J25: =LEN(I25) -> 6
A26: 1.0 | B26: amp_u_max | D26: 赵成虎 | F26: maximum phase voltage | G26: 最大相电压 | I26: MaxUph | J26: =LEN(I26) -> 6
A27: 1.0 | B27: amp_2harm_ua | C27: =IF(B27="","",IF(C27<>"",C27,NOW())) -> 0 | D27: 薛宇 | F27: voltage 2nd harmonic，phase A | G27: A相电压二次谐波 | H27: =LEN(G27) -> 8 | I27: Hm2(UA) | J27: =LEN(I27) -> 7
A28: 1.0 | B28: amp_2harm_ub | D28: 薛宇 | F28: voltage 2nd harmonic，phase B | G28: B相电压二次谐波 | H28: =LEN(G28) -> 8 | I28: Hm2(UB) | J28: =LEN(I28) -> 7
A29: 1.0 | B29: amp_2harm_uc | D29: 薛宇 | F29: voltage 2nd harmonic，phase C | G29: C相电压二次谐波 | H29: =LEN(G29) -> 8 | I29: Hm2(UC) | J29: =LEN(I29) -> 7
A30: 1.0 | B30: amp_3harm_ua | C30: =IF(B30="","",IF(C30<>"",C30,NOW())) -> 0 | D30: 薛宇 | F30: voltage 3rd harmonic，phase A | G30: A相电压三次谐波 | H30: =LEN(G30) -> 8 | I30: Hm3(UA) | J30: =LEN(I30) -> 7
A31: 1.0 | B31: amp_3harm_ub | D31: 薛宇 | F31: voltage 3rd harmonic，phase B | G31: B相电压三次谐波 | H31: =LEN(G31) -> 8 | I31: Hm3(UB) | J31: =LEN(I31) -> 7
